Workbook

Sheet 盘货信息
A1: ID | B1: skuid | C1: 型号 | D1: 到手价 | E1: 国补后到手价 | F1: 前台券（优先） | G1: 卡萨帝95折 | H1: 消费券 | I1: 限时后返 | J1: 限时补贴力度 | K1: 国补额度 | L1: 是否补全国 | M1: 是否国补 | N1: 是否参与全店瓜分 | O1: 全店跨类目折扣 2件96折/3件94折 | P1: 爆量玩法 | Q1: 店铺站外种草活动 | R1: 以旧换新优惠 | S1: 发逛逛后返 | T1: 商品暗券 | U1: 商品暗券链接 | V1: 赠品权益 | W1: 晒单 | X1: 后返 | Y1: 卡萨帝全店玩法满额送赠玩法 | Z1: 延保 | AA1: 服务1：免息 | AB1: 服务2（手动填写） | AC1: 是否减暗券（必填） | AD1: 验证金额 | AE1: 验证对错
AD2: =IF(C2="","",IF($AC2="是",D2-(G2+H2+I2+J2+K2+T2),D2-(G2+H2+I2+J2+K2+F2))) | AE2: =IF(C2="","",IF(ROUND(E2,0)=ROUND(AD2,0),"√","×"))
AD3: =IF(C3="","",IF($AC3="是",D3-(G3+H3+I3+J3+K3+T3),D3-(G3+H3+I3+J3+K3+F3))) | AE3: =IF(C3="","",IF(ROUND(E3,0)=ROUND(AD3,0),"√","×"))
AD4: =IF(C4="","",IF($AC4="是",D4-(G4+H4+I4+J4+K4+T4),D4-(G4+H4+I4+J4+K4+F4))) | AE4: =IF(C4="","",IF(ROUND(E4,0)=ROUND(AD4,0),"√","×"))
AD5: =IF(C5="","",IF($AC5="是",D5-(G5+H5+I5+J5+K5+T5),D5-(G5+H5+I5+J5+K5+F5))) | AE5: =IF(C5="","",IF(ROUND(E5,0)=ROUND(AD5,0),"√","×"))
AD6: =IF(C6="","",IF($AC6="是",D6-(G6+H6+I6+J6+K6+T6),D6-(G6+H6+I6+J6+K6+F6))) | AE6: =IF(C6="","",IF(ROUND(E6,0)=ROUND(AD6,0),"√","×"))
AD7: =IF(C7="","",IF($AC7="是",D7-(G7+H7+I7+J7+K7+T7),D7-(G7+H7+I7+J7+K7+F7))) | AE7: =IF(C7="","",IF(ROUND(E7,0)=ROUND(AD7,0),"√","×"))
AD8: =IF(C8="","",IF($AC8="是",D8-(G8+H8+I8+J8+K8+T8),D8-(G8+H8+I8+J8+K8+F8))) | AE8: =IF(C8="","",IF(ROUND(E8,0)=ROUND(AD8,0),"√","×"))
AD9: =IF(C9="","",IF($AC9="是",D9-(G9+H9+I9+J9+K9+T9),D9-(G9+H9+I9+J9+K9+F9))) | AE9: =IF(C9="","",IF(ROUND(E9,0)=ROUND(AD9,0),"√","×"))
AD10: =IF(C10="","",IF($AC10="是",D10-(G10+H10+I10+J10+K10+T10),D10-(G10+H10+I10+J10+K10+F10))) | AE10: =IF(C10="","",IF(ROUND(E10,0)=ROUND(AD10,0),"√","×"))
AD11: =IF(C11="","",IF($AC11="是",D11-(G11+H11+I11+J11+K11+T11),D11-(G11+H11+I11+J11+K11+F11))) | AE11: =IF(C11="","",IF(ROUND(E11,0)=ROUND(AD11,0),"√","×"))
AD12: =IF(C12="","",IF($AC12="是",D12-(G12+H12+I12+J12+K12+T12),D12-(G12+H12+I12+J12+K12+F12))) | AE12: =IF(C12="","",IF(ROUND(E12,0)=ROUND(AD12,0),"√","×"))
AD13: =IF(C13="","",IF($AC13="是",D13-(G13+H13+I13+J13+K13+T13),D13-(G13+H13+I13+J13+K13+F13))) | AE13: =IF(C13="","",IF(ROUND(E13,0)=ROUND(AD13,0),"√","×"))
... AD501: =IF(C501="","",IF($AC501="是",D501-(G501+H501+I501+J501+K501+T501),D501-(G501+H501+I501+J501+K501+F501))) | AE501: =IF(C501="","",IF(ROUND(E501,0)=ROUND(AD501,0),"√","×"))

Sheet 固定信息
A1: 分隔符 | B1: —————————————
A2: 活动氛围
A3: 活动时间
A4: 产业
A5: 1元预约链接
A6: 消费券链接
A7: 瓜分信息

Sheet 促销信息
A1: =IF(盘货信息!A1="","",盘货信息!A1) -> ID | B1: =IF(盘货信息!B1="","",盘货信息!B1) -> skuid | C1: =IF(盘货信息!C1="","",盘货信息!C1) -> 型号 | D1: 促销信息 | E1: 活动氛围 | F1: 型号+产业 | G1: 活动时间 | H1: 分割线 | I1: 1元预约 | J1: 价格 | K1: 分割线 | L1: 商品暗券 | M1: 爆量 | N1: =盘货信息!$V$1 -> 赠品权益 | O1: =盘货信息!$W$1 -> 晒单 | P1: =盘货信息!$S$1 -> 发逛逛后返 | Q1: =盘货信息!$X$1 -> 后返 | R1: =盘货信息!$Z$1 -> 延保 | S1: =盘货信息!$Q$1 -> 店铺站外种草活动 | T1: 以旧换新 | U1: 分割线 | V1: 卡萨帝全店玩法满额送赠玩法 | W1: 折扣 | X1: 瓜分 | Y1: 分割线 | Z1: 服务
A2: =IF(盘货信息!A2="","",盘货信息!A2) | B2: =IF(盘货信息!B2="","",盘货信息!B2) | C2: =IF(盘货信息!C2="","",盘货信息!C2) | D2: =_xlfn.TEXTJOIN(CHAR(10),TRUE,OFFSET(INDIRECT("RC",FALSE),0,1,1,30)) | E2: =IF(C2="","",固定信息!$B$2) | F2: =IF(C2="","","【"&C2&"】"&固定信息!$B$4) | G2: =IF(C2="","","【"&"活动时间："&固定信息!$B$3&"】") | H2: =IF($C2="","",固定信息!$B$1) | I2: =IF(OR(C2="",固定信息!$B$5=""),"","【1元预约锁好礼】"&固定信息!$B$5) | J2: {=_xlfn.XLOOKUP($A2&$B2&$C2,价格信息!$A:$A&价格信息!$B:$B&价格信息!$C:$C,价格信息!$D:$D)} | K2: =IF($C2="","",固定信息!$B$1) | L2: {=IF(_xlfn.XLOOKUP($A2&$B2&$C2,盘货信息!$A:$A&盘货信息!$B:$B&盘货信息!$C:$C,盘货信息!$T:$T)="","","【优惠券】领"&_xlfn.XLOOKUP($A2&$B2&$C2,盘货信息!$A:$A&盘货信息!$B:$B&盘货信息!$C:$C,盘货信息!$T:$T)&"元优惠卷下单更优惠，领券链接："&_xlfn.XLOOKUP($A2&$B2&$C2,盘货信息!$A:$A&盘货信息!$B:$B&盘货信息!$C:$C,盘货信息!$U:$U))} | M2: {=IF(_xlfn.XLOOKUP($A2&$B2&$C2,盘货信息!$A:$A&盘货信息!$B:$B&盘货信息!$C:$C,盘货信息!$P:$P)="","","【限时】"&_xlfn.XLOOKUP($A2&$B2&$C2,盘货信息!$A:$A&盘货信息!$B:$B&盘货信息!$C:$C,盘货信息!$P:$P))} | N2: {=IF(_xlfn.XLOOKUP($A2&$B2&$C2,盘货信息!$A:$A&盘货信息!$B:$B&盘货信息!$C:$C,盘货信息!$V:$V)="","","【"&盘货信息!$V$1&"】"&_xlfn.XLOOKUP($A2&$B2&$C2,盘货信息!$A:$A&盘货信息!$B:$B&盘货信息!$C:$C,盘货信息!$V:$V))} | O2: {=IF(_xlfn.XLOOKUP($A2&$B2&$C2,盘货信息!$A:$A&盘货信息!$B:$B&盘货信息!$C:$C,盘货信息!$W:$W)="","","【"&盘货信息!$W$1&"】"&_xlfn.XLOOKUP($A2&$B2&$C2,盘货信息!$A:$A&盘货信息!$B:$B&盘货信息!$C:$C,盘货信息!$W:$W))} | P2: {=IF(_xlfn.XLOOKUP($A2&$B2&$C2,盘货信息!$A:$A&盘货信息!$B:$B&盘货信息!$C:$C,盘货信息!$S:$S)<1,"","【"&盘货信息!$S$1&"】"&"后返"&_xlfn.XLOOKUP($A2&$B2&$C2,盘货信息!$A:$A&盘货信息!$B:$B&盘货信息!$C:$C,盘货信息!$S:$S)&"元")} | Q2: {=IF(_xlfn.XLOOKUP($A2&$B2&$C2,盘货信息!$A:$A&盘货信息!$B:$B&盘货信息!$C:$C,盘货信息!$X:$X)="","","【"&盘货信息!$X$1&"】"&_xlfn.XLOOKUP($A2&$B2&$C2,盘货信息!$A:$A&盘货信息!$B:$B&盘货信息!$C:$C,盘货信息!$X:$X))} | R2: {=IF(_xlfn.XLOOKUP($A2&$B2&$C2,盘货信息!$A:$A&盘货信息!$B:$B&盘货信息!$C:$C,盘货信息!$Z:$Z)="","","【"&盘货信息!$Z$1&"】"&_xlfn.XLOOKUP($A2&$B2&$C2,盘货信息!$A:$A&盘货信息!$B:$B&盘货信息!$C:$C,盘货信息!$Z:$Z))} | S2: {=IF(_xlfn.XLOOKUP($A2&$B2&$C2,盘货信息!$A:$A&盘货信息!$B:$B&盘货信息!$C:$C,盘货信息!$Q:$Q)="","","【种草】站外带指定话题种草后返"&_xlfn.XLOOKUP($A2&$B2&$C2,盘货信息!$A:$A&盘货信息!$B:$B&盘货信息!$C:$C,盘货信息!$Q:$Q)&"元红包（每个淘宝账号仅限对应一个站外种草账号，同一个种草账号不可对应多个淘宝账号）")} | T2: {=IF(_xlfn.XLOOKUP($A2&$B2&$C2,盘货信息!$A:$A&盘货信息!$B:$B&盘货信息!$C:$C,盘货信息!$R:$R)<1,"","【以旧换新】"&"享补贴"&ROUND(_xlfn.XLOOKUP($A2&$B2&$C2,盘货信息!$A:$A&盘货信息!$B:$B&盘货信息!$C:$C,盘货信息!$R:$R),0)&"元（可无旧机换新）")} | U2: =IF(AND($N2="",$O2="",$P2="",$Q2="",$R2="",$S2="",$T2=""),"",固定信息!$B$1) | V2: {=IF(_xlfn.XLOOKUP($A2&$B2&$C2,盘货信息!$A:$A&盘货信息!$B:$B&盘货信息!$C:$C,盘货信息!$Y:$Y)="","","【卡萨帝送赠】活动指定时间"&_xlfn.TEXTBEFORE(_xlfn.TEXTAFTER(_xlfn.XLOOKUP($A2&$B2&$C2,盘货信息!$A:$A&盘货信息!$B:$B&盘货信息!$C:$C,盘货信息!$Y:$Y),"点"),"（"))} | W2: {=IF(COUNTIF(_xlfn.XLOOKUP($A2&$B2&$C2,盘货信息!$A:$A&盘货信息!$B:$B&盘货信息!$C:$C,盘货信息!$O:$O),"*是*"),"【折扣】指定型号满2类享96折，满3类享94折","")} | X2: {=IF(固定信息!$B$7="","",IF(_xlfn.XLOOKUP($A2&$B2&$C2,盘货信息!$A:$A&盘货信息!$B:$B&盘货信息!$C:$C,盘货信息!$N:$N)="是","【瓜分】"&固定信息!$B$7,""))} | Y2: =IF(AND($V2="",$W2="",$X2=""),"",固定信息!$B$1) | Z2: {=IF($C2="","",_xlfn.XLOOKUP($A2&$B2&$C2,服务!$A:$A&服务!$B:$B&服务!$C:$C,服务!$D:$D))}
A3: =IF(盘货信息!A3="","",盘货信息!A3) | B3: =IF(盘货信息!B3="","",盘货信息!B3) | C3: =IF(盘货信息!C3="","",盘货信息!C3) | D3: =_xlfn.TEXTJOIN(CHAR(10),TRUE,OFFSET(INDIRECT("RC",FALSE),0,1,1,30)) | E3: =IF(C3="","",固定信息!$B$2) | F3: =IF(C3="","","【"&C3&"】"&固定信息!$B$4) | G3: =IF(C3="","","【"&"活动时间："&固定信息!$B$3&"】") | H3: =IF($C3="","",固定信息!$B$1) | I3: =IF(OR(C3="",固定信息!$B$5=""),"","【1元预约锁好礼】"&固定信息!$B$5) | J3: {=_xlfn.XLOOKUP($A3&$B3&$C3,价格信息!$A:$A&价格信息!$B:$B&价格信息!$C:$C,价格信息!$D:$D)} | K3: =IF($C3="","",固定信息!$B$1) | L3: {=IF(_xlfn.XLOOKUP($A3&$B3&$C3,盘货信息!$A:$A&盘货信息!$B:$B&盘货信息!$C:$C,盘货信息!$T:$T)="","","【优惠券】领"&_xlfn.XLOOKUP($A3&$B3&$C3,盘货信息!$A:$A&盘货信息!$B:$B&盘货信息!$C:$C,盘货信息!$T:$T)&"元优惠卷下单更优惠，领券链接："&_xlfn.XLOOKUP($A3&$B3&$C3,盘货信息!$A:$A&盘货信息!$B:$B&盘货信息!$C:$C,盘货信息!$U:$U))} | M3: {=IF(_xlfn.XLOOKUP($A3&$B3&$C3,盘货信息!$A:$A&盘货信息!$B:$B&盘货信息!$C:$C,盘货信息!$P:$P)="","","【限时】"&_xlfn.XLOOKUP($A3&$B3&$C3,盘货信息!$A:$A&盘货信息!$B:$B&盘货信息!$C:$C,盘货信息!$P:$P))} | N3: {=IF(_xlfn.XLOOKUP($A3&$B3&$C3,盘货信息!$A:$A&盘货信息!$B:$B&盘货信息!$C:$C,盘货信息!$V:$V)="","","【"&盘货信息!$V$1&"】"&_xlfn.XLOOKUP($A3&$B3&$C3,盘货信息!$A:$A&盘货信息!$B:$B&盘货信息!$C:$C,盘货信息!$V:$V))} | O3: {=IF(_xlfn.XLOOKUP($A3&$B3&$C3,盘货信息!$A:$A&盘货信息!$B:$B&盘货信息!$C:$C,盘货信息!$W:$W)="","","【"&盘货信息!$W$1&"】"&_xlfn.XLOOKUP($A3&$B3&$C3,盘货信息!$A:$A&盘货信息!$B:$B&盘货信息!$C:$C,盘货信息!$W:$W))} | P3: {=IF(_xlfn.XLOOKUP($A3&$B3&$C3,盘货信息!$A:$A&盘货信息!$B:$B&盘货信息!$C:$C,盘货信息!$S:$S)<1,"","【"&盘货信息!$S$1&"】"&"后返"&_xlfn.XLOOKUP($A3&$B3&$C3,盘货信息!$A:$A&盘货信息!$B:$B&盘货信息!$C:$C,盘货信息!$S:$S)&"元")} | Q3: {=IF(_xlfn.XLOOKUP($A3&$B3&$C3,盘货信息!$A:$A&盘货信息!$B:$B&盘货信息!$C:$C,盘货信息!$X:$X)="","","【"&盘货信息!$X$1&"】"&_xlfn.XLOOKUP($A3&$B3&$C3,盘货信息!$A:$A&盘货信息!$B:$B&盘货信息!$C:$C,盘货信息!$X:$X))} | R3: {=IF(_xlfn.XLOOKUP($A3&$B3&$C3,盘货信息!$A:$A&盘货信息!$B:$B&盘货信息!$C:$C,盘货信息!$Z:$Z)="","","【"&盘货信息!$Z$1&"】"&_xlfn.XLOOKUP($A3&$B3&$C3,盘货信息!$A:$A&盘货信息!$B:$B&盘货信息!$C:$C,盘货信息!$Z:$Z))} | S3: {=IF(_xlfn.XLOOKUP($A3&$B3&$C3,盘货信息!$A:$A&盘货信息!$B:$B&盘货信息!$C:$C,盘货信息!$Q:$Q)="","","【种草】站外带指定话题种草后返"&_xlfn.XLOOKUP($A3&$B3&$C3,盘货信息!$A:$A&盘货信息!$B:$B&盘货信息!$C:$C,盘货信息!$Q:$Q)&"元红包（每个淘宝账号仅限对应一个站外种草账号，同一个种草账号不可对应多个淘宝账号）")} | T3: {=IF(_xlfn.XLOOKUP($A3&$B3&$C3,盘货信息!$A:$A&盘货信息!$B:$B&盘货信息!$C:$C,盘货信息!$R:$R)<1,"","【以旧换新】"&"享补贴"&ROUND(_xlfn.XLOOKUP($A3&$B3&$C3,盘货信息!$A:$A&盘货信息!$B:$B&盘货信息!$C:$C,盘货信息!$R:$R),0)&"元（可无旧机换新）")} | U3: =IF(AND($N3="",$O3="",$P3="",$Q3="",$R3="",$S3="",$T3=""),"",固定信息!$B$1) | V3: {=IF(_xlfn.XLOOKUP($A3&$B3&$C3,盘货信息!$A:$A&盘货信息!$B:$B&盘货信息!$C:$C,盘货信息!$Y:$Y)="","","【卡萨帝送赠】活动指定时间"&_xlfn.TEXTBEFORE(_xlfn.TEXTAFTER(_xlfn.XLOOKUP($A3&$B3&$C3,盘货信息!$A:$A&盘货信息!$B:$B&盘货信息!$C:$C,盘货信息!$Y:$Y),"点"),"（"))} | W3: {=IF(COUNTIF(_xlfn.XLOOKUP($A3&$B3&$C3,盘货信息!$A:$A&盘货信息!$B:$B&盘货信息!$C:$C,盘货信息!$O:$O),"*是*"),"【折扣】指定型号满2类享96折，满3类享94折","")} | X3: {=IF(固定信息!$B$7="","",IF(_xlfn.XLOOKUP($A3&$B3&$C3,盘货信息!$A:$A&盘货信息!$B:$B&盘货信息!$C:$C,盘货信息!$N:$N)="是","【瓜分】"&固定信息!$B$7,""))} | Y3: =IF(AND($V3="",$W3="",$X3=""),"",固定信息!$B$1) | Z3: {=IF($C3="","",_xlfn.XLOOKUP($A3&$B3&$C3,服务!$A:$A&服务!$B:$B&服务!$C:$C,服务!$D:$D))}
A4: =IF(盘货信息!A4="","",盘货信息!A4) | B4: =IF(盘货信息!B4="","",盘货信息!B4) | C4: =IF(盘货信息!C4="","",盘货信息!C4) | D4: =_xlfn.TEXTJOIN(CHAR(10),TRUE,OFFSET(INDIRECT("RC",FALSE),0,1,1,30)) | E4: =IF(C4="","",固定信息!$B$2) | F4: =IF(C4="","","【"&C4&"】"&固定信息!$B$4) | G4: =IF(C4="","","【"&"活动时间："&固定信息!$B$3&"】") | H4: =IF($C4="","",固定信息!$B$1) | I4: =IF(OR(C4="",固定信息!$B$5=""),"","【1元预约锁好礼】"&固定信息!$B$5) | J4: {=_xlfn.XLOOKUP($A4&$B4&$C4,价格信息!$A:$A&价格信息!$B:$B&价格信息!$C:$C,价格信息!$D:$D)} | K4: =IF($C4="","",固定信息!$B$1) | L4: {=IF(_xlfn.XLOOKUP($A4&$B4&$C4,盘货信息!$A:$A&盘货信息!$B:$B&盘货信息!$C:$C,盘货信息!$T:$T)="","","【优惠券】领"&_xlfn.XLOOKUP($A4&$B4&$C4,盘货信息!$A:$A&盘货信息!$B:$B&盘货信息!$C:$C,盘货信息!$T:$T)&"元优惠卷下单更优惠，领券链接："&_xlfn.XLOOKUP($A4&$B4&$C4,盘货信息!$A:$A&盘货信息!$B:$B&盘货信息!$C:$C,盘货信息!$U:$U))} | M4: {=IF(_xlfn.XLOOKUP($A4&$B4&$C4,盘货信息!$A:$A&盘货信息!$B:$B&盘货信息!$C:$C,盘货信息!$P:$P)="","","【限时】"&_xlfn.XLOOKUP($A4&$B4&$C4,盘货信息!$A:$A&盘货信息!$B:$B&盘货信息!$C:$C,盘货信息!$P:$P))} | N4: {=IF(_xlfn.XLOOKUP($A4&$B4&$C4,盘货信息!$A:$A&盘货信息!$B:$B&盘货信息!$C:$C,盘货信息!$V:$V)="","","【"&盘货信息!$V$1&"】"&_xlfn.XLOOKUP($A4&$B4&$C4,盘货信息!$A:$A&盘货信息!$B:$B&盘货信息!$C:$C,盘货信息!$V:$V))} | O4: {=IF(_xlfn.XLOOKUP($A4&$B4&$C4,盘货信息!$A:$A&盘货信息!$B:$B&盘货信息!$C:$C,盘货信息!$W:$W)="","","【"&盘货信息!$W$1&"】"&_xlfn.XLOOKUP($A4&$B4&$C4,盘货信息!$A:$A&盘货信息!$B:$B&盘货信息!$C:$C,盘货信息!$W:$W))} | P4: {=IF(_xlfn.XLOOKUP($A4&$B4&$C4,盘货信息!$A:$A&盘货信息!$B:$B&盘货信息!$C:$C,盘货信息!$S:$S)<1,"","【"&盘货信息!$S$1&"】"&"后返"&_xlfn.XLOOKUP($A4&$B4&$C4,盘货信息!$A:$A&盘货信息!$B:$B&盘货信息!$C:$C,盘货信息!$S:$S)&"元")} | Q4: {=IF(_xlfn.XLOOKUP($A4&$B4&$C4,盘货信息!$A:$A&盘货信息!$B:$B&盘货信息!$C:$C,盘货信息!$X:$X)="","","【"&盘货信息!$X$1&"】"&_xlfn.XLOOKUP($A4&$B4&$C4,盘货信息!$A:$A&盘货信息!$B:$B&盘货信息!$C:$C,盘货信息!$X:$X))} | R4: {=IF(_xlfn.XLOOKUP($A4&$B4&$C4,盘货信息!$A:$A&盘货信息!$B:$B&盘货信息!$C:$C,盘货信息!$Z:$Z)="","","【"&盘货信息!$Z$1&"】"&_xlfn.XLOOKUP($A4&$B4&$C4,盘货信息!$A:$A&盘货信息!$B:$B&盘货信息!$C:$C,盘货信息!$Z:$Z))} | S4: {=IF(_xlfn.XLOOKUP($A4&$B4&$C4,盘货信息!$A:$A&盘货信息!$B:$B&盘货信息!$C:$C,盘货信息!$Q:$Q)="","","【种草】站外带指定话题种草后返"&_xlfn.XLOOKUP($A4&$B4&$C4,盘货信息!$A:$A&盘货信息!$B:$B&盘货信息!$C:$C,盘货信息!$Q:$Q)&"元红包（每个淘宝账号仅限对应一个站外种草账号，同一个种草账号不可对应多个淘宝账号）")} | T4: {=IF(_xlfn.XLOOKUP($A4&$B4&$C4,盘货信息!$A:$A&盘货信息!$B:$B&盘货信息!$C:$C,盘货信息!$R:$R)<1,"","【以旧换新】"&"享补贴"&ROUND(_xlfn.XLOOKUP($A4&$B4&$C4,盘货信息!$A:$A&盘货信息!$B:$B&盘货信息!$C:$C,盘货信息!$R:$R),0)&"元（可无旧机换新）")} | U4: =IF(AND($N4="",$O4="",$P4="",$Q4="",$R4="",$S4="",$T4=""),"",固定信息!$B$1) | V4: {=IF(_xlfn.XLOOKUP($A4&$B4&$C4,盘货信息!$A:$A&盘货信息!$B:$B&盘货信息!$C:$C,盘货信息!$Y:$Y)="","","【卡萨帝送赠】活动指定时间"&_xlfn.TEXTBEFORE(_xlfn.TEXTAFTER(_xlfn.XLOOKUP($A4&$B4&$C4,盘货信息!$A:$A&盘货信息!$B:$B&盘货信息!$C:$C,盘货信息!$Y:$Y),"点"),"（"))} | W4: {=IF(COUNTIF(_xlfn.XLOOKUP($A4&$B4&$C4,盘货信息!$A:$A&盘货信息!$B:$B&盘货信息!$C:$C,盘货信息!$O:$O),"*是*"),"【折扣】指定型号满2类享96折，满3类享94折","")} | X4: {=IF(固定信息!$B$7="","",IF(_xlfn.XLOOKUP($A4&$B4&$C4,盘货信息!$A:$A&盘货信息!$B:$B&盘货信息!$C:$C,盘货信息!$N:$N)="是","【瓜分】"&固定信息!$B$7,""))} | Y4: =IF(AND($V4="",$W4="",$X4=""),"",固定信息!$B$1) | Z4: {=IF($C4="","",_xlfn.XLOOKUP($A4&$B4&$C4,服务!$A:$A&服务!$B:$B&服务!$C:$C,服务!$D:$D))}
A5: =IF(盘货信息!A5="","",盘货信息!A5) | B5: =IF(盘货信息!B5="","",盘货信息!B5) | C5: =IF(盘货信息!C5="","",盘货信息!C5) | D5: =_xlfn.TEXTJOIN(CHAR(10),TRUE,OFFSET(INDIRECT("RC",FALSE),0,1,1,30)) | E5: =IF(C5="","",固定信息!$B$2) | F5: =IF(C5="","","【"&C5&"】"&固定信息!$B$4) | G5: =IF(C5="","","【"&"活动时间："&固定信息!$B$3&"】") | H5: =IF($C5="","",固定信息!$B$1) | I5: =IF(OR(C5="",固定信息!$B$5=""),"","【1元预约锁好礼】"&固定信息!$B$5) | J5: {=_xlfn.XLOOKUP($A5&$B5&$C5,价格信息!$A:$A&价格信息!$B:$B&价格信息!$C:$C,价格信息!$D:$D)} | K5: =IF($C5="","",固定信息!$B$1) | L5: {=IF(_xlfn.XLOOKUP($A5&$B5&$C5,盘货信息!$A:$A&盘货信息!$B:$B&盘货信息!$C:$C,盘货信息!$T:$T)="","","【优惠券】领"&_xlfn.XLOOKUP($A5&$B5&$C5,盘货信息!$A:$A&盘货信息!$B:$B&盘货信息!$C:$C,盘货信息!$T:$T)&"元优惠卷下单更优惠，领券链接："&_xlfn.XLOOKUP($A5&$B5&$C5,盘货信息!$A:$A&盘货信息!$B:$B&盘货信息!$C:$C,盘货信息!$U:$U))} | M5: {=IF(_xlfn.XLOOKUP($A5&$B5&$C5,盘货信息!$A:$A&盘货信息!$B:$B&盘货信息!$C:$C,盘货信息!$P:$P)="","","【限时】"&_xlfn.XLOOKUP($A5&$B5&$C5,盘货信息!$A:$A&盘货信息!$B:$B&盘货信息!$C:$C,盘货信息!$P:$P))} | N5: {=IF(_xlfn.XLOOKUP($A5&$B5&$C5,盘货信息!$A:$A&盘货信息!$B:$B&盘货信息!$C:$C,盘货信息!$V:$V)="","","【"&盘货信息!$V$1&"】"&_xlfn.XLOOKUP($A5&$B5&$C5,盘货信息!$A:$A&盘货信息!$B:$B&盘货信息!$C:$C,盘货信息!$V:$V))} | O5: {=IF(_xlfn.XLOOKUP($A5&$B5&$C5,盘货信息!$A:$A&盘货信息!$B:$B&盘货信息!$C:$C,盘货信息!$W:$W)="","","【"&盘货信息!$W$1&"】"&_xlfn.XLOOKUP($A5&$B5&$C5,盘货信息!$A:$A&盘货信息!$B:$B&盘货信息!$C:$C,盘货信息!$W:$W))} | P5: {=IF(_xlfn.XLOOKUP($A5&$B5&$C5,盘货信息!$A:$A&盘货信息!$B:$B&盘货信息!$C:$C,盘货信息!$S:$S)<1,"","【"&盘货信息!$S$1&"】"&"后返"&_xlfn.XLOOKUP($A5&$B5&$C5,盘货信息!$A:$A&盘货信息!$B:$B&盘货信息!$C:$C,盘货信息!$S:$S)&"元")} | Q5: {=IF(_xlfn.XLOOKUP($A5&$B5&$C5,盘货信息!$A:$A&盘货信息!$B:$B&盘货信息!$C:$C,盘货信息!$X:$X)="","","【"&盘货信息!$X$1&"】"&_xlfn.XLOOKUP($A5&$B5&$C5,盘货信息!$A:$A&盘货信息!$B:$B&盘货信息!$C:$C,盘货信息!$X:$X))} | R5: {=IF(_xlfn.XLOOKUP($A5&$B5&$C5,盘货信息!$A:$A&盘货信息!$B:$B&盘货信息!$C:$C,盘货信息!$Z:$Z)="","","【"&盘货信息!$Z$1&"】"&_xlfn.XLOOKUP($A5&$B5&$C5,盘货信息!$A:$A&盘货信息!$B:$B&盘货信息!$C:$C,盘货信息!$Z:$Z))} | S5: {=IF(_xlfn.XLOOKUP($A5&$B5&$C5,盘货信息!$A:$A&盘货信息!$B:$B&盘货信息!$C:$C,盘货信息!$Q:$Q)="","","【种草】站外带指定话题种草后返"&_xlfn.XLOOKUP($A5&$B5&$C5,盘货信息!$A:$A&盘货信息!$B:$B&盘货信息!$C:$C,盘货信息!$Q:$Q)&"元红包（每个淘宝账号仅限对应一个站外种草账号，同一个种草账号不可对应多个淘宝账号）")} | T5: {=IF(_xlfn.XLOOKUP($A5&$B5&$C5,盘货信息!$A:$A&盘货信息!$B:$B&盘货信息!$C:$C,盘货信息!$R:$R)<1,"","【以旧换新】"&"享补贴"&ROUND(_xlfn.XLOOKUP($A5&$B5&$C5,盘货信息!$A:$A&盘货信息!$B:$B&盘货信息!$C:$C,盘货信息!$R:$R),0)&"元（可无旧机换新）")} | U5: =IF(AND($N5="",$O5="",$P5="",$Q5="",$R5="",$S5="",$T5=""),"",固定信息!$B$1) | V5: {=IF(_xlfn.XLOOKUP($A5&$B5&$C5,盘货信息!$A:$A&盘货信息!$B:$B&盘货信息!$C:$C,盘货信息!$Y:$Y)="","","【卡萨帝送赠】活动指定时间"&_xlfn.TEXTBEFORE(_xlfn.TEXTAFTER(_xlfn.XLOOKUP($A5&$B5&$C5,盘货信息!$A:$A&盘货信息!$B:$B&盘货信息!$C:$C,盘货信息!$Y:$Y),"点"),"（"))} | W5: {=IF(COUNTIF(_xlfn.XLOOKUP($A5&$B5&$C5,盘货信息!$A:$A&盘货信息!$B:$B&盘货信息!$C:$C,盘货信息!$O:$O),"*是*"),"【折扣】指定型号满2类享96折，满3类享94折","")} | X5: {=IF(固定信息!$B$7="","",IF(_xlfn.XLOOKUP($A5&$B5&$C5,盘货信息!$A:$A&盘货信息!$B:$B&盘货信息!$C:$C,盘货信息!$N:$N)="是","【瓜分】"&固定信息!$B$7,""))} | Y5: =IF(AND($V5="",$W5="",$X5=""),"",固定信息!$B$1) | Z5: {=IF($C5="","",_xlfn.XLOOKUP($A5&$B5&$C5,服务!$A:$A&服务!$B:$B&服务!$C:$C,服务!$D:$D))}
A6: =IF(盘货信息!A6="","",盘货信息!A6) | B6: =IF(盘货信息!B6="","",盘货信息!B6) | C6: =IF(盘货信息!C6="","",盘货信息!C6) | D6: =_xlfn.TEXTJOIN(CHAR(10),TRUE,OFFSET(INDIRECT("RC",FALSE),0,1,1,30)) | E6: =IF(C6="","",固定信息!$B$2) | F6: =IF(C6="","","【"&C6&"】"&固定信息!$B$4) | G6: =IF(C6="","","【"&"活动时间："&固定信息!$B$3&"】") | H6: =IF($C6="","",固定信息!$B$1) | I6: =IF(OR(C6="",固定信息!$B$5=""),"","【1元预约锁好礼】"&固定信息!$B$5) | J6: {=_xlfn.XLOOKUP($A6&$B6&$C6,价格信息!$A:$A&价格信息!$B:$B&价格信息!$C:$C,价格信息!$D:$D)} | K6: =IF($C6="","",固定信息!$B$1) | L6: {=IF(_xlfn.XLOOKUP($A6&$B6&$C6,盘货信息!$A:$A&盘货信息!$B:$B&盘货信息!$C:$C,盘货信息!$T:$T)="","","【优惠券】领"&_xlfn.XLOOKUP($A6&$B6&$C6,盘货信息!$A:$A&盘货信息!$B:$B&盘货信息!$C:$C,盘货信息!$T:$T)&"元优惠卷下单更优惠，领券链接："&_xlfn.XLOOKUP($A6&$B6&$C6,盘货信息!$A:$A&盘货信息!$B:$B&盘货信息!$C:$C,盘货信息!$U:$U))} | M6: {=IF(_xlfn.XLOOKUP($A6&$B6&$C6,盘货信息!$A:$A&盘货信息!$B:$B&盘货信息!$C:$C,盘货信息!$P:$P)="","","【限时】"&_xlfn.XLOOKUP($A6&$B6&$C6,盘货信息!$A:$A&盘货信息!$B:$B&盘货信息!$C:$C,盘货信息!$P:$P))} | N6: {=IF(_xlfn.XLOOKUP($A6&$B6&$C6,盘货信息!$A:$A&盘货信息!$B:$B&盘货信息!$C:$C,盘货信息!$V:$V)="","","【"&盘货信息!$V$1&"】"&_xlfn.XLOOKUP($A6&$B6&$C6,盘货信息!$A:$A&盘货信息!$B:$B&盘货信息!$C:$C,盘货信息!$V:$V))} | O6: {=IF(_xlfn.XLOOKUP($A6&$B6&$C6,盘货信息!$A:$A&盘货信息!$B:$B&盘货信息!$C:$C,盘货信息!$W:$W)="","","【"&盘货信息!$W$1&"】"&_xlfn.XLOOKUP($A6&$B6&$C6,盘货信息!$A:$A&盘货信息!$B:$B&盘货信息!$C:$C,盘货信息!$W:$W))} | P6: {=IF(_xlfn.XLOOKUP($A6&$B6&$C6,盘货信息!$A:$A&盘货信息!$B:$B&盘货信息!$C:$C,盘货信息!$S:$S)<1,"","【"&盘货信息!$S$1&"】"&"后返"&_xlfn.XLOOKUP($A6&$B6&$C6,盘货信息!$A:$A&盘货信息!$B:$B&盘货信息!$C:$C,盘货信息!$S:$S)&"元")} | Q6: {=IF(_xlfn.XLOOKUP($A6&$B6&$C6,盘货信息!$A:$A&盘货信息!$B:$B&盘货信息!$C:$C,盘货信息!$X:$X)="","","【"&盘货信息!$X$1&"】"&_xlfn.XLOOKUP($A6&$B6&$C6,盘货信息!$A:$A&盘货信息!$B:$B&盘货信息!$C:$C,盘货信息!$X:$X))} | R6: {=IF(_xlfn.XLOOKUP($A6&$B6&$C6,盘货信息!$A:$A&盘货信息!$B:$B&盘货信息!$C:$C,盘货信息!$Z:$Z)="","","【"&盘货信息!$Z$1&"】"&_xlfn.XLOOKUP($A6&$B6&$C6,盘货信息!$A:$A&盘货信息!$B:$B&盘货信息!$C:$C,盘货信息!$Z:$Z))} | S6: {=IF(_xlfn.XLOOKUP($A6&$B6&$C6,盘货信息!$A:$A&盘货信息!$B:$B&盘货信息!$C:$C,盘货信息!$Q:$Q)="","","【种草】站外带指定话题种草后返"&_xlfn.XLOOKUP($A6&$B6&$C6,盘货信息!$A:$A&盘货信息!$B:$B&盘货信息!$C:$C,盘货信息!$Q:$Q)&"元红包（每个淘宝账号仅限对应一个站外种草账号，同一个种草账号不可对应多个淘宝账号）")} | T6: {=IF(_xlfn.XLOOKUP($A6&$B6&$C6,盘货信息!$A:$A&盘货信息!$B:$B&盘货信息!$C:$C,盘货信息!$R:$R)<1,"","【以旧换新】"&"享补贴"&ROUND(_xlfn.XLOOKUP($A6&$B6&$C6,盘货信息!$A:$A&盘货信息!$B:$B&盘货信息!$C:$C,盘货信息!$R:$R),0)&"元（可无旧机换新）")} | U6: =IF(AND($N6="",$O6="",$P6="",$Q6="",$R6="",$S6="",$T6=""),"",固定信息!$B$1) | V6: {=IF(_xlfn.XLOOKUP($A6&$B6&$C6,盘货信息!$A:$A&盘货信息!$B:$B&盘货信息!$C:$C,盘货信息!$Y:$Y)="","","【卡萨帝送赠】活动指定时间"&_xlfn.TEXTBEFORE(_xlfn.TEXTAFTER(_xlfn.XLOOKUP($A6&$B6&$C6,盘货信息!$A:$A&盘货信息!$B:$B&盘货信息!$C:$C,盘货信息!$Y:$Y),"点"),"（"))} | W6: {=IF(COUNTIF(_xlfn.XLOOKUP($A6&$B6&$C6,盘货信息!$A:$A&盘货信息!$B:$B&盘货信息!$C:$C,盘货信息!$O:$O),"*是*"),"【折扣】指定型号满2类享96折，满3类享94折","")} | X6: {=IF(固定信息!$B$7="","",IF(_xlfn.XLOOKUP($A6&$B6&$C6,盘货信息!$A:$A&盘货信息!$B:$B&盘货信息!$C:$C,盘货信息!$N:$N)="是","【瓜分】"&固定信息!$B$7,""))} | Y6: =IF(AND($V6="",$W6="",$X6=""),"",固定信息!$B$1) | Z6: {=IF($C6="","",_xlfn.XLOOKUP($A6&$B6&$C6,服务!$A:$A&服务!$B:$B&服务!$C:$C,服务!$D:$D))}
A7: =IF(盘货信息!A7="","",盘货信息!A7) | B7: =IF(盘货信息!B7="","",盘货信息!B7) | C7: =IF(盘货信息!C7="","",盘货信息!C7) | D7: =_xlfn.TEXTJOIN(CHAR(10),TRUE,OFFSET(INDIRECT("RC",FALSE),0,1,1,30)) | E7: =IF(C7="","",固定信息!$B$2) | F7: =IF(C7="","","【"&C7&"】"&固定信息!$B$4) | G7: =IF(C7="","","【"&"活动时间："&固定信息!$B$3&"】") | H7: =IF($C7="","",固定信息!$B$1) | I7: =IF(OR(C7="",固定信息!$B$5=""),"","【1元预约锁好礼】"&固定信息!$B$5) | J7: {=_xlfn.XLOOKUP($A7&$B7&$C7,价格信息!$A:$A&价格信息!$B:$B&价格信息!$C:$C,价格信息!$D:$D)} | K7: =IF($C7="","",固定信息!$B$1) | L7: {=IF(_xlfn.XLOOKUP($A7&$B7&$C7,盘货信息!$A:$A&盘货信息!$B:$B&盘货信息!$C:$C,盘货信息!$T:$T)="","","【优惠券】领"&_xlfn.XLOOKUP($A7&$B7&$C7,盘货信息!$A:$A&盘货信息!$B:$B&盘货信息!$C:$C,盘货信息!$T:$T)&"元优惠卷下单更优惠，领券链接："&_xlfn.XLOOKUP($A7&$B7&$C7,盘货信息!$A:$A&盘货信息!$B:$B&盘货信息!$C:$C,盘货信息!$U:$U))} | M7: {=IF(_xlfn.XLOOKUP($A7&$B7&$C7,盘货信息!$A:$A&盘货信息!$B:$B&盘货信息!$C:$C,盘货信息!$P:$P)="","","【限时】"&_xlfn.XLOOKUP($A7&$B7&$C7,盘货信息!$A:$A&盘货信息!$B:$B&盘货信息!$C:$C,盘货信息!$P:$P))} | N7: {=IF(_xlfn.XLOOKUP($A7&$B7&$C7,盘货信息!$A:$A&盘货信息!$B:$B&盘货信息!$C:$C,盘货信息!$V:$V)="","","【"&盘货信息!$V$1&"】"&_xlfn.XLOOKUP($A7&$B7&$C7,盘货信息!$A:$A&盘货信息!$B:$B&盘货信息!$C:$C,盘货信息!$V:$V))} | O7: {=IF(_xlfn.XLOOKUP($A7&$B7&$C7,盘货信息!$A:$A&盘货信息!$B:$B&盘货信息!$C:$C,盘货信息!$W:$W)="","","【"&盘货信息!$W$1&"】"&_xlfn.XLOOKUP($A7&$B7&$C7,盘货信息!$A:$A&盘货信息!$B:$B&盘货信息!$C:$C,盘货信息!$W:$W))} | P7: {=IF(_xlfn.XLOOKUP($A7&$B7&$C7,盘货信息!$A:$A&盘货信息!$B:$B&盘货信息!$C:$C,盘货信息!$S:$S)<1,"","【"&盘货信息!$S$1&"】"&"后返"&_xlfn.XLOOKUP($A7&$B7&$C7,盘货信息!$A:$A&盘货信息!$B:$B&盘货信息!$C:$C,盘货信息!$S:$S)&"元")} | Q7: {=IF(_xlfn.XLOOKUP($A7&$B7&$C7,盘货信息!$A:$A&盘货信息!$B:$B&盘货信息!$C:$C,盘货信息!$X:$X)="","","【"&盘货信息!$X$1&"】"&_xlfn.XLOOKUP($A7&$B7&$C7,盘货信息!$A:$A&盘货信息!$B:$B&盘货信息!$C:$C,盘货信息!$X:$X))} | R7: {=IF(_xlfn.XLOOKUP($A7&$B7&$C7,盘货信息!$A:$A&盘货信息!$B:$B&盘货信息!$C:$C,盘货信息!$Z:$Z)="","","【"&盘货信息!$Z$1&"】"&_xlfn.XLOOKUP($A7&$B7&$C7,盘货信息!$A:$A&盘货信息!$B:$B&盘货信息!$C:$C,盘货信息!$Z:$Z))} | S7: {=IF(_xlfn.XLOOKUP($A7&$B7&$C7,盘货信息!$A:$A&盘货信息!$B:$B&盘货信息!$C:$C,盘货信息!$Q:$Q)="","","【种草】站外带指定话题种草后返"&_xlfn.XLOOKUP($A7&$B7&$C7,盘货信息!$A:$A&盘货信息!$B:$B&盘货信息!$C:$C,盘货信息!$Q:$Q)&"元红包（每个淘宝账号仅限对应一个站外种草账号，同一个种草账号不可对应多个淘宝账号）")} | T7: {=IF(_xlfn.XLOOKUP($A7&$B7&$C7,盘货信息!$A:$A&盘货信息!$B:$B&盘货信息!$C:$C,盘货信息!$R:$R)<1,"","【以旧换新】"&"享补贴"&ROUND(_xlfn.XLOOKUP($A7&$B7&$C7,盘货信息!$A:$A&盘货信息!$B:$B&盘货信息!$C:$C,盘货信息!$R:$R),0)&"元（可无旧机换新）")} | U7: =IF(AND($N7="",$O7="",$P7="",$Q7="",$R7="",$S7="",$T7=""),"",固定信息!$B$1) | V7: {=IF(_xlfn.XLOOKUP($A7&$B7&$C7,盘货信息!$A:$A&盘货信息!$B:$B&盘货信息!$C:$C,盘货信息!$Y:$Y)="","","【卡萨帝送赠】活动指定时间"&_xlfn.TEXTBEFORE(_xlfn.TEXTAFTER(_xlfn.XLOOKUP($A7&$B7&$C7,盘货信息!$A:$A&盘货信息!$B:$B&盘货信息!$C:$C,盘货信息!$Y:$Y),"点"),"（"))} | W7: {=IF(COUNTIF(_xlfn.XLOOKUP($A7&$B7&$C7,盘货信息!$A:$A&盘货信息!$B:$B&盘货信息!$C:$C,盘货信息!$O:$O),"*是*"),"【折扣】指定型号满2类享96折，满3类享94折","")} | X7: {=IF(固定信息!$B$7="","",IF(_xlfn.XLOOKUP($A7&$B7&$C7,盘货信息!$A:$A&盘货信息!$B:$B&盘货信息!$C:$C,盘货信息!$N:$N)="是","【瓜分】"&固定信息!$B$7,""))} | Y7: =IF(AND($V7="",$W7="",$X7=""),"",固定信息!$B$1) | Z7: {=IF($C7="","",_xlfn.XLOOKUP($A7&$B7&$C7,服务!$A:$A&服务!$B:$B&服务!$C:$C,服务!$D:$D))}
A8: =IF(盘货信息!A8="","",盘货信息!A8) | B8: =IF(盘货信息!B8="","",盘货信息!B8) | C8: =IF(盘货信息!C8="","",盘货信息!C8) | D8: =_xlfn.TEXTJOIN(CHAR(10),TRUE,OFFSET(INDIRECT("RC",FALSE),0,1,1,30)) | E8: =IF(C8="","",固定信息!$B$2) | F8: =IF(C8="","","【"&C8&"】"&固定信息!$B$4) | G8: =IF(C8="","","【"&"活动时间："&固定信息!$B$3&"】") | H8: =IF($C8="","",固定信息!$B$1) | I8: =IF(OR(C8="",固定信息!$B$5=""),"","【1元预约锁好礼】"&固定信息!$B$5) | J8: {=_xlfn.XLOOKUP($A8&$B8&$C8,价格信息!$A:$A&价格信息!$B:$B&价格信息!$C:$C,价格信息!$D:$D)} | K8: =IF($C8="","",固定信息!$B$1) | L8: {=IF(_xlfn.XLOOKUP($A8&$B8&$C8,盘货信息!$A:$A&盘货信息!$B:$B&盘货信息!$C:$C,盘货信息!$T:$T)="","","【优惠券】领"&_xlfn.XLOOKUP($A8&$B8&$C8,盘货信息!$A:$A&盘货信息!$B:$B&盘货信息!$C:$C,盘货信息!$T:$T)&"元优惠卷下单更优惠，领券链接："&_xlfn.XLOOKUP($A8&$B8&$C8,盘货信息!$A:$A&盘货信息!$B:$B&盘货信息!$C:$C,盘货信息!$U:$U))} | M8: {=IF(_xlfn.XLOOKUP($A8&$B8&$C8,盘货信息!$A:$A&盘货信息!$B:$B&盘货信息!$C:$C,盘货信息!$P:$P)="","","【限时】"&_xlfn.XLOOKUP($A8&$B8&$C8,盘货信息!$A:$A&盘货信息!$B:$B&盘货信息!$C:$C,盘货信息!$P:$P))} | N8: {=IF(_xlfn.XLOOKUP($A8&$B8&$C8,盘货信息!$A:$A&盘货信息!$B:$B&盘货信息!$C:$C,盘货信息!$V:$V)="","","【"&盘货信息!$V$1&"】"&_xlfn.XLOOKUP($A8&$B8&$C8,盘货信息!$A:$A&盘货信息!$B:$B&盘货信息!$C:$C,盘货信息!$V:$V))} | O8: {=IF(_xlfn.XLOOKUP($A8&$B8&$C8,盘货信息!$A:$A&盘货信息!$B:$B&盘货信息!$C:$C,盘货信息!$W:$W)="","","【"&盘货信息!$W$1&"】"&_xlfn.XLOOKUP($A8&$B8&$C8,盘货信息!$A:$A&盘货信息!$B:$B&盘货信息!$C:$C,盘货信息!$W:$W))} | P8: {=IF(_xlfn.XLOOKUP($A8&$B8&$C8,盘货信息!$A:$A&盘货信息!$B:$B&盘货信息!$C:$C,盘货信息!$S:$S)<1,"","【"&盘货信息!$S$1&"】"&"后返"&_xlfn.XLOOKUP($A8&$B8&$C8,盘货信息!$A:$A&盘货信息!$B:$B&盘货信息!$C:$C,盘货信息!$S:$S)&"元")} | Q8: {=IF(_xlfn.XLOOKUP($A8&$B8&$C8,盘货信息!$A:$A&盘货信息!$B:$B&盘货信息!$C:$C,盘货信息!$X:$X)="","","【"&盘货信息!$X$1&"】"&_xlfn.XLOOKUP($A8&$B8&$C8,盘货信息!$A:$A&盘货信息!$B:$B&盘货信息!$C:$C,盘货信息!$X:$X))} | R8: {=IF(_xlfn.XLOOKUP($A8&$B8&$C8,盘货信息!$A:$A&盘货信息!$B:$B&盘货信息!$C:$C,盘货信息!$Z:$Z)="","","【"&盘货信息!$Z$1&"】"&_xlfn.XLOOKUP($A8&$B8&$C8,盘货信息!$A:$A&盘货信息!$B:$B&盘货信息!$C:$C,盘货信息!$Z:$Z))} | S8: {=IF(_xlfn.XLOOKUP($A8&$B8&$C8,盘货信息!$A:$A&盘货信息!$B:$B&盘货信息!$C:$C,盘货信息!$Q:$Q)="","","【种草】站外带指定话题种草后返"&_xlfn.XLOOKUP($A8&$B8&$C8,盘货信息!$A:$A&盘货信息!$B:$B&盘货信息!$C:$C,盘货信息!$Q:$Q)&"元红包（每个淘宝账号仅限对应一个站外种草账号，同一个种草账号不可对应多个淘宝账号）")} | T8: {=IF(_xlfn.XLOOKUP($A8&$B8&$C8,盘货信息!$A:$A&盘货信息!$B:$B&盘货信息!$C:$C,盘货信息!$R:$R)<1,"","【以旧换新】"&"享补贴"&ROUND(_xlfn.XLOOKUP($A8&$B8&$C8,盘货信息!$A:$A&盘货信息!$B:$B&盘货信息!$C:$C,盘货信息!$R:$R),0)&"元（可无旧机换新）")} | U8: =IF(AND($N8="",$O8="",$P8="",$Q8="",$R8="",$S8="",$T8=""),"",固定信息!$B$1) | V8: {=IF(_xlfn.XLOOKUP($A8&$B8&$C8,盘货信息!$A:$A&盘货信息!$B:$B&盘货信息!$C:$C,盘货信息!$Y:$Y)="","","【卡萨帝送赠】活动指定时间"&_xlfn.TEXTBEFORE(_xlfn.TEXTAFTER(_xlfn.XLOOKUP($A8&$B8&$C8,盘货信息!$A:$A&盘货信息!$B:$B&盘货信息!$C:$C,盘货信息!$Y:$Y),"点"),"（"))} | W8: {=IF(COUNTIF(_xlfn.XLOOKUP($A8&$B8&$C8,盘货信息!$A:$A&盘货信息!$B:$B&盘货信息!$C:$C,盘货信息!$O:$O),"*是*"),"【折扣】指定型号满2类享96折，满3类享94折","")} | X8: {=IF(固定信息!$B$7="","",IF(_xlfn.XLOOKUP($A8&$B8&$C8,盘货信息!$A:$A&盘货信息!$B:$B&盘货信息!$C:$C,盘货信息!$N:$N)="是","【瓜分】"&固定信息!$B$7,""))} | Y8: =IF(AND($V8="",$W8="",$X8=""),"",固定信息!$B$1) | Z8: {=IF($C8="","",_xlfn.XLOOKUP($A8&$B8&$C8,服务!$A:$A&服务!$B:$B&服务!$C:$C,服务!$D:$D))}
A9: =IF(盘货信息!A9="","",盘货信息!A9) | B9: =IF(盘货信息!B9="","",盘货信息!B9) | C9: =IF(盘货信息!C9="","",盘货信息!C9) | D9: =_xlfn.TEXTJOIN(CHAR(10),TRUE,OFFSET(INDIRECT("RC",FALSE),0,1,1,30)) | E9: =IF(C9="","",固定信息!$B$2) | F9: =IF(C9="","","【"&C9&"】"&固定信息!$B$4) | G9: =IF(C9="","","【"&"活动时间："&固定信息!$B$3&"】") | H9: =IF($C9="","",固定信息!$B$1) | I9: =IF(OR(C9="",固定信息!$B$5=""),"","【1元预约锁好礼】"&固定信息!$B$5) | J9: {=_xlfn.XLOOKUP($A9&$B9&$C9,价格信息!$A:$A&价格信息!$B:$B&价格信息!$C:$C,价格信息!$D:$D)} | K9: =IF($C9="","",固定信息!$B$1) | L9: {=IF(_xlfn.XLOOKUP($A9&$B9&$C9,盘货信息!$A:$A&盘货信息!$B:$B&盘货信息!$C:$C,盘货信息!$T:$T)="","","【优惠券】领"&_xlfn.XLOOKUP($A9&$B9&$C9,盘货信息!$A:$A&盘货信息!$B:$B&盘货信息!$C:$C,盘货信息!$T:$T)&"元优惠卷下单更优惠，领券链接："&_xlfn.XLOOKUP($A9&$B9&$C9,盘货信息!$A:$A&盘货信息!$B:$B&盘货信息!$C:$C,盘货信息!$U:$U))} | M9: {=IF(_xlfn.XLOOKUP($A9&$B9&$C9,盘货信息!$A:$A&盘货信息!$B:$B&盘货信息!$C:$C,盘货信息!$P:$P)="","","【限时】"&_xlfn.XLOOKUP($A9&$B9&$C9,盘货信息!$A:$A&盘货信息!$B:$B&盘货信息!$C:$C,盘货信息!$P:$P))} | N9: {=IF(_xlfn.XLOOKUP($A9&$B9&$C9,盘货信息!$A:$A&盘货信息!$B:$B&盘货信息!$C:$C,盘货信息!$V:$V)="","","【"&盘货信息!$V$1&"】"&_xlfn.XLOOKUP($A9&$B9&$C9,盘货信息!$A:$A&盘货信息!$B:$B&盘货信息!$C:$C,盘货信息!$V:$V))} | O9: {=IF(_xlfn.XLOOKUP($A9&$B9&$C9,盘货信息!$A:$A&盘货信息!$B:$B&盘货信息!$C:$C,盘货信息!$W:$W)="","","【"&盘货信息!$W$1&"】"&_xlfn.XLOOKUP($A9&$B9&$C9,盘货信息!$A:$A&盘货信息!$B:$B&盘货信息!$C:$C,盘货信息!$W:$W))} | P9: {=IF(_xlfn.XLOOKUP($A9&$B9&$C9,盘货信息!$A:$A&盘货信息!$B:$B&盘货信息!$C:$C,盘货信息!$S:$S)<1,"","【"&盘货信息!$S$1&"】"&"后返"&_xlfn.XLOOKUP($A9&$B9&$C9,盘货信息!$A:$A&盘货信息!$B:$B&盘货信息!$C:$C,盘货信息!$S:$S)&"元")} | Q9: {=IF(_xlfn.XLOOKUP($A9&$B9&$C9,盘货信息!$A:$A&盘货信息!$B:$B&盘货信息!$C:$C,盘货信息!$X:$X)="","","【"&盘货信息!$X$1&"】"&_xlfn.XLOOKUP($A9&$B9&$C9,盘货信息!$A:$A&盘货信息!$B:$B&盘货信息!$C:$C,盘货信息!$X:$X))} | R9: {=IF(_xlfn.XLOOKUP($A9&$B9&$C9,盘货信息!$A:$A&盘货信息!$B:$B&盘货信息!$C:$C,盘货信息!$Z:$Z)="","","【"&盘货信息!$Z$1&"】"&_xlfn.XLOOKUP($A9&$B9&$C9,盘货信息!$A:$A&盘货信息!$B:$B&盘货信息!$C:$C,盘货信息!$Z:$Z))} | S9: {=IF(_xlfn.XLOOKUP($A9&$B9&$C9,盘货信息!$A:$A&盘货信息!$B:$B&盘货信息!$C:$C,盘货信息!$Q:$Q)="","","【种草】站外带指定话题种草后返"&_xlfn.XLOOKUP($A9&$B9&$C9,盘货信息!$A:$A&盘货信息!$B:$B&盘货信息!$C:$C,盘货信息!$Q:$Q)&"元红包（每个淘宝账号仅限对应一个站外种草账号，同一个种草账号不可对应多个淘宝账号）")} | T9: {=IF(_xlfn.XLOOKUP($A9&$B9&$C9,盘货信息!$A:$A&盘货信息!$B:$B&盘货信息!$C:$C,盘货信息!$R:$R)<1,"","【以旧换新】"&"享补贴"&ROUND(_xlfn.XLOOKUP($A9&$B9&$C9,盘货信息!$A:$A&盘货信息!$B:$B&盘货信息!$C:$C,盘货信息!$R:$R),0)&"元（可无旧机换新）")} | U9: =IF(AND($N9="",$O9="",$P9="",$Q9="",$R9="",$S9="",$T9=""),"",固定信息!$B$1) | V9: {=IF(_xlfn.XLOOKUP($A9&$B9&$C9,盘货信息!$A:$A&盘货信息!$B:$B&盘货信息!$C:$C,盘货信息!$Y:$Y)="","","【卡萨帝送赠】活动指定时间"&_xlfn.TEXTBEFORE(_xlfn.TEXTAFTER(_xlfn.XLOOKUP($A9&$B9&$C9,盘货信息!$A:$A&盘货信息!$B:$B&盘货信息!$C:$C,盘货信息!$Y:$Y),"点"),"（"))} | W9: {=IF(COUNTIF(_xlfn.XLOOKUP($A9&$B9&$C9,盘货信息!$A:$A&盘货信息!$B:$B&盘货信息!$C:$C,盘货信息!$O:$O),"*是*"),"【折扣】指定型号满2类享96折，满3类享94折","")} | X9: {=IF(固定信息!$B$7="","",IF(_xlfn.XLOOKUP($A9&$B9&$C9,盘货信息!$A:$A&盘货信息!$B:$B&盘货信息!$C:$C,盘货信息!$N:$N)="是","【瓜分】"&固定信息!$B$7,""))} | Y9: =IF(AND($V9="",$W9="",$X9=""),"",固定信息!$B$1) | Z9: {=IF($C9="","",_xlfn.XLOOKUP($A9&$B9&$C9,服务!$A:$A&服务!$B:$B&服务!$C:$C,服务!$D:$D))}
A10: =IF(盘货信息!A10="","",盘货信息!A10) | B10: =IF(盘货信息!B10="","",盘货信息!B10) | C10: =IF(盘货信息!C10="","",盘货信息!C10) | D10: =_xlfn.TEXTJOIN(CHAR(10),TRUE,OFFSET(INDIRECT("RC",FALSE),0,1,1,30)) | E10: =IF(C10="","",固定信息!$B$2) | F10: =IF(C10="","","【"&C10&"】"&固定信息!$B$4) | G10: =IF(C10="","","【"&"活动时间："&固定信息!$B$3&"】") | H10: =IF($C10="","",固定信息!$B$1) | I10: =IF(OR(C10="",固定信息!$B$5=""),"","【1元预约锁好礼】"&固定信息!$B$5) | J10: {=_xlfn.XLOOKUP($A10&$B10&$C10,价格信息!$A:$A&价格信息!$B:$B&价格信息!$C:$C,价格信息!$D:$D)} | K10: =IF($C10="","",固定信息!$B$1) | L10: {=IF(_xlfn.XLOOKUP($A10&$B10&$C10,盘货信息!$A:$A&盘货信息!$B:$B&盘货信息!$C:$C,盘货信息!$T:$T)="","","【优惠券】领"&_xlfn.XLOOKUP($A10&$B10&$C10,盘货信息!$A:$A&盘货信息!$B:$B&盘货信息!$C:$C,盘货信息!$T:$T)&"元优惠卷下单更优惠，领券链接："&_xlfn.XLOOKUP($A10&$B10&$C10,盘货信息!$A:$A&盘货信息!$B:$B&盘货信息!$C:$C,盘货信息!$U:$U))} | M10: {=IF(_xlfn.XLOOKUP($A10&$B10&$C10,盘货信息!$A:$A&盘货信息!$B:$B&盘货信息!$C:$C,盘货信息!$P:$P)="","","【限时】"&_xlfn.XLOOKUP($A10&$B10&$C10,盘货信息!$A:$A&盘货信息!$B:$B&盘货信息!$C:$C,盘货信息!$P:$P))} | N10: {=IF(_xlfn.XLOOKUP($A10&$B10&$C10,盘货信息!$A:$A&盘货信息!$B:$B&盘货信息!$C:$C,盘货信息!$V:$V)="","","【"&盘货信息!$V$1&"】"&_xlfn.XLOOKUP($A10&$B10&$C10,盘货信息!$A:$A&盘货信息!$B:$B&盘货信息!$C:$C,盘货信息!$V:$V))} | O10: {=IF(_xlfn.XLOOKUP($A10&$B10&$C10,盘货信息!$A:$A&盘货信息!$B:$B&盘货信息!$C:$C,盘货信息!$W:$W)="","","【"&盘货信息!$W$1&"】"&_xlfn.XLOOKUP($A10&$B10&$C10,盘货信息!$A:$A&盘货信息!$B:$B&盘货信息!$C:$C,盘货信息!$W:$W))} | P10: {=IF(_xlfn.XLOOKUP($A10&$B10&$C10,盘货信息!$A:$A&盘货信息!$B:$B&盘货信息!$C:$C,盘货信息!$S:$S)<1,"","【"&盘货信息!$S$1&"】"&"后返"&_xlfn.XLOOKUP($A10&$B10&$C10,盘货信息!$A:$A&盘货信息!$B:$B&盘货信息!$C:$C,盘货信息!$S:$S)&"元")} | Q10: {=IF(_xlfn.XLOOKUP($A10&$B10&$C10,盘货信息!$A:$A&盘货信息!$B:$B&盘货信息!$C:$C,盘货信息!$X:$X)="","","【"&盘货信息!$X$1&"】"&_xlfn.XLOOKUP($A10&$B10&$C10,盘货信息!$A:$A&盘货信息!$B:$B&盘货信息!$C:$C,盘货信息!$X:$X))} | R10: {=IF(_xlfn.XLOOKUP($A10&$B10&$C10,盘货信息!$A:$A&盘货信息!$B:$B&盘货信息!$C:$C,盘货信息!$Z:$Z)="","","【"&盘货信息!$Z$1&"】"&_xlfn.XLOOKUP($A10&$B10&$C10,盘货信息!$A:$A&盘货信息!$B:$B&盘货信息!$C:$C,盘货信息!$Z:$Z))} | S10: {=IF(_xlfn.XLOOKUP($A10&$B10&$C10,盘货信息!$A:$A&盘货信息!$B:$B&盘货信息!$C:$C,盘货信息!$Q:$Q)="","","【种草】站外带指定话题种草后返"&_xlfn.XLOOKUP($A10&$B10&$C10,盘货信息!$A:$A&盘货信息!$B:$B&盘货信息!$C:$C,盘货信息!$Q:$Q)&"元红包（每个淘宝账号仅限对应一个站外种草账号，同一个种草账号不可对应多个淘宝账号）")} | T10: {=IF(_xlfn.XLOOKUP($A10&$B10&$C10,盘货信息!$A:$A&盘货信息!$B:$B&盘货信息!$C:$C,盘货信息!$R:$R)<1,"","【以旧换新】"&"享补贴"&ROUND(_xlfn.XLOOKUP($A10&$B10&$C10,盘货信息!$A:$A&盘货信息!$B:$B&盘货信息!$C:$C,盘货信息!$R:$R),0)&"元（可无旧机换新）")} | U10: =IF(AND($N10="",$O10="",$P10="",$Q10="",$R10="",$S10="",$T10=""),"",固定信息!$B$1) | V10: {=IF(_xlfn.XLOOKUP($A10&$B10&$C10,盘货信息!$A:$A&盘货信息!$B:$B&盘货信息!$C:$C,盘货信息!$Y:$Y)="","","【卡萨帝送赠】活动指定时间"&_xlfn.TEXTBEFORE(_xlfn.TEXTAFTER(_xlfn.XLOOKUP($A10&$B10&$C10,盘货信息!$A:$A&盘货信息!$B:$B&盘货信息!$C:$C,盘货信息!$Y:$Y),"点"),"（"))} | W10: {=IF(COUNTIF(_xlfn.XLOOKUP($A10&$B10&$C10,盘货信息!$A:$A&盘货信息!$B:$B&盘货信息!$C:$C,盘货信息!$O:$O),"*是*"),"【折扣】指定型号满2类享96折，满3类享94折","")} | X10: {=IF(固定信息!$B$7="","",IF(_xlfn.XLOOKUP($A10&$B10&$C10,盘货信息!$A:$A&盘货信息!$B:$B&盘货信息!$C:$C,盘货信息!$N:$N)="是","【瓜分】"&固定信息!$B$7,""))} | Y10: =IF(AND($V10="",$W10="",$X10=""),"",固定信息!$B$1) | Z10: {=IF($C10="","",_xlfn.XLOOKUP($A10&$B10&$C10,服务!$A:$A&服务!$B:$B&服务!$C:$C,服务!$D:$D))}
A11: =IF(盘货信息!A11="","",盘货信息!A11) | B11: =IF(盘货信息!B11="","",盘货信息!B11) | C11: =IF(盘货信息!C11="","",盘货信息!C11) | D11: =_xlfn.TEXTJOIN(CHAR(10),TRUE,OFFSET(INDIRECT("RC",FALSE),0,1,1,30)) | E11: =IF(C11="","",固定信息!$B$2) | F11: =IF(C11="","","【"&C11&"】"&固定信息!$B$4) | G11: =IF(C11="","","【"&"活动时间："&固定信息!$B$3&"】") | H11: =IF($C11="","",固定信息!$B$1) | I11: =IF(OR(C11="",固定信息!$B$5=""),"","【1元预约锁好礼】"&固定信息!$B$5) | J11: {=_xlfn.XLOOKUP($A11&$B11&$C11,价格信息!$A:$A&价格信息!$B:$B&价格信息!$C:$C,价格信息!$D:$D)} | K11: =IF($C11="","",固定信息!$B$1) | L11: {=IF(_xlfn.XLOOKUP($A11&$B11&$C11,盘货信息!$A:$A&盘货信息!$B:$B&盘货信息!$C:$C,盘货信息!$T:$T)="","","【优惠券】领"&_xlfn.XLOOKUP($A11&$B11&$C11,盘货信息!$A:$A&盘货信息!$B:$B&盘货信息!$C:$C,盘货信息!$T:$T)&"元优惠卷下单更优惠，领券链接："&_xlfn.XLOOKUP($A11&$B11&$C11,盘货信息!$A:$A&盘货信息!$B:$B&盘货信息!$C:$C,盘货信息!$U:$U))} | M11: {=IF(_xlfn.XLOOKUP($A11&$B11&$C11,盘货信息!$A:$A&盘货信息!$B:$B&盘货信息!$C:$C,盘货信息!$P:$P)="","","【限时】"&_xlfn.XLOOKUP($A11&$B11&$C11,盘货信息!$A:$A&盘货信息!$B:$B&盘货信息!$C:$C,盘货信息!$P:$P))} | N11: {=IF(_xlfn.XLOOKUP($A11&$B11&$C11,盘货信息!$A:$A&盘货信息!$B:$B&盘货信息!$C:$C,盘货信息!$V:$V)="","","【"&盘货信息!$V$1&"】"&_xlfn.XLOOKUP($A11&$B11&$C11,盘货信息!$A:$A&盘货信息!$B:$B&盘货信息!$C:$C,盘货信息!$V:$V))} | O11: {=IF(_xlfn.XLOOKUP($A11&$B11&$C11,盘货信息!$A:$A&盘货信息!$B:$B&盘货信息!$C:$C,盘货信息!$W:$W)="","","【"&盘货信息!$W$1&"】"&_xlfn.XLOOKUP($A11&$B11&$C11,盘货信息!$A:$A&盘货信息!$B:$B&盘货信息!$C:$C,盘货信息!$W:$W))} | P11: {=IF(_xlfn.XLOOKUP($A11&$B11&$C11,盘货信息!$A:$A&盘货信息!$B:$B&盘货信息!$C:$C,盘货信息!$S:$S)<1,"","【"&盘货信息!$S$1&"】"&"后返"&_xlfn.XLOOKUP($A11&$B11&$C11,盘货信息!$A:$A&盘货信息!$B:$B&盘货信息!$C:$C,盘货信息!$S:$S)&"元")} | Q11: {=IF(_xlfn.XLOOKUP($A11&$B11&$C11,盘货信息!$A:$A&盘货信息!$B:$B&盘货信息!$C:$C,盘货信息!$X:$X)="","","【"&盘货信息!$X$1&"】"&_xlfn.XLOOKUP($A11&$B11&$C11,盘货信息!$A:$A&盘货信息!$B:$B&盘货信息!$C:$C,盘货信息!$X:$X))} | R11: {=IF(_xlfn.XLOOKUP($A11&$B11&$C11,盘货信息!$A:$A&盘货信息!$B:$B&盘货信息!$C:$C,盘货信息!$Z:$Z)="","","【"&盘货信息!$Z$1&"】"&_xlfn.XLOOKUP($A11&$B11&$C11,盘货信息!$A:$A&盘货信息!$B:$B&盘货信息!$C:$C,盘货信息!$Z:$Z))} | S11: {=IF(_xlfn.XLOOKUP($A11&$B11&$C11,盘货信息!$A:$A&盘货信息!$B:$B&盘货信息!$C:$C,盘货信息!$Q:$Q)="","","【种草】站外带指定话题种草后返"&_xlfn.XLOOKUP($A11&$B11&$C11,盘货信息!$A:$A&盘货信息!$B:$B&盘货信息!$C:$C,盘货信息!$Q:$Q)&"元红包（每个淘宝账号仅限对应一个站外种草账号，同一个种草账号不可对应多个淘宝账号）")} | T11: {=IF(_xlfn.XLOOKUP($A11&$B11&$C11,盘货信息!$A:$A&盘货信息!$B:$B&盘货信息!$C:$C,盘货信息!$R:$R)<1,"","【以旧换新】"&"享补贴"&ROUND(_xlfn.XLOOKUP($A11&$B11&$C11,盘货信息!$A:$A&盘货信息!$B:$B&盘货信息!$C:$C,盘货信息!$R:$R),0)&"元（可无旧机换新）")} | U11: =IF(AND($N11="",$O11="",$P11="",$Q11="",$R11="",$S11="",$T11=""),"",固定信息!$B$1) | V11: {=IF(_xlfn.XLOOKUP($A11&$B11&$C11,盘货信息!$A:$A&盘货信息!$B:$B&盘货信息!$C:$C,盘货信息!$Y:$Y)="","","【卡萨帝送赠】活动指定时间"&_xlfn.TEXTBEFORE(_xlfn.TEXTAFTER(_xlfn.XLOOKUP($A11&$B11&$C11,盘货信息!$A:$A&盘货信息!$B:$B&盘货信息!$C:$C,盘货信息!$Y:$Y),"点"),"（"))} | W11: {=IF(COUNTIF(_xlfn.XLOOKUP($A11&$B11&$C11,盘货信息!$A:$A&盘货信息!$B:$B&盘货信息!$C:$C,盘货信息!$O:$O),"*是*"),"【折扣】指定型号满2类享96折，满3类享94折","")} | X11: {=IF(固定信息!$B$7="","",IF(_xlfn.XLOOKUP($A11&$B11&$C11,盘货信息!$A:$A&盘货信息!$B:$B&盘货信息!$C:$C,盘货信息!$N:$N)="是","【瓜分】"&固定信息!$B$7,""))} | Y11: =IF(AND($V11="",$W11="",$X11=""),"",固定信息!$B$1) | Z11: {=IF($C11="","",_xlfn.XLOOKUP($A11&$B11&$C11,服务!$A:$A&服务!$B:$B&服务!$C:$C,服务!$D:$D))}
A12: =IF(盘货信息!A12="","",盘货信息!A12) | B12: =IF(盘货信息!B12="","",盘货信息!B12) | C12: =IF(盘货信息!C12="","",盘货信息!C12) | D12: =_xlfn.TEXTJOIN(CHAR(10),TRUE,OFFSET(INDIRECT("RC",FALSE),0,1,1,30)) | E12: =IF(C12="","",固定信息!$B$2) | F12: =IF(C12="","","【"&C12&"】"&固定信息!$B$4) | G12: =IF(C12="","","【"&"活动时间："&固定信息!$B$3&"】") | H12: =IF($C12="","",固定信息!$B$1) | I12: =IF(OR(C12="",固定信息!$B$5=""),"","【1元预约锁好礼】"&固定信息!$B$5) | J12: {=_xlfn.XLOOKUP($A12&$B12&$C12,价格信息!$A:$A&价格信息!$B:$B&价格信息!$C:$C,价格信息!$D:$D)} | K12: =IF($C12="","",固定信息!$B$1) | L12: {=IF(_xlfn.XLOOKUP($A12&$B12&$C12,盘货信息!$A:$A&盘货信息!$B:$B&盘货信息!$C:$C,盘货信息!$T:$T)="","","【优惠券】领"&_xlfn.XLOOKUP($A12&$B12&$C12,盘货信息!$A:$A&盘货信息!$B:$B&盘货信息!$C:$C,盘货信息!$T:$T)&"元优惠卷下单更优惠，领券链接："&_xlfn.XLOOKUP($A12&$B12&$C12,盘货信息!$A:$A&盘货信息!$B:$B&盘货信息!$C:$C,盘货信息!$U:$U))} | M12: {=IF(_xlfn.XLOOKUP($A12&$B12&$C12,盘货信息!$A:$A&盘货信息!$B:$B&盘货信息!$C:$C,盘货信息!$P:$P)="","","【限时】"&_xlfn.XLOOKUP($A12&$B12&$C12,盘货信息!$A:$A&盘货信息!$B:$B&盘货信息!$C:$C,盘货信息!$P:$P))} | N12: {=IF(_xlfn.XLOOKUP($A12&$B12&$C12,盘货信息!$A:$A&盘货信息!$B:$B&盘货信息!$C:$C,盘货信息!$V:$V)="","","【"&盘货信息!$V$1&"】"&_xlfn.XLOOKUP($A12&$B12&$C12,盘货信息!$A:$A&盘货信息!$B:$B&盘货信息!$C:$C,盘货信息!$V:$V))} | O12: {=IF(_xlfn.XLOOKUP($A12&$B12&$C12,盘货信息!$A:$A&盘货信息!$B:$B&盘货信息!$C:$C,盘货信息!$W:$W)="","","【"&盘货信息!$W$1&"】"&_xlfn.XLOOKUP($A12&$B12&$C12,盘货信息!$A:$A&盘货信息!$B:$B&盘货信息!$C:$C,盘货信息!$W:$W))} | P12: {=IF(_xlfn.XLOOKUP($A12&$B12&$C12,盘货信息!$A:$A&盘货信息!$B:$B&盘货信息!$C:$C,盘货信息!$S:$S)<1,"","【"&盘货信息!$S$1&"】"&"后返"&_xlfn.XLOOKUP($A12&$B12&$C12,盘货信息!$A:$A&盘货信息!$B:$B&盘货信息!$C:$C,盘货信息!$S:$S)&"元")} | Q12: {=IF(_xlfn.XLOOKUP($A12&$B12&$C12,盘货信息!$A:$A&盘货信息!$B:$B&盘货信息!$C:$C,盘货信息!$X:$X)="","","【"&盘货信息!$X$1&"】"&_xlfn.XLOOKUP($A12&$B12&$C12,盘货信息!$A:$A&盘货信息!$B:$B&盘货信息!$C:$C,盘货信息!$X:$X))} | R12: {=IF(_xlfn.XLOOKUP($A12&$B12&$C12,盘货信息!$A:$A&盘货信息!$B:$B&盘货信息!$C:$C,盘货信息!$Z:$Z)="","","【"&盘货信息!$Z$1&"】"&_xlfn.XLOOKUP($A12&$B12&$C12,盘货信息!$A:$A&盘货信息!$B:$B&盘货信息!$C:$C,盘货信息!$Z:$Z))} | S12: {=IF(_xlfn.XLOOKUP($A12&$B12&$C12,盘货信息!$A:$A&盘货信息!$B:$B&盘货信息!$C:$C,盘货信息!$Q:$Q)="","","【种草】站外带指定话题种草后返"&_xlfn.XLOOKUP($A12&$B12&$C12,盘货信息!$A:$A&盘货信息!$B:$B&盘货信息!$C:$C,盘货信息!$Q:$Q)&"元红包（每个淘宝账号仅限对应一个站外种草账号，同一个种草账号不可对应多个淘宝账号）")} | T12: {=IF(_xlfn.XLOOKUP($A12&$B12&$C12,盘货信息!$A:$A&盘货信息!$B:$B&盘货信息!$C:$C,盘货信息!$R:$R)<1,"","【以旧换新】"&"享补贴"&ROUND(_xlfn.XLOOKUP($A12&$B12&$C12,盘货信息!$A:$A&盘货信息!$B:$B&盘货信息!$C:$C,盘货信息!$R:$R),0)&"元（可无旧机换新）")} | U12: =IF(AND($N12="",$O12="",$P12="",$Q12="",$R12="",$S12="",$T12=""),"",固定信息!$B$1) | V12: {=IF(_xlfn.XLOOKUP($A12&$B12&$C12,盘货信息!$A:$A&盘货信息!$B:$B&盘货信息!$C:$C,盘货信息!$Y:$Y)="","","【卡萨帝送赠】活动指定时间"&_xlfn.TEXTBEFORE(_xlfn.TEXTAFTER(_xlfn.XLOOKUP($A12&$B12&$C12,盘货信息!$A:$A&盘货信息!$B:$B&盘货信息!$C:$C,盘货信息!$Y:$Y),"点"),"（"))} | W12: {=IF(COUNTIF(_xlfn.XLOOKUP($A12&$B12&$C12,盘货信息!$A:$A&盘货信息!$B:$B&盘货信息!$C:$C,盘货信息!$O:$O),"*是*"),"【折扣】指定型号满2类享96折，满3类享94折","")} | X12: {=IF(固定信息!$B$7="","",IF(_xlfn.XLOOKUP($A12&$B12&$C12,盘货信息!$A:$A&盘货信息!$B:$B&盘货信息!$C:$C,盘货信息!$N:$N)="是","【瓜分】"&固定信息!$B$7,""))} | Y12: =IF(AND($V12="",$W12="",$X12=""),"",固定信息!$B$1) | Z12: {=IF($C12="","",_xlfn.XLOOKUP($A12&$B12&$C12,服务!$A:$A&服务!$B:$B&服务!$C:$C,服务!$D:$D))}
A13: =IF(盘货信息!A13="","",盘货信息!A13) | B13: =IF(盘货信息!B13="","",盘货信息!B13) | C13: =IF(盘货信息!C13="","",盘货信息!C13) | D13: =_xlfn.TEXTJOIN(CHAR(10),TRUE,OFFSET(INDIRECT("RC",FALSE),0,1,1,30)) | E13: =IF(C13="","",固定信息!$B$2) | F13: =IF(C13="","","【"&C13&"】"&固定信息!$B$4) | G13: =IF(C13="","","【"&"活动时间："&固定信息!$B$3&"】") | H13: =IF($C13="","",固定信息!$B$1) | I13: =IF(OR(C13="",固定信息!$B$5=""),"","【1元预约锁好礼】"&固定信息!$B$5) | J13: {=_xlfn.XLOOKUP($A13&$B13&$C13,价格信息!$A:$A&价格信息!$B:$B&价格信息!$C:$C,价格信息!$D:$D)} | K13: =IF($C13="","",固定信息!$B$1) | L13: {=IF(_xlfn.XLOOKUP($A13&$B13&$C13,盘货信息!$A:$A&盘货信息!$B:$B&盘货信息!$C:$C,盘货信息!$T:$T)="","","【优惠券】领"&_xlfn.XLOOKUP($A13&$B13&$C13,盘货信息!$A:$A&盘货信息!$B:$B&盘货信息!$C:$C,盘货信息!$T:$T)&"元优惠卷下单更优惠，领券链接："&_xlfn.XLOOKUP($A13&$B13&$C13,盘货信息!$A:$A&盘货信息!$B:$B&盘货信息!$C:$C,盘货信息!$U:$U))} | M13: {=IF(_xlfn.XLOOKUP($A13&$B13&$C13,盘货信息!$A:$A&盘货信息!$B:$B&盘货信息!$C:$C,盘货信息!$P:$P)="","","【限时】"&_xlfn.XLOOKUP($A13&$B13&$C13,盘货信息!$A:$A&盘货信息!$B:$B&盘货信息!$C:$C,盘货信息!$P:$P))} | N13: {=IF(_xlfn.XLOOKUP($A13&$B13&$C13,盘货信息!$A:$A&盘货信息!$B:$B&盘货信息!$C:$C,盘货信息!$V:$V)="","","【"&盘货信息!$V$1&"】"&_xlfn.XLOOKUP($A13&$B13&$C13,盘货信息!$A:$A&盘货信息!$B:$B&盘货信息!$C:$C,盘货信息!$V:$V))} | O13: {=IF(_xlfn.XLOOKUP($A13&$B13&$C13,盘货信息!$A:$A&盘货信息!$B:$B&盘货信息!$C:$C,盘货信息!$W:$W)="","","【"&盘货信息!$W$1&"】"&_xlfn.XLOOKUP($A13&$B13&$C13,盘货信息!$A:$A&盘货信息!$B:$B&盘货信息!$C:$C,盘货信息!$W:$W))} | P13: {=IF(_xlfn.XLOOKUP($A13&$B13&$C13,盘货信息!$A:$A&盘货信息!$B:$B&盘货信息!$C:$C,盘货信息!$S:$S)<1,"","【"&盘货信息!$S$1&"】"&"后返"&_xlfn.XLOOKUP($A13&$B13&$C13,盘货信息!$A:$A&盘货信息!$B:$B&盘货信息!$C:$C,盘货信息!$S:$S)&"元")} | Q13: {=IF(_xlfn.XLOOKUP($A13&$B13&$C13,盘货信息!$A:$A&盘货信息!$B:$B&盘货信息!$C:$C,盘货信息!$X:$X)="","","【"&盘货信息!$X$1&"】"&_xlfn.XLOOKUP($A13&$B13&$C13,盘货信息!$A:$A&盘货信息!$B:$B&盘货信息!$C:$C,盘货信息!$X:$X))} | R13: {=IF(_xlfn.XLOOKUP($A13&$B13&$C13,盘货信息!$A:$A&盘货信息!$B:$B&盘货信息!$C:$C,盘货信息!$Z:$Z)="","","【"&盘货信息!$Z$1&"】"&_xlfn.XLOOKUP($A13&$B13&$C13,盘货信息!$A:$A&盘货信息!$B:$B&盘货信息!$C:$C,盘货信息!$Z:$Z))} | S13: {=IF(_xlfn.XLOOKUP($A13&$B13&$C13,盘货信息!$A:$A&盘货信息!$B:$B&盘货信息!$C:$C,盘货信息!$Q:$Q)="","","【种草】站外带指定话题种草后返"&_xlfn.XLOOKUP($A13&$B13&$C13,盘货信息!$A:$A&盘货信息!$B:$B&盘货信息!$C:$C,盘货信息!$Q:$Q)&"元红包（每个淘宝账号仅限对应一个站外种草账号，同一个种草账号不可对应多个淘宝账号）")} | T13: {=IF(_xlfn.XLOOKUP($A13&$B13&$C13,盘货信息!$A:$A&盘货信息!$B:$B&盘货信息!$C:$C,盘货信息!$R:$R)<1,"","【以旧换新】"&"享补贴"&ROUND(_xlfn.XLOOKUP($A13&$B13&$C13,盘货信息!$A:$A&盘货信息!$B:$B&盘货信息!$C:$C,盘货信息!$R:$R),0)&"元（可无旧机换新）")} | U13: =IF(AND($N13="",$O13="",$P13="",$Q13="",$R13="",$S13="",$T13=""),"",固定信息!$B$1) | V13: {=IF(_xlfn.XLOOKUP($A13&$B13&$C13,盘货信息!$A:$A&盘货信息!$B:$B&盘货信息!$C:$C,盘货信息!$Y:$Y)="","","【卡萨帝送赠】活动指定时间"&_xlfn.TEXTBEFORE(_xlfn.TEXTAFTER(_xlfn.XLOOKUP($A13&$B13&$C13,盘货信息!$A:$A&盘货信息!$B:$B&盘货信息!$C:$C,盘货信息!$Y:$Y),"点"),"（"))} | W13: {=IF(COUNTIF(_xlfn.XLOOKUP($A13&$B13&$C13,盘货信息!$A:$A&盘货信息!$B:$B&盘货信息!$C:$C,盘货信息!$O:$O),"*是*"),"【折扣】指定型号满2类享96折，满3类享94折","")} | X13: {=IF(固定信息!$B$7="","",IF(_xlfn.XLOOKUP($A13&$B13&$C13,盘货信息!$A:$A&盘货信息!$B:$B&盘货信息!$C:$C,盘货信息!$N:$N)="是","【瓜分】"&固定信息!$B$7,""))} | Y13: =IF(AND($V13="",$W13="",$X13=""),"",固定信息!$B$1) | Z13: {=IF($C13="","",_xlfn.XLOOKUP($A13&$B13&$C13,服务!$A:$A&服务!$B:$B&服务!$C:$C,服务!$D:$D))}
... A501: =IF(盘货信息!A501="","",盘货信息!A501) | B501: =IF(盘货信息!B501="","",盘货信息!B501) | C501: =IF(盘货信息!C501="","",盘货信息!C501) | D501: =_xlfn.TEXTJOIN(CHAR(10),TRUE,OFFSET(INDIRECT("RC",FALSE),0,1,1,30)) | E501: =IF(C501="","",固定信息!$B$2) | F501: =IF(C501="","","【"&C501&"】"&固定信息!$B$4) | G501: =IF(C501="","","【"&"活动时间："&固定信息!$B$3&"】") | H501: =IF($C501="","",固定信息!$B$1) | I501: =IF(OR(C501="",固定信息!$B$5=""),"","【1元预约锁好礼】"&固定信息!$B$5) | J501: {=_xlfn.XLOOKUP($A501&$B501&$C501,价格信息!$A:$A&价格信息!$B:$B&价格信息!$C:$C,价格信息!$D:$D)} | K501: =IF($C501="","",固定信息!$B$1) | L501: {=IF(_xlfn.XLOOKUP($A501&$B501&$C501,盘货信息!$A:$A&盘货信息!$B:$B&盘货信息!$C:$C,盘货信息!$T:$T)="","","【优惠券】领"&_xlfn.XLOOKUP($A501&$B501&$C501,盘货信息!$A:$A&盘货信息!$B:$B&盘货信息!$C:$C,盘货信息!$T:$T)&"元优惠卷下单更优惠，领券链接："&_xlfn.XLOOKUP($A501&$B501&$C501,盘货信息!$A:$A&盘货信息!$B:$B&盘货信息!$C:$C,盘货信息!$U:$U))} | M501: {=IF(_xlfn.XLOOKUP($A501&$B501&$C501,盘货信息!$A:$A&盘货信息!$B:$B&盘货信息!$C:$C,盘货信息!$P:$P)="","","【限时】"&_xlfn.XLOOKUP($A501&$B501&$C501,盘货信息!$A:$A&盘货信息!$B:$B&盘货信息!$C:$C,盘货信息!$P:$P))} | N501: {=IF(_xlfn.XLOOKUP($A501&$B501&$C501,盘货信息!$A:$A&盘货信息!$B:$B&盘货信息!$C:$C,盘货信息!$V:$V)="","","【"&盘货信息!$V$1&"】"&_xlfn.XLOOKUP($A501&$B501&$C501,盘货信息!$A:$A&盘货信息!$B:$B&盘货信息!$C:$C,盘货信息!$V:$V))} | O501: {=IF(_xlfn.XLOOKUP($A501&$B501&$C501,盘货信息!$A:$A&盘货信息!$B:$B&盘货信息!$C:$C,盘货信息!$W:$W)="","","【"&盘货信息!$W$1&"】"&_xlfn.XLOOKUP($A501&$B501&$C501,盘货信息!$A:$A&盘货信息!$B:$B&盘货信息!$C:$C,盘货信息!$W:$W))} | P501: {=IF(_xlfn.XLOOKUP($A501&$B501&$C501,盘货信息!$A:$A&盘货信息!$B:$B&盘货信息!$C:$C,盘货信息!$S:$S)<1,"","【"&盘货信息!$S$1&"】"&"后返"&_xlfn.XLOOKUP($A501&$B501&$C501,盘货信息!$A:$A&盘货信息!$B:$B&盘货信息!$C:$C,盘货信息!$S:$S)&"元")} | Q501: {=IF(_xlfn.XLOOKUP($A501&$B501&$C501,盘货信息!$A:$A&盘货信息!$B:$B&盘货信息!$C:$C,盘货信息!$X:$X)="","","【"&盘货信息!$X$1&"】"&_xlfn.XLOOKUP($A501&$B501&$C501,盘货信息!$A:$A&盘货信息!$B:$B&盘货信息!$C:$C,盘货信息!$X:$X))} | R501: {=IF(_xlfn.XLOOKUP($A501&$B501&$C501,盘货信息!$A:$A&盘货信息!$B:$B&盘货信息!$C:$C,盘货信息!$Z:$Z)="","","【"&盘货信息!$Z$1&"】"&_xlfn.XLOOKUP($A501&$B501&$C501,盘货信息!$A:$A&盘货信息!$B:$B&盘货信息!$C:$C,盘货信息!$Z:$Z))} | S501: {=IF(_xlfn.XLOOKUP($A501&$B501&$C501,盘货信息!$A:$A&盘货信息!$B:$B&盘货信息!$C:$C,盘货信息!$Q:$Q)="","","【种草】站外带指定话题种草后返"&_xlfn.XLOOKUP($A501&$B501&$C501,盘货信息!$A:$A&盘货信息!$B:$B&盘货信息!$C:$C,盘货信息!$Q:$Q)&"元红包（每个淘宝账号仅限对应一个站外种草账号，同一个种草账号不可对应多个淘宝账号）")} | T501: {=IF(_xlfn.XLOOKUP($A501&$B501&$C501,盘货信息!$A:$A&盘货信息!$B:$B&盘货信息!$C:$C,盘货信息!$R:$R)<1,"","【以旧换新】"&"享补贴"&ROUND(_xlfn.XLOOKUP($A501&$B501&$C501,盘货信息!$A:$A&盘货信息!$B:$B&盘货信息!$C:$C,盘货信息!$R:$R),0)&"元（可无旧机换新）")} | U501: =IF(AND($N501="",$O501="",$P501="",$Q501="",$R501="",$S501="",$T501=""),"",固定信息!$B$1) | V501: {=IF(_xlfn.XLOOKUP($A501&$B501&$C501,盘货信息!$A:$A&盘货信息!$B:$B&盘货信息!$C:$C,盘货信息!$Y:$Y)="","","【卡萨帝送赠】活动指定时间"&_xlfn.TEXTBEFORE(_xlfn.TEXTAFTER(_xlfn.XLOOKUP($A501&$B501&$C501,盘货信息!$A:$A&盘货信息!$B:$B&盘货信息!$C:$C,盘货信息!$Y:$Y),"点"),"（"))} | W501: {=IF(COUNTIF(_xlfn.XLOOKUP($A501&$B501&$C501,盘货信息!$A:$A&盘货信息!$B:$B&盘货信息!$C:$C,盘货信息!$O:$O),"*是*"),"【折扣】指定型号满2类享96折，满3类享94折","")} | X501: {=IF(固定信息!$B$7="","",IF(_xlfn.XLOOKUP($A501&$B501&$C501,盘货信息!$A:$A&盘货信息!$B:$B&盘货信息!$C:$C,盘货信息!$N:$N)="是","【瓜分】"&固定信息!$B$7,""))} | Y501: =IF(AND($V501="",$W501="",$X501=""),"",固定信息!$B$1) | Z501: {=IF($C501="","",_xlfn.XLOOKUP($A501&$B501&$C501,服务!$A:$A&服务!$B:$B&服务!$C:$C,服务!$D:$D))}

Sheet 价格信息
A1: =IF(盘货信息!A1="","",盘货信息!A1) -> ID | B1: =IF(盘货信息!B1="","",盘货信息!B1) -> skuid | C1: =IF(盘货信息!C1="","",盘货信息!C1) -> 型号 | D1: 价格 | E1: 国补后到手价 | F1: 到手价 | G1: 卡萨帝95折 | H1: 限时后返 | I1: 消费卷 | J1: 限时补贴 | K1: 国补额度 | L1: 补全国信息 | M1: 前台券 | N1: 价格2 | O1: 消费卷链接
A2: =IF(盘货信息!A2="","",盘货信息!A2) | B2: =IF(盘货信息!B2="","",盘货信息!B2) | C2: =IF(盘货信息!C2="","",盘货信息!C2) | D2: =IF($C2="","",_xlfn.TEXTJOIN(CHAR(10),TRUE,N2:O2)) | E2: {=IF($C2="","",IF(AND(OR(_xlfn.XLOOKUP($A2&$B2&$C2,盘货信息!$A:$A&盘货信息!$B:$B&盘货信息!$C:$C,盘货信息!$L:$L)="否",_xlfn.XLOOKUP($A2&$B2&$C2,盘货信息!$A:$A&盘货信息!$B:$B&盘货信息!$C:$C,盘货信息!$L:$L)=""),_xlfn.XLOOKUP($A2&$B2&$C2,盘货信息!$A:$A&盘货信息!$B:$B&盘货信息!$C:$C,盘货信息!$M:$M)="否"),"【预估到手价"&_xlfn.XLOOKUP($A2&$B2&$C2,盘货信息!$A:$A&盘货信息!$B:$B&盘货信息!$C:$C,盘货信息!$D:$D)&"元】",IF(AND(_xlfn.XLOOKUP($A2&$B2&$C2,盘货信息!$A:$A&盘货信息!$B:$B&盘货信息!$C:$C,盘货信息!$M:$M)="是",OR(_xlfn.XLOOKUP($A2&$B2&$C2,盘货信息!$A:$A&盘货信息!$B:$B&盘货信息!$C:$C,盘货信息!$L:$L)="否",_xlfn.XLOOKUP($A2&$B2&$C2,盘货信息!$A:$A&盘货信息!$B:$B&盘货信息!$C:$C,盘货信息!$L:$L)="")),"【预估到手价"&_xlfn.XLOOKUP($A2&$B2&$C2,盘货信息!$A:$A&盘货信息!$B:$B&盘货信息!$C:$C,盘货信息!$D:$D)&"元】"&CHAR(10)&"【焕新补贴预估价"&ROUND(_xlfn.XLOOKUP($A2&$B2&$C2,盘货信息!$A:$A&盘货信息!$B:$B&盘货信息!$C:$C,盘货信息!$E:$E),0)&"元】","【焕新补贴预估价"&ROUND(_xlfn.XLOOKUP($A2&$B2&$C2,盘货信息!$A:$A&盘货信息!$B:$B&盘货信息!$C:$C,盘货信息!$E:$E),0)&"元】")))} | F2: {=IF($C2="","",_xlfn.XLOOKUP($A2&$B2&$C2,盘货信息!$A:$A&盘货信息!$B:$B&盘货信息!$C:$C,盘货信息!$D:$D)&"元到手价")} | G2: {=IF($C2="","",IF(_xlfn.XLOOKUP($A2&$B2&$C2,盘货信息!$A:$A&盘货信息!$B:$B&盘货信息!$C:$C,盘货信息!$G:$G)<1,"",ROUND(_xlfn.XLOOKUP($A2&$B2&$C2,盘货信息!$A:$A&盘货信息!$B:$B&盘货信息!$C:$C,盘货信息!$G:$G),0)&"元88VIP立减"))} | H2: {=IF($C2="","",IF(_xlfn.XLOOKUP($A2&$B2&$C2,盘货信息!$A:$A&盘货信息!$B:$B&盘货信息!$C:$C,盘货信息!$I:$I)<1,"",_xlfn.XLOOKUP($A2&$B2&$C2,盘货信息!$A:$A&盘货信息!$B:$B&盘货信息!$C:$C,盘货信息!$I:$I)&"元限时后返（到货联系客服登记）"))} | I2: {=IF($C2="","",IF(_xlfn.XLOOKUP($A2&$B2&$C2,盘货信息!$A:$A&盘货信息!$B:$B&盘货信息!$C:$C,盘货信息!$H:$H)<1,"",ROUND(_xlfn.XLOOKUP($A2&$B2&$C2,盘货信息!$A:$A&盘货信息!$B:$B&盘货信息!$C:$C,盘货信息!$H:$H),0)&"元消费券"))} | J2: {=IF($C2="","",IF(_xlfn.XLOOKUP($A2&$B2&$C2,盘货信息!$A:$A&盘货信息!$B:$B&盘货信息!$C:$C,盘货信息!$J:$J)<1,"",ROUND(_xlfn.XLOOKUP($A2&$B2&$C2,盘货信息!$A:$A&盘货信息!$B:$B&盘货信息!$C:$C,盘货信息!$J:$J),0)&"元限时补贴"))} | K2: {=IF($C2="","",IF(_xlfn.XLOOKUP($A2&$B2&$C2,盘货信息!$A:$A&盘货信息!$B:$B&盘货信息!$C:$C,盘货信息!$K:$K)<1,"",ROUND(_xlfn.XLOOKUP($A2&$B2&$C2,盘货信息!$A:$A&盘货信息!$B:$B&盘货信息!$C:$C,盘货信息!$K:$K),0)&"元预估焕新补贴"))} | L2: {=IF($C2="","",IF(AND(_xlfn.XLOOKUP($A2&$B2&$C2,盘货信息!$A:$A&盘货信息!$B:$B&盘货信息!$C:$C,盘货信息!$L:$L)="是",_xlfn.XLOOKUP($A2&$B2&$C2,盘货信息!$A:$A&盘货信息!$B:$B&盘货信息!$C:$C,盘货信息!$M:$M)="是",_xlfn.XLOOKUP($A2&$B2&$C2,盘货信息!$A:$A&盘货信息!$B:$B&盘货信息!$C:$C,盘货信息!$K:$K)>0),"【全民可用，不限地址】",IF(AND(OR(_xlfn.XLOOKUP($A2&$B2&$C2,盘货信息!$A:$A&盘货信息!$B:$B&盘货信息!$C:$C,盘货信息!$L:$L)="否",_xlfn.XLOOKUP($A2&$B2&$C2,盘货信息!$A:$A&盘货信息!$B:$B&盘货信息!$C:$C,盘货信息!$L:$L)=""),_xlfn.XLOOKUP($A2&$B2&$C2,盘货信息!$A:$A&盘货信息!$B:$B&盘货信息!$C:$C,盘货信息!$M:$M)="是",_xlfn.XLOOKUP($A2&$B2&$C2,盘货信息!$A:$A&盘货信息!$B:$B&盘货信息!$C:$C,盘货信息!$K:$K)>0),"【详情页领取】","")))} | M2: {=IF($C2="","",IF(_xlfn.XLOOKUP($A2&$B2&$C2,盘货信息!$A:$A&盘货信息!$B:$B&盘货信息!$C:$C,盘货信息!$F:$F)<1,"",_xlfn.XLOOKUP($A2&$B2&$C2,盘货信息!$A:$A&盘货信息!$B:$B&盘货信息!$C:$C,盘货信息!$F:$F)&"元明卷"))} | N2: =IF(C2="","",E2&"="&F2&IF(G2="","","-"&G2)&IF(H2="","","-"&H2)&IF(I2="","","-"&I2)&IF(J2="","","-"&J2)&IF(K2="","","-"&K2&L2)) | O2: =IF(I2="","","【消费券链接】"&固定信息!$B$6)
A3: =IF(盘货信息!A3="","",盘货信息!A3) | B3: =IF(盘货信息!B3="","",盘货信息!B3) | C3: =IF(盘货信息!C3="","",盘货信息!C3) | D3: =IF($C3="","",_xlfn.TEXTJOIN(CHAR(10),TRUE,N3:O3)) | E3: {=IF($C3="","",IF(AND(OR(_xlfn.XLOOKUP($A3&$B3&$C3,盘货信息!$A:$A&盘货信息!$B:$B&盘货信息!$C:$C,盘货信息!$L:$L)="否",_xlfn.XLOOKUP($A3&$B3&$C3,盘货信息!$A:$A&盘货信息!$B:$B&盘货信息!$C:$C,盘货信息!$L:$L)=""),_xlfn.XLOOKUP($A3&$B3&$C3,盘货信息!$A:$A&盘货信息!$B:$B&盘货信息!$C:$C,盘货信息!$M:$M)="否"),"【预估到手价"&_xlfn.XLOOKUP($A3&$B3&$C3,盘货信息!$A:$A&盘货信息!$B:$B&盘货信息!$C:$C,盘货信息!$D:$D)&"元】",IF(AND(_xlfn.XLOOKUP($A3&$B3&$C3,盘货信息!$A:$A&盘货信息!$B:$B&盘货信息!$C:$C,盘货信息!$M:$M)="是",OR(_xlfn.XLOOKUP($A3&$B3&$C3,盘货信息!$A:$A&盘货信息!$B:$B&盘货信息!$C:$C,盘货信息!$L:$L)="否",_xlfn.XLOOKUP($A3&$B3&$C3,盘货信息!$A:$A&盘货信息!$B:$B&盘货信息!$C:$C,盘货信息!$L:$L)="")),"【预估到手价"&_xlfn.XLOOKUP($A3&$B3&$C3,盘货信息!$A:$A&盘货信息!$B:$B&盘货信息!$C:$C,盘货信息!$D:$D)&"元】"&CHAR(10)&"【焕新补贴预估价"&ROUND(_xlfn.XLOOKUP($A3&$B3&$C3,盘货信息!$A:$A&盘货信息!$B:$B&盘货信息!$C:$C,盘货信息!$E:$E),0)&"元】","【焕新补贴预估价"&ROUND(_xlfn.XLOOKUP($A3&$B3&$C3,盘货信息!$A:$A&盘货信息!$B:$B&盘货信息!$C:$C,盘货信息!$E:$E),0)&"元】")))} | F3: {=IF($C3="","",_xlfn.XLOOKUP($A3&$B3&$C3,盘货信息!$A:$A&盘货信息!$B:$B&盘货信息!$C:$C,盘货信息!$D:$D)&"元到手价")} | G3: {=IF($C3="","",IF(_xlfn.XLOOKUP($A3&$B3&$C3,盘货信息!$A:$A&盘货信息!$B:$B&盘货信息!$C:$C,盘货信息!$G:$G)<1,"",ROUND(_xlfn.XLOOKUP($A3&$B3&$C3,盘货信息!$A:$A&盘货信息!$B:$B&盘货信息!$C:$C,盘货信息!$G:$G),0)&"元88VIP立减"))} | H3: {=IF($C3="","",IF(_xlfn.XLOOKUP($A3&$B3&$C3,盘货信息!$A:$A&盘货信息!$B:$B&盘货信息!$C:$C,盘货信息!$I:$I)<1,"",_xlfn.XLOOKUP($A3&$B3&$C3,盘货信息!$A:$A&盘货信息!$B:$B&盘货信息!$C:$C,盘货信息!$I:$I)&"元惊喜立减"))} | I3: {=IF($C3="","",IF(_xlfn.XLOOKUP($A3&$B3&$C3,盘货信息!$A:$A&盘货信息!$B:$B&盘货信息!$C:$C,盘货信息!$H:$H)<1,"",ROUND(_xlfn.XLOOKUP($A3&$B3&$C3,盘货信息!$A:$A&盘货信息!$B:$B&盘货信息!$C:$C,盘货信息!$H:$H),0)&"元消费券"))} | J3: {=IF($C3="","",IF(_xlfn.XLOOKUP($A3&$B3&$C3,盘货信息!$A:$A&盘货信息!$B:$B&盘货信息!$C:$C,盘货信息!$J:$J)<1,"",ROUND(_xlfn.XLOOKUP($A3&$B3&$C3,盘货信息!$A:$A&盘货信息!$B:$B&盘货信息!$C:$C,盘货信息!$J:$J),0)&"元限时补贴"))} | K3: {=IF($C3="","",IF(_xlfn.XLOOKUP($A3&$B3&$C3,盘货信息!$A:$A&盘货信息!$B:$B&盘货信息!$C:$C,盘货信息!$K:$K)<1,"",ROUND(_xlfn.XLOOKUP($A3&$B3&$C3,盘货信息!$A:$A&盘货信息!$B:$B&盘货信息!$C:$C,盘货信息!$K:$K),0)&"元预估焕新补贴"))} | L3: {=IF($C3="","",IF(AND(_xlfn.XLOOKUP($A3&$B3&$C3,盘货信息!$A:$A&盘货信息!$B:$B&盘货信息!$C:$C,盘货信息!$L:$L)="是",_xlfn.XLOOKUP($A3&$B3&$C3,盘货信息!$A:$A&盘货信息!$B:$B&盘货信息!$C:$C,盘货信息!$M:$M)="是",_xlfn.XLOOKUP($A3&$B3&$C3,盘货信息!$A:$A&盘货信息!$B:$B&盘货信息!$C:$C,盘货信息!$K:$K)>0),"【全民可用，不限地址】",IF(AND(OR(_xlfn.XLOOKUP($A3&$B3&$C3,盘货信息!$A:$A&盘货信息!$B:$B&盘货信息!$C:$C,盘货信息!$L:$L)="否",_xlfn.XLOOKUP($A3&$B3&$C3,盘货信息!$A:$A&盘货信息!$B:$B&盘货信息!$C:$C,盘货信息!$L:$L)=""),_xlfn.XLOOKUP($A3&$B3&$C3,盘货信息!$A:$A&盘货信息!$B:$B&盘货信息!$C:$C,盘货信息!$M:$M)="是",_xlfn.XLOOKUP($A3&$B3&$C3,盘货信息!$A:$A&盘货信息!$B:$B&盘货信息!$C:$C,盘货信息!$K:$K)>0),"【详情页领取】","")))} | M3: {=IF($C3="","",IF(_xlfn.XLOOKUP($A3&$B3&$C3,盘货信息!$A:$A&盘货信息!$B:$B&盘货信息!$C:$C,盘货信息!$F:$F)<1,"",_xlfn.XLOOKUP($A3&$B3&$C3,盘货信息!$A:$A&盘货信息!$B:$B&盘货信息!$C:$C,盘货信息!$F:$F)&"元明卷"))} | N3: =IF(C3="","",E3&"="&F3&IF(G3="","","-"&G3)&IF(H3="","","-"&H3)&IF(I3="","","-"&I3)&IF(J3="","","-"&J3)&IF(K3="","","-"&K3&L3)) | O3: =IF(I3="","","【消费券链接】"&固定信息!$B$6)
A4: =IF(盘货信息!A4="","",盘货信息!A4) | B4: =IF(盘货信息!B4="","",盘货信息!B4) | C4: =IF(盘货信息!C4="","",盘货信息!C4) | D4: =IF($C4="","",_xlfn.TEXTJOIN(CHAR(10),TRUE,N4:O4)) | E4: {=IF($C4="","",IF(AND(OR(_xlfn.XLOOKUP($A4&$B4&$C4,盘货信息!$A:$A&盘货信息!$B:$B&盘货信息!$C:$C,盘货信息!$L:$L)="否",_xlfn.XLOOKUP($A4&$B4&$C4,盘货信息!$A:$A&盘货信息!$B:$B&盘货信息!$C:$C,盘货信息!$L:$L)=""),_xlfn.XLOOKUP($A4&$B4&$C4,盘货信息!$A:$A&盘货信息!$B:$B&盘货信息!$C:$C,盘货信息!$M:$M)="否"),"【预估到手价"&_xlfn.XLOOKUP($A4&$B4&$C4,盘货信息!$A:$A&盘货信息!$B:$B&盘货信息!$C:$C,盘货信息!$D:$D)&"元】",IF(AND(_xlfn.XLOOKUP($A4&$B4&$C4,盘货信息!$A:$A&盘货信息!$B:$B&盘货信息!$C:$C,盘货信息!$M:$M)="是",OR(_xlfn.XLOOKUP($A4&$B4&$C4,盘货信息!$A:$A&盘货信息!$B:$B&盘货信息!$C:$C,盘货信息!$L:$L)="否",_xlfn.XLOOKUP($A4&$B4&$C4,盘货信息!$A:$A&盘货信息!$B:$B&盘货信息!$C:$C,盘货信息!$L:$L)="")),"【预估到手价"&_xlfn.XLOOKUP($A4&$B4&$C4,盘货信息!$A:$A&盘货信息!$B:$B&盘货信息!$C:$C,盘货信息!$D:$D)&"元】"&CHAR(10)&"【焕新补贴预估价"&ROUND(_xlfn.XLOOKUP($A4&$B4&$C4,盘货信息!$A:$A&盘货信息!$B:$B&盘货信息!$C:$C,盘货信息!$E:$E),0)&"元】","【焕新补贴预估价"&ROUND(_xlfn.XLOOKUP($A4&$B4&$C4,盘货信息!$A:$A&盘货信息!$B:$B&盘货信息!$C:$C,盘货信息!$E:$E),0)&"元】")))} | F4: {=IF($C4="","",_xlfn.XLOOKUP($A4&$B4&$C4,盘货信息!$A:$A&盘货信息!$B:$B&盘货信息!$C:$C,盘货信息!$D:$D)&"元到手价")} | G4: {=IF($C4="","",IF(_xlfn.XLOOKUP($A4&$B4&$C4,盘货信息!$A:$A&盘货信息!$B:$B&盘货信息!$C:$C,盘货信息!$G:$G)<1,"",ROUND(_xlfn.XLOOKUP($A4&$B4&$C4,盘货信息!$A:$A&盘货信息!$B:$B&盘货信息!$C:$C,盘货信息!$G:$G),0)&"元88VIP立减"))} | H4: {=IF($C4="","",IF(_xlfn.XLOOKUP($A4&$B4&$C4,盘货信息!$A:$A&盘货信息!$B:$B&盘货信息!$C:$C,盘货信息!$I:$I)<1,"",_xlfn.XLOOKUP($A4&$B4&$C4,盘货信息!$A:$A&盘货信息!$B:$B&盘货信息!$C:$C,盘货信息!$I:$I)&"元惊喜立减"))} | I4: {=IF($C4="","",IF(_xlfn.XLOOKUP($A4&$B4&$C4,盘货信息!$A:$A&盘货信息!$B:$B&盘货信息!$C:$C,盘货信息!$H:$H)<1,"",ROUND(_xlfn.XLOOKUP($A4&$B4&$C4,盘货信息!$A:$A&盘货信息!$B:$B&盘货信息!$C:$C,盘货信息!$H:$H),0)&"元消费券"))} | J4: {=IF($C4="","",IF(_xlfn.XLOOKUP($A4&$B4&$C4,盘货信息!$A:$A&盘货信息!$B:$B&盘货信息!$C:$C,盘货信息!$J:$J)<1,"",ROUND(_xlfn.XLOOKUP($A4&$B4&$C4,盘货信息!$A:$A&盘货信息!$B:$B&盘货信息!$C:$C,盘货信息!$J:$J),0)&"元限时补贴"))} | K4: {=IF($C4="","",IF(_xlfn.XLOOKUP($A4&$B4&$C4,盘货信息!$A:$A&盘货信息!$B:$B&盘货信息!$C:$C,盘货信息!$K:$K)<1,"",ROUND(_xlfn.XLOOKUP($A4&$B4&$C4,盘货信息!$A:$A&盘货信息!$B:$B&盘货信息!$C:$C,盘货信息!$K:$K),0)&"元预估焕新补贴"))} | L4: {=IF($C4="","",IF(AND(_xlfn.XLOOKUP($A4&$B4&$C4,盘货信息!$A:$A&盘货信息!$B:$B&盘货信息!$C:$C,盘货信息!$L:$L)="是",_xlfn.XLOOKUP($A4&$B4&$C4,盘货信息!$A:$A&盘货信息!$B:$B&盘货信息!$C:$C,盘货信息!$M:$M)="是",_xlfn.XLOOKUP($A4&$B4&$C4,盘货信息!$A:$A&盘货信息!$B:$B&盘货信息!$C:$C,盘货信息!$K:$K)>0),"【全民可用，不限地址】",IF(AND(OR(_xlfn.XLOOKUP($A4&$B4&$C4,盘货信息!$A:$A&盘货信息!$B:$B&盘货信息!$C:$C,盘货信息!$L:$L)="否",_xlfn.XLOOKUP($A4&$B4&$C4,盘货信息!$A:$A&盘货信息!$B:$B&盘货信息!$C:$C,盘货信息!$L:$L)=""),_xlfn.XLOOKUP($A4&$B4&$C4,盘货信息!$A:$A&盘货信息!$B:$B&盘货信息!$C:$C,盘货信息!$M:$M)="是",_xlfn.XLOOKUP($A4&$B4&$C4,盘货信息!$A:$A&盘货信息!$B:$B&盘货信息!$C:$C,盘货信息!$K:$K)>0),"【详情页领取】","")))} | M4: {=IF($C4="","",IF(_xlfn.XLOOKUP($A4&$B4&$C4,盘货信息!$A:$A&盘货信息!$B:$B&盘货信息!$C:$C,盘货信息!$F:$F)<1,"",_xlfn.XLOOKUP($A4&$B4&$C4,盘货信息!$A:$A&盘货信息!$B:$B&盘货信息!$C:$C,盘货信息!$F:$F)&"元明卷"))} | N4: =IF(C4="","",E4&"="&F4&IF(G4="","","-"&G4)&IF(H4="","","-"&H4)&IF(I4="","","-"&I4)&IF(J4="","","-"&J4)&IF(K4="","","-"&K4&L4)) | O4: =IF(I4="","","【消费券链接】"&固定信息!$B$6)
A5: =IF(盘货信息!A5="","",盘货信息!A5) | B5: =IF(盘货信息!B5="","",盘货信息!B5) | C5: =IF(盘货信息!C5="","",盘货信息!C5) | D5: =IF($C5="","",_xlfn.TEXTJOIN(CHAR(10),TRUE,N5:O5)) | E5: {=IF($C5="","",IF(AND(OR(_xlfn.XLOOKUP($A5&$B5&$C5,盘货信息!$A:$A&盘货信息!$B:$B&盘货信息!$C:$C,盘货信息!$L:$L)="否",_xlfn.XLOOKUP($A5&$B5&$C5,盘货信息!$A:$A&盘货信息!$B:$B&盘货信息!$C:$C,盘货信息!$L:$L)=""),_xlfn.XLOOKUP($A5&$B5&$C5,盘货信息!$A:$A&盘货信息!$B:$B&盘货信息!$C:$C,盘货信息!$M:$M)="否"),"【预估到手价"&_xlfn.XLOOKUP($A5&$B5&$C5,盘货信息!$A:$A&盘货信息!$B:$B&盘货信息!$C:$C,盘货信息!$D:$D)&"元】",IF(AND(_xlfn.XLOOKUP($A5&$B5&$C5,盘货信息!$A:$A&盘货信息!$B:$B&盘货信息!$C:$C,盘货信息!$M:$M)="是",OR(_xlfn.XLOOKUP($A5&$B5&$C5,盘货信息!$A:$A&盘货信息!$B:$B&盘货信息!$C:$C,盘货信息!$L:$L)="否",_xlfn.XLOOKUP($A5&$B5&$C5,盘货信息!$A:$A&盘货信息!$B:$B&盘货信息!$C:$C,盘货信息!$L:$L)="")),"【预估到手价"&_xlfn.XLOOKUP($A5&$B5&$C5,盘货信息!$A:$A&盘货信息!$B:$B&盘货信息!$C:$C,盘货信息!$D:$D)&"元】"&CHAR(10)&"【焕新补贴预估价"&ROUND(_xlfn.XLOOKUP($A5&$B5&$C5,盘货信息!$A:$A&盘货信息!$B:$B&盘货信息!$C:$C,盘货信息!$E:$E),0)&"元】","【焕新补贴预估价"&ROUND(_xlfn.XLOOKUP($A5&$B5&$C5,盘货信息!$A:$A&盘货信息!$B:$B&盘货信息!$C:$C,盘货信息!$E:$E),0)&"元】")))} | F5: {=IF($C5="","",_xlfn.XLOOKUP($A5&$B5&$C5,盘货信息!$A:$A&盘货信息!$B:$B&盘货信息!$C:$C,盘货信息!$D:$D)&"元到手价")} | G5: {=IF($C5="","",IF(_xlfn.XLOOKUP($A5&$B5&$C5,盘货信息!$A:$A&盘货信息!$B:$B&盘货信息!$C:$C,盘货信息!$G:$G)<1,"",ROUND(_xlfn.XLOOKUP($A5&$B5&$C5,盘货信息!$A:$A&盘货信息!$B:$B&盘货信息!$C:$C,盘货信息!$G:$G),0)&"元88VIP立减"))} | H5: {=IF($C5="","",IF(_xlfn.XLOOKUP($A5&$B5&$C5,盘货信息!$A:$A&盘货信息!$B:$B&盘货信息!$C:$C,盘货信息!$I:$I)<1,"",_xlfn.XLOOKUP($A5&$B5&$C5,盘货信息!$A:$A&盘货信息!$B:$B&盘货信息!$C:$C,盘货信息!$I:$I)&"元惊喜立减"))} | I5: {=IF($C5="","",IF(_xlfn.XLOOKUP($A5&$B5&$C5,盘货信息!$A:$A&盘货信息!$B:$B&盘货信息!$C:$C,盘货信息!$H:$H)<1,"",ROUND(_xlfn.XLOOKUP($A5&$B5&$C5,盘货信息!$A:$A&盘货信息!$B:$B&盘货信息!$C:$C,盘货信息!$H:$H),0)&"元消费券"))} | J5: {=IF($C5="","",IF(_xlfn.XLOOKUP($A5&$B5&$C5,盘货信息!$A:$A&盘货信息!$B:$B&盘货信息!$C:$C,盘货信息!$J:$J)<1,"",ROUND(_xlfn.XLOOKUP($A5&$B5&$C5,盘货信息!$A:$A&盘货信息!$B:$B&盘货信息!$C:$C,盘货信息!$J:$J),0)&"元限时补贴"))} | K5: {=IF($C5="","",IF(_xlfn.XLOOKUP($A5&$B5&$C5,盘货信息!$A:$A&盘货信息!$B:$B&盘货信息!$C:$C,盘货信息!$K:$K)<1,"",ROUND(_xlfn.XLOOKUP($A5&$B5&$C5,盘货信息!$A:$A&盘货信息!$B:$B&盘货信息!$C:$C,盘货信息!$K:$K),0)&"元预估焕新补贴"))} | L5: {=IF($C5="","",IF(AND(_xlfn.XLOOKUP($A5&$B5&$C5,盘货信息!$A:$A&盘货信息!$B:$B&盘货信息!$C:$C,盘货信息!$L:$L)="是",_xlfn.XLOOKUP($A5&$B5&$C5,盘货信息!$A:$A&盘货信息!$B:$B&盘货信息!$C:$C,盘货信息!$M:$M)="是",_xlfn.XLOOKUP($A5&$B5&$C5,盘货信息!$A:$A&盘货信息!$B:$B&盘货信息!$C:$C,盘货信息!$K:$K)>0),"【全民可用，不限地址】",IF(AND(OR(_xlfn.XLOOKUP($A5&$B5&$C5,盘货信息!$A:$A&盘货信息!$B:$B&盘货信息!$C:$C,盘货信息!$L:$L)="否",_xlfn.XLOOKUP($A5&$B5&$C5,盘货信息!$A:$A&盘货信息!$B:$B&盘货信息!$C:$C,盘货信息!$L:$L)=""),_xlfn.XLOOKUP($A5&$B5&$C5,盘货信息!$A:$A&盘货信息!$B:$B&盘货信息!$C:$C,盘货信息!$M:$M)="是",_xlfn.XLOOKUP($A5&$B5&$C5,盘货信息!$A:$A&盘货信息!$B:$B&盘货信息!$C:$C,盘货信息!$K:$K)>0),"【详情页领取】","")))} | M5: {=IF($C5="","",IF(_xlfn.XLOOKUP($A5&$B5&$C5,盘货信息!$A:$A&盘货信息!$B:$B&盘货信息!$C:$C,盘货信息!$F:$F)<1,"",_xlfn.XLOOKUP($A5&$B5&$C5,盘货信息!$A:$A&盘货信息!$B:$B&盘货信息!$C:$C,盘货信息!$F:$F)&"元明卷"))} | N5: =IF(C5="","",E5&"="&F5&IF(G5="","","-"&G5)&IF(H5="","","-"&H5)&IF(I5="","","-"&I5)&IF(J5="","","-"&J5)&IF(K5="","","-"&K5&L5)) | O5: =IF(I5="","","【消费券链接】"&固定信息!$B$6)
A6: =IF(盘货信息!A6="","",盘货信息!A6) | B6: =IF(盘货信息!B6="","",盘货信息!B6) | C6: =IF(盘货信息!C6="","",盘货信息!C6) | D6: =IF($C6="","",_xlfn.TEXTJOIN(CHAR(10),TRUE,N6:O6)) | E6: {=IF($C6="","",IF(AND(OR(_xlfn.XLOOKUP($A6&$B6&$C6,盘货信息!$A:$A&盘货信息!$B:$B&盘货信息!$C:$C,盘货信息!$L:$L)="否",_xlfn.XLOOKUP($A6&$B6&$C6,盘货信息!$A:$A&盘货信息!$B:$B&盘货信息!$C:$C,盘货信息!$L:$L)=""),_xlfn.XLOOKUP($A6&$B6&$C6,盘货信息!$A:$A&盘货信息!$B:$B&盘货信息!$C:$C,盘货信息!$M:$M)="否"),"【预估到手价"&_xlfn.XLOOKUP($A6&$B6&$C6,盘货信息!$A:$A&盘货信息!$B:$B&盘货信息!$C:$C,盘货信息!$D:$D)&"元】",IF(AND(_xlfn.XLOOKUP($A6&$B6&$C6,盘货信息!$A:$A&盘货信息!$B:$B&盘货信息!$C:$C,盘货信息!$M:$M)="是",OR(_xlfn.XLOOKUP($A6&$B6&$C6,盘货信息!$A:$A&盘货信息!$B:$B&盘货信息!$C:$C,盘货信息!$L:$L)="否",_xlfn.XLOOKUP($A6&$B6&$C6,盘货信息!$A:$A&盘货信息!$B:$B&盘货信息!$C:$C,盘货信息!$L:$L)="")),"【预估到手价"&_xlfn.XLOOKUP($A6&$B6&$C6,盘货信息!$A:$A&盘货信息!$B:$B&盘货信息!$C:$C,盘货信息!$D:$D)&"元】"&CHAR(10)&"【焕新补贴预估价"&ROUND(_xlfn.XLOOKUP($A6&$B6&$C6,盘货信息!$A:$A&盘货信息!$B:$B&盘货信息!$C:$C,盘货信息!$E:$E),0)&"元】","【焕新补贴预估价"&ROUND(_xlfn.XLOOKUP($A6&$B6&$C6,盘货信息!$A:$A&盘货信息!$B:$B&盘货信息!$C:$C,盘货信息!$E:$E),0)&"元】")))} | F6: {=IF($C6="","",_xlfn.XLOOKUP($A6&$B6&$C6,盘货信息!$A:$A&盘货信息!$B:$B&盘货信息!$C:$C,盘货信息!$D:$D)&"元到手价")} | G6: {=IF($C6="","",IF(_xlfn.XLOOKUP($A6&$B6&$C6,盘货信息!$A:$A&盘货信息!$B:$B&盘货信息!$C:$C,盘货信息!$G:$G)<1,"",ROUND(_xlfn.XLOOKUP($A6&$B6&$C6,盘货信息!$A:$A&盘货信息!$B:$B&盘货信息!$C:$C,盘货信息!$G:$G),0)&"元88VIP立减"))} | H6: {=IF($C6="","",IF(_xlfn.XLOOKUP($A6&$B6&$C6,盘货信息!$A:$A&盘货信息!$B:$B&盘货信息!$C:$C,盘货信息!$I:$I)<1,"",_xlfn.XLOOKUP($A6&$B6&$C6,盘货信息!$A:$A&盘货信息!$B:$B&盘货信息!$C:$C,盘货信息!$I:$I)&"元惊喜立减"))} | I6: {=IF($C6="","",IF(_xlfn.XLOOKUP($A6&$B6&$C6,盘货信息!$A:$A&盘货信息!$B:$B&盘货信息!$C:$C,盘货信息!$H:$H)<1,"",ROUND(_xlfn.XLOOKUP($A6&$B6&$C6,盘货信息!$A:$A&盘货信息!$B:$B&盘货信息!$C:$C,盘货信息!$H:$H),0)&"元消费券"))} | J6: {=IF($C6="","",IF(_xlfn.XLOOKUP($A6&$B6&$C6,盘货信息!$A:$A&盘货信息!$B:$B&盘货信息!$C:$C,盘货信息!$J:$J)<1,"",ROUND(_xlfn.XLOOKUP($A6&$B6&$C6,盘货信息!$A:$A&盘货信息!$B:$B&盘货信息!$C:$C,盘货信息!$J:$J),0)&"元限时补贴"))} | K6: {=IF($C6="","",IF(_xlfn.XLOOKUP($A6&$B6&$C6,盘货信息!$A:$A&盘货信息!$B:$B&盘货信息!$C:$C,盘货信息!$K:$K)<1,"",ROUND(_xlfn.XLOOKUP($A6&$B6&$C6,盘货信息!$A:$A&盘货信息!$B:$B&盘货信息!$C:$C,盘货信息!$K:$K),0)&"元预估焕新补贴"))} | L6: {=IF($C6="","",IF(AND(_xlfn.XLOOKUP($A6&$B6&$C6,盘货信息!$A:$A&盘货信息!$B:$B&盘货信息!$C:$C,盘货信息!$L:$L)="是",_xlfn.XLOOKUP($A6&$B6&$C6,盘货信息!$A:$A&盘货信息!$B:$B&盘货信息!$C:$C,盘货信息!$M:$M)="是",_xlfn.XLOOKUP($A6&$B6&$C6,盘货信息!$A:$A&盘货信息!$B:$B&盘货信息!$C:$C,盘货信息!$K:$K)>0),"【全民可用，不限地址】",IF(AND(OR(_xlfn.XLOOKUP($A6&$B6&$C6,盘货信息!$A:$A&盘货信息!$B:$B&盘货信息!$C:$C,盘货信息!$L:$L)="否",_xlfn.XLOOKUP($A6&$B6&$C6,盘货信息!$A:$A&盘货信息!$B:$B&盘货信息!$C:$C,盘货信息!$L:$L)=""),_xlfn.XLOOKUP($A6&$B6&$C6,盘货信息!$A:$A&盘货信息!$B:$B&盘货信息!$C:$C,盘货信息!$M:$M)="是",_xlfn.XLOOKUP($A6&$B6&$C6,盘货信息!$A:$A&盘货信息!$B:$B&盘货信息!$C:$C,盘货信息!$K:$K)>0),"【详情页领取】","")))} | M6: {=IF($C6="","",IF(_xlfn.XLOOKUP($A6&$B6&$C6,盘货信息!$A:$A&盘货信息!$B:$B&盘货信息!$C:$C,盘货信息!$F:$F)<1,"",_xlfn.XLOOKUP($A6&$B6&$C6,盘货信息!$A:$A&盘货信息!$B:$B&盘货信息!$C:$C,盘货信息!$F:$F)&"元明卷"))} | N6: =IF(C6="","",E6&"="&F6&IF(G6="","","-"&G6)&IF(H6="","","-"&H6)&IF(I6="","","-"&I6)&IF(J6="","","-"&J6)&IF(K6="","","-"&K6&L6)) | O6: =IF(I6="","","【消费券链接】"&固定信息!$B$6)
