Workbook

Sheet 盘货信息
A1: ID | B1: SKUID | C1: 型号 | D1: 细分品类 | E1: 到手价 | F1: 最低保价到手价 | G1: 是否参加焕新补贴-真国补 | H1: 自补补全国-最新 | I1: 88vip立减 | J1: 优惠券-明券 | K1: 以旧换新 | L1: 限时补贴 | M1: 主图打标额度 | N1: 焕新补贴&以旧换新到手价-客服话术 卡萨帝型号为88vip用户到手价 | O1: 客服权益-客服暗券 （首响话术透出，领券链接做进话术，与店铺任何优惠券不叠加，包括直播券、商品券、店铺券、淘客券，话术漏出金额大的券） | P1: 客服端券链接 | Q1: 会员红包 | R1: 优惠券（金额） | S1: 赠品 | T1: 瓜分 | U1: 持续玩法-跨品类折扣 | V1: 分期免息（X期） | W1: 价保 | X1: 持续玩法-领券 | Y1: 淘客券 | Z1: 优惠券短链

Sheet 固定信息
A1: 分隔符 | B1: —————————————
A2: 活动氛围
A3: 活动时间
A4: 产业
A5: 1元预约链接
A6: 消费券链接
A7: 瓜分信息

Sheet 促销信息
A1: =IF(盘货信息!A1="","",盘货信息!A1) -> ID | B1: =IF(盘货信息!B1="","",盘货信息!B1) -> SKUID | C1: =IF(盘货信息!C1="","",盘货信息!C1) -> 型号 | D1: 促销信息 | E1: 活动氛围 | F1: 型号+产业 | G1: 活动时间 | H1: 分割线 | I1: 1元预约 | J1: 价格 | K1: 优惠券（金额） | L1: 分割线 | M1: 客服暗券 | N1: 88vip95折 | O1: 以旧换新 | P1: 赠品 | Q1: 分割线 | R1: 跨品折扣 | S1: 会员全店红包 | T1: 瓜分 | U1: 分割线 | V1: 服务
A2: =IF(盘货信息!A2="","",盘货信息!A2) | B2: =IF(盘货信息!B2="","",盘货信息!B2) | C2: =IF(盘货信息!C2="","",盘货信息!C2) | D2: =_xlfn.TEXTJOIN(CHAR(10),TRUE,OFFSET(INDIRECT("RC",FALSE),0,1,1,30)) | E2: =IF(C2="","",固定信息!$B$2) | F2: {=IF(C2="","","【"&C2&"】"&_xlfn.XLOOKUP(A2&B2&C2,盘货信息!$A:$A&盘货信息!$B:$B&盘货信息!$C:$C,盘货信息!$D:$D))} | G2: =IF(C2="","","【"&"活动时间："&固定信息!$B$3&"】") | H2: =IF($C2="","",固定信息!$B$1) | J2: {=_xlfn.XLOOKUP(A2&B2&C2,价格信息!$A:$A&价格信息!$B:$B&价格信息!$C:$C,价格信息!$D:$D)} | K2: {=IF(_xlfn.XLOOKUP(A2&B2&C2,价格信息!$A:$A&价格信息!$B:$B&价格信息!$C:$C,价格信息!$I:$I)="","","【优惠券链接】"&固定信息!$B$6)} | L2: =IF($C2="","",固定信息!$B$1) | M2: {=IF(_xlfn.XLOOKUP(A2&B2&C2,盘货信息!$A:$A&盘货信息!$B:$B&盘货信息!$C:$C,盘货信息!$O:$O)="","","【优惠券】领"&INDEX(_wpsfn.REGEXP(_xlfn.XLOOKUP(A2&B2&C2,盘货信息!$A:$A&盘货信息!$B:$B&盘货信息!$C:$C,盘货信息!$O:$O),"\d+"),1,1)&"元优惠券下单更优惠，优惠卷："&_xlfn.XLOOKUP(A2&B2&C2,盘货信息!$A:$A&盘货信息!$B:$B&盘货信息!$C:$C,盘货信息!$P:$P))} | N2: {=IF(AND(ISNUMBER(_xlfn.XLOOKUP(A2&B2&C2,盘货信息!$A:$A&盘货信息!$B:$B&盘货信息!$C:$C,盘货信息!$I:$I)),_xlfn.XLOOKUP(A2&B2&C2,盘货信息!$A:$A&盘货信息!$B:$B&盘货信息!$C:$C,盘货信息!$I:$I)>1),"【88VIP】立减"&_xlfn.XLOOKUP(A2&B2&C2,盘货信息!$A:$A&盘货信息!$B:$B&盘货信息!$C:$C,盘货信息!$I:$I)&"元","")} | O2: {=IF(_xlfn.XLOOKUP(A2&B2&C2,盘货信息!$A:$A&盘货信息!$B:$B&盘货信息!$C:$C,盘货信息!$K:$K)="","",IF(AND(_xlfn.XLOOKUP(A2&B2&C2,盘货信息!$A:$A&盘货信息!$B:$B&盘货信息!$C:$C,盘货信息!$G:$G)="不参加",_xlfn.XLOOKUP(A2&B2&C2,盘货信息!$A:$A&盘货信息!$B:$B&盘货信息!$C:$C,盘货信息!$H:$H)=""),"【以旧换新】"&_xlfn.XLOOKUP(A2&B2&C2,盘货信息!$A:$A&盘货信息!$B:$B&盘货信息!$C:$C,盘货信息!$K:$K)&"元以旧换新补贴（可无旧机换新）",""))} | P2: {=_xlfn.XLOOKUP(A2&B2&C2,赠品!$A:$A&赠品!$B:$B&赠品!$C:$C,赠品!$D:$D)} | Q2: =IF($C2="","",IF(AND(M2="",N2="",P2=""),"",固定信息!$B$1)) | R2: {=IF(ISNUMBER(SEARCH("是",_xlfn.XLOOKUP(A2&B2&C2,盘货信息!$A:$A&盘货信息!$B:$B&盘货信息!$C:$C,盘货信息!$U:$U))),"【折扣】指定型号满2类享96折，满3类享94折","")} | S2: {=IF(_xlfn.XLOOKUP(A2&B2&C2,盘货信息!$A:$A&盘货信息!$B:$B&盘货信息!$C:$C,盘货信息!$Q:$Q)<1,"","【红包】活动时间购机送"&_xlfn.TEXTJOIN("",,IF(ISNUMBER(--MID(_xlfn.XLOOKUP(A2&B2&C2,盘货信息!$A:$A&盘货信息!$B:$B&盘货信息!$C:$C,盘货信息!$Q:$Q),_xlfn.SEQUENCE(LEN(_xlfn.XLOOKUP(A2&B2&C2,盘货信息!$A:$A&盘货信息!$B:$B&盘货信息!$C:$C,盘货信息!$Q:$Q))),1)),MID(_xlfn.XLOOKUP(A2&B2&C2,盘货信息!$A:$A&盘货信息!$B:$B&盘货信息!$C:$C,盘货信息!$Q:$Q),_xlfn.SEQUENCE(LEN(_xlfn.XLOOKUP(A2&B2&C2,盘货信息!$A:$A&盘货信息!$B:$B&盘货信息!$C:$C,盘货信息!$Q:$Q))),1),""))&"元")} | T2: {=IF(ISNUMBER(SEARCH("是",_xlfn.XLOOKUP(A2&B2&C2,盘货信息!$A:$A&盘货信息!$B:$B&盘货信息!$C:$C,盘货信息!$T:$T))),"【瓜分】"&固定信息!$B$7,"")} | U2: =IF($C2="","",IF(AND(R2="",S2="",T2=""),"",固定信息!$B$1)) | V2: {=IF(C2="","","【服务】"&IF(_xlfn.XLOOKUP(A2&B2&C2,盘货信息!$A:$A&盘货信息!$B:$B&盘货信息!$C:$C,盘货信息!$V:$V)="","",_xlfn.XLOOKUP(A2&B2&C2,盘货信息!$A:$A&盘货信息!$B:$B&盘货信息!$C:$C,盘货信息!$V:$V)&"免息,")&IF(_xlfn.XLOOKUP(A2&B2&C2,盘货信息!$A:$A&盘货信息!$B:$B&盘货信息!$C:$C,盘货信息!$W:$W)="","",_xlfn.XLOOKUP(A2&B2&C2,盘货信息!$A:$A&盘货信息!$B:$B&盘货信息!$C:$C,盘货信息!$W:$W)&"，")&"送货入户，退换免运费")}
A3: =IF(盘货信息!A3="","",盘货信息!A3) | B3: =IF(盘货信息!B3="","",盘货信息!B3) | C3: =IF(盘货信息!C3="","",盘货信息!C3) | D3: =_xlfn.TEXTJOIN(CHAR(10),TRUE,OFFSET(INDIRECT("RC",FALSE),0,1,1,30)) | E3: =IF(C3="","",固定信息!$B$2) | F3: {=IF(C3="","","【"&C3&"】"&_xlfn.XLOOKUP(A3&B3&C3,盘货信息!$A:$A&盘货信息!$B:$B&盘货信息!$C:$C,盘货信息!$D:$D))} | G3: =IF(C3="","","【"&"活动时间："&固定信息!$B$3&"】") | H3: =IF($C3="","",固定信息!$B$1) | J3: {=_xlfn.XLOOKUP(A3&B3&C3,价格信息!$A:$A&价格信息!$B:$B&价格信息!$C:$C,价格信息!$D:$D)} | K3: {=IF(_xlfn.XLOOKUP(A3&B3&C3,价格信息!$A:$A&价格信息!$B:$B&价格信息!$C:$C,价格信息!$I:$I)="","","【优惠券链接】"&固定信息!$B$6)} | L3: =IF($C3="","",固定信息!$B$1) | M3: {=IF(_xlfn.XLOOKUP(A3&B3&C3,盘货信息!$A:$A&盘货信息!$B:$B&盘货信息!$C:$C,盘货信息!$O:$O)="","","【优惠券】领"&INDEX(_wpsfn.REGEXP(_xlfn.XLOOKUP(A3&B3&C3,盘货信息!$A:$A&盘货信息!$B:$B&盘货信息!$C:$C,盘货信息!$O:$O),"\d+"),1,1)&"元优惠券下单更优惠，优惠卷："&_xlfn.XLOOKUP(A3&B3&C3,盘货信息!$A:$A&盘货信息!$B:$B&盘货信息!$C:$C,盘货信息!$P:$P))} | N3: {=IF(AND(ISNUMBER(_xlfn.XLOOKUP(A3&B3&C3,盘货信息!$A:$A&盘货信息!$B:$B&盘货信息!$C:$C,盘货信息!$I:$I)),_xlfn.XLOOKUP(A3&B3&C3,盘货信息!$A:$A&盘货信息!$B:$B&盘货信息!$C:$C,盘货信息!$I:$I)>1),"【88VIP】立减"&_xlfn.XLOOKUP(A3&B3&C3,盘货信息!$A:$A&盘货信息!$B:$B&盘货信息!$C:$C,盘货信息!$I:$I)&"元","")} | O3: {=IF(_xlfn.XLOOKUP(A3&B3&C3,盘货信息!$A:$A&盘货信息!$B:$B&盘货信息!$C:$C,盘货信息!$K:$K)="","",IF(AND(_xlfn.XLOOKUP(A3&B3&C3,盘货信息!$A:$A&盘货信息!$B:$B&盘货信息!$C:$C,盘货信息!$G:$G)="不参加",_xlfn.XLOOKUP(A3&B3&C3,盘货信息!$A:$A&盘货信息!$B:$B&盘货信息!$C:$C,盘货信息!$H:$H)=""),"【以旧换新】"&_xlfn.XLOOKUP(A3&B3&C3,盘货信息!$A:$A&盘货信息!$B:$B&盘货信息!$C:$C,盘货信息!$K:$K)&"元以旧换新补贴（可无旧机换新）",""))} | P3: {=_xlfn.XLOOKUP(A3&B3&C3,赠品!$A:$A&赠品!$B:$B&赠品!$C:$C,赠品!$D:$D)} | Q3: =IF($C3="","",IF(AND(M3="",N3="",P3=""),"",固定信息!$B$1)) | R3: {=IF(ISNUMBER(SEARCH("是",_xlfn.XLOOKUP(A3&B3&C3,盘货信息!$A:$A&盘货信息!$B:$B&盘货信息!$C:$C,盘货信息!$U:$U))),"【折扣】指定型号满2类享96折，满3类享94折","")} | S3: {=IF(_xlfn.XLOOKUP(A3&B3&C3,盘货信息!$A:$A&盘货信息!$B:$B&盘货信息!$C:$C,盘货信息!$Q:$Q)<1,"","【红包】活动时间购机送"&_xlfn.TEXTJOIN("",,IF(ISNUMBER(--MID(_xlfn.XLOOKUP(A3&B3&C3,盘货信息!$A:$A&盘货信息!$B:$B&盘货信息!$C:$C,盘货信息!$Q:$Q),_xlfn.SEQUENCE(LEN(_xlfn.XLOOKUP(A3&B3&C3,盘货信息!$A:$A&盘货信息!$B:$B&盘货信息!$C:$C,盘货信息!$Q:$Q))),1)),MID(_xlfn.XLOOKUP(A3&B3&C3,盘货信息!$A:$A&盘货信息!$B:$B&盘货信息!$C:$C,盘货信息!$Q:$Q),_xlfn.SEQUENCE(LEN(_xlfn.XLOOKUP(A3&B3&C3,盘货信息!$A:$A&盘货信息!$B:$B&盘货信息!$C:$C,盘货信息!$Q:$Q))),1),""))&"元")} | T3: {=IF(ISNUMBER(SEARCH("是",_xlfn.XLOOKUP(A3&B3&C3,盘货信息!$A:$A&盘货信息!$B:$B&盘货信息!$C:$C,盘货信息!$T:$T))),"【瓜分】"&固定信息!$B$7,"")} | U3: =IF($C3="","",IF(AND(R3="",S3="",T3=""),"",固定信息!$B$1)) | V3: {=IF(C3="","","【服务】"&IF(_xlfn.XLOOKUP(A3&B3&C3,盘货信息!$A:$A&盘货信息!$B:$B&盘货信息!$C:$C,盘货信息!$V:$V)="","",_xlfn.XLOOKUP(A3&B3&C3,盘货信息!$A:$A&盘货信息!$B:$B&盘货信息!$C:$C,盘货信息!$V:$V)&"免息,")&IF(_xlfn.XLOOKUP(A3&B3&C3,盘货信息!$A:$A&盘货信息!$B:$B&盘货信息!$C:$C,盘货信息!$W:$W)="","",_xlfn.XLOOKUP(A3&B3&C3,盘货信息!$A:$A&盘货信息!$B:$B&盘货信息!$C:$C,盘货信息!$W:$W)&"，")&"送货入户，退换免运费")}
A4: =IF(盘货信息!A4="","",盘货信息!A4) | B4: =IF(盘货信息!B4="","",盘货信息!B4) | C4: =IF(盘货信息!C4="","",盘货信息!C4) | D4: =_xlfn.TEXTJOIN(CHAR(10),TRUE,OFFSET(INDIRECT("RC",FALSE),0,1,1,30)) | E4: =IF(C4="","",固定信息!$B$2) | F4: {=IF(C4="","","【"&C4&"】"&_xlfn.XLOOKUP(A4&B4&C4,盘货信息!$A:$A&盘货信息!$B:$B&盘货信息!$C:$C,盘货信息!$D:$D))} | G4: =IF(C4="","","【"&"活动时间："&固定信息!$B$3&"】") | H4: =IF($C4="","",固定信息!$B$1) | J4: {=_xlfn.XLOOKUP(A4&B4&C4,价格信息!$A:$A&价格信息!$B:$B&价格信息!$C:$C,价格信息!$D:$D)} | K4: {=IF(_xlfn.XLOOKUP(A4&B4&C4,价格信息!$A:$A&价格信息!$B:$B&价格信息!$C:$C,价格信息!$I:$I)="","","【优惠券链接】"&固定信息!$B$6)} | L4: =IF($C4="","",固定信息!$B$1) | M4: {=IF(_xlfn.XLOOKUP(A4&B4&C4,盘货信息!$A:$A&盘货信息!$B:$B&盘货信息!$C:$C,盘货信息!$O:$O)="","","【优惠券】领"&INDEX(_wpsfn.REGEXP(_xlfn.XLOOKUP(A4&B4&C4,盘货信息!$A:$A&盘货信息!$B:$B&盘货信息!$C:$C,盘货信息!$O:$O),"\d+"),1,1)&"元优惠券下单更优惠，优惠卷："&_xlfn.XLOOKUP(A4&B4&C4,盘货信息!$A:$A&盘货信息!$B:$B&盘货信息!$C:$C,盘货信息!$P:$P))} | N4: {=IF(AND(ISNUMBER(_xlfn.XLOOKUP(A4&B4&C4,盘货信息!$A:$A&盘货信息!$B:$B&盘货信息!$C:$C,盘货信息!$I:$I)),_xlfn.XLOOKUP(A4&B4&C4,盘货信息!$A:$A&盘货信息!$B:$B&盘货信息!$C:$C,盘货信息!$I:$I)>1),"【88VIP】立减"&_xlfn.XLOOKUP(A4&B4&C4,盘货信息!$A:$A&盘货信息!$B:$B&盘货信息!$C:$C,盘货信息!$I:$I)&"元","")} | O4: {=IF(_xlfn.XLOOKUP(A4&B4&C4,盘货信息!$A:$A&盘货信息!$B:$B&盘货信息!$C:$C,盘货信息!$K:$K)="","",IF(AND(_xlfn.XLOOKUP(A4&B4&C4,盘货信息!$A:$A&盘货信息!$B:$B&盘货信息!$C:$C,盘货信息!$G:$G)="不参加",_xlfn.XLOOKUP(A4&B4&C4,盘货信息!$A:$A&盘货信息!$B:$B&盘货信息!$C:$C,盘货信息!$H:$H)=""),"【以旧换新】"&_xlfn.XLOOKUP(A4&B4&C4,盘货信息!$A:$A&盘货信息!$B:$B&盘货信息!$C:$C,盘货信息!$K:$K)&"元以旧换新补贴（可无旧机换新）",""))} | P4: {=_xlfn.XLOOKUP(A4&B4&C4,赠品!$A:$A&赠品!$B:$B&赠品!$C:$C,赠品!$D:$D)} | Q4: =IF($C4="","",IF(AND(M4="",N4="",P4=""),"",固定信息!$B$1)) | R4: {=IF(ISNUMBER(SEARCH("是",_xlfn.XLOOKUP(A4&B4&C4,盘货信息!$A:$A&盘货信息!$B:$B&盘货信息!$C:$C,盘货信息!$U:$U))),"【折扣】指定型号满2类享96折，满3类享94折","")} | S4: {=IF(_xlfn.XLOOKUP(A4&B4&C4,盘货信息!$A:$A&盘货信息!$B:$B&盘货信息!$C:$C,盘货信息!$Q:$Q)<1,"","【红包】活动时间购机送"&_xlfn.TEXTJOIN("",,IF(ISNUMBER(--MID(_xlfn.XLOOKUP(A4&B4&C4,盘货信息!$A:$A&盘货信息!$B:$B&盘货信息!$C:$C,盘货信息!$Q:$Q),_xlfn.SEQUENCE(LEN(_xlfn.XLOOKUP(A4&B4&C4,盘货信息!$A:$A&盘货信息!$B:$B&盘货信息!$C:$C,盘货信息!$Q:$Q))),1)),MID(_xlfn.XLOOKUP(A4&B4&C4,盘货信息!$A:$A&盘货信息!$B:$B&盘货信息!$C:$C,盘货信息!$Q:$Q),_xlfn.SEQUENCE(LEN(_xlfn.XLOOKUP(A4&B4&C4,盘货信息!$A:$A&盘货信息!$B:$B&盘货信息!$C:$C,盘货信息!$Q:$Q))),1),""))&"元")} | T4: {=IF(ISNUMBER(SEARCH("是",_xlfn.XLOOKUP(A4&B4&C4,盘货信息!$A:$A&盘货信息!$B:$B&盘货信息!$C:$C,盘货信息!$T:$T))),"【瓜分】"&固定信息!$B$7,"")} | U4: =IF($C4="","",IF(AND(R4="",S4="",T4=""),"",固定信息!$B$1)) | V4: {=IF(C4="","","【服务】"&IF(_xlfn.XLOOKUP(A4&B4&C4,盘货信息!$A:$A&盘货信息!$B:$B&盘货信息!$C:$C,盘货信息!$V:$V)="","",_xlfn.XLOOKUP(A4&B4&C4,盘货信息!$A:$A&盘货信息!$B:$B&盘货信息!$C:$C,盘货信息!$V:$V)&"免息,")&IF(_xlfn.XLOOKUP(A4&B4&C4,盘货信息!$A:$A&盘货信息!$B:$B&盘货信息!$C:$C,盘货信息!$W:$W)="","",_xlfn.XLOOKUP(A4&B4&C4,盘货信息!$A:$A&盘货信息!$B:$B&盘货信息!$C:$C,盘货信息!$W:$W)&"，")&"送货入户，退换免运费")}
A5: =IF(盘货信息!A5="","",盘货信息!A5) | B5: =IF(盘货信息!B5="","",盘货信息!B5) | C5: =IF(盘货信息!C5="","",盘货信息!C5) | D5: =_xlfn.TEXTJOIN(CHAR(10),TRUE,OFFSET(INDIRECT("RC",FALSE),0,1,1,30)) | E5: =IF(C5="","",固定信息!$B$2) | F5: {=IF(C5="","","【"&C5&"】"&_xlfn.XLOOKUP(A5&B5&C5,盘货信息!$A:$A&盘货信息!$B:$B&盘货信息!$C:$C,盘货信息!$D:$D))} | G5: =IF(C5="","","【"&"活动时间："&固定信息!$B$3&"】") | H5: =IF($C5="","",固定信息!$B$1) | J5: {=_xlfn.XLOOKUP(A5&B5&C5,价格信息!$A:$A&价格信息!$B:$B&价格信息!$C:$C,价格信息!$D:$D)} | K5: {=IF(_xlfn.XLOOKUP(A5&B5&C5,价格信息!$A:$A&价格信息!$B:$B&价格信息!$C:$C,价格信息!$I:$I)="","","【优惠券链接】"&固定信息!$B$6)} | L5: =IF($C5="","",固定信息!$B$1) | M5: {=IF(_xlfn.XLOOKUP(A5&B5&C5,盘货信息!$A:$A&盘货信息!$B:$B&盘货信息!$C:$C,盘货信息!$O:$O)="","","【优惠券】领"&INDEX(_wpsfn.REGEXP(_xlfn.XLOOKUP(A5&B5&C5,盘货信息!$A:$A&盘货信息!$B:$B&盘货信息!$C:$C,盘货信息!$O:$O),"\d+"),1,1)&"元优惠券下单更优惠，优惠卷："&_xlfn.XLOOKUP(A5&B5&C5,盘货信息!$A:$A&盘货信息!$B:$B&盘货信息!$C:$C,盘货信息!$P:$P))} | N5: {=IF(AND(ISNUMBER(_xlfn.XLOOKUP(A5&B5&C5,盘货信息!$A:$A&盘货信息!$B:$B&盘货信息!$C:$C,盘货信息!$I:$I)),_xlfn.XLOOKUP(A5&B5&C5,盘货信息!$A:$A&盘货信息!$B:$B&盘货信息!$C:$C,盘货信息!$I:$I)>1),"【88VIP】立减"&_xlfn.XLOOKUP(A5&B5&C5,盘货信息!$A:$A&盘货信息!$B:$B&盘货信息!$C:$C,盘货信息!$I:$I)&"元","")} | O5: {=IF(_xlfn.XLOOKUP(A5&B5&C5,盘货信息!$A:$A&盘货信息!$B:$B&盘货信息!$C:$C,盘货信息!$K:$K)="","",IF(AND(_xlfn.XLOOKUP(A5&B5&C5,盘货信息!$A:$A&盘货信息!$B:$B&盘货信息!$C:$C,盘货信息!$G:$G)="不参加",_xlfn.XLOOKUP(A5&B5&C5,盘货信息!$A:$A&盘货信息!$B:$B&盘货信息!$C:$C,盘货信息!$H:$H)=""),"【以旧换新】"&_xlfn.XLOOKUP(A5&B5&C5,盘货信息!$A:$A&盘货信息!$B:$B&盘货信息!$C:$C,盘货信息!$K:$K)&"元以旧换新补贴（可无旧机换新）",""))} | P5: {=_xlfn.XLOOKUP(A5&B5&C5,赠品!$A:$A&赠品!$B:$B&赠品!$C:$C,赠品!$D:$D)} | Q5: =IF($C5="","",IF(AND(M5="",N5="",P5=""),"",固定信息!$B$1)) | R5: {=IF(ISNUMBER(SEARCH("是",_xlfn.XLOOKUP(A5&B5&C5,盘货信息!$A:$A&盘货信息!$B:$B&盘货信息!$C:$C,盘货信息!$U:$U))),"【折扣】指定型号满2类享96折，满3类享94折","")} | S5: {=IF(_xlfn.XLOOKUP(A5&B5&C5,盘货信息!$A:$A&盘货信息!$B:$B&盘货信息!$C:$C,盘货信息!$Q:$Q)<1,"","【红包】活动时间购机送"&_xlfn.TEXTJOIN("",,IF(ISNUMBER(--MID(_xlfn.XLOOKUP(A5&B5&C5,盘货信息!$A:$A&盘货信息!$B:$B&盘货信息!$C:$C,盘货信息!$Q:$Q),_xlfn.SEQUENCE(LEN(_xlfn.XLOOKUP(A5&B5&C5,盘货信息!$A:$A&盘货信息!$B:$B&盘货信息!$C:$C,盘货信息!$Q:$Q))),1)),MID(_xlfn.XLOOKUP(A5&B5&C5,盘货信息!$A:$A&盘货信息!$B:$B&盘货信息!$C:$C,盘货信息!$Q:$Q),_xlfn.SEQUENCE(LEN(_xlfn.XLOOKUP(A5&B5&C5,盘货信息!$A:$A&盘货信息!$B:$B&盘货信息!$C:$C,盘货信息!$Q:$Q))),1),""))&"元")} | T5: {=IF(ISNUMBER(SEARCH("是",_xlfn.XLOOKUP(A5&B5&C5,盘货信息!$A:$A&盘货信息!$B:$B&盘货信息!$C:$C,盘货信息!$T:$T))),"【瓜分】"&固定信息!$B$7,"")} | U5: =IF($C5="","",IF(AND(R5="",S5="",T5=""),"",固定信息!$B$1)) | V5: {=IF(C5="","","【服务】"&IF(_xlfn.XLOOKUP(A5&B5&C5,盘货信息!$A:$A&盘货信息!$B:$B&盘货信息!$C:$C,盘货信息!$V:$V)="","",_xlfn.XLOOKUP(A5&B5&C5,盘货信息!$A:$A&盘货信息!$B:$B&盘货信息!$C:$C,盘货信息!$V:$V)&"免息,")&IF(_xlfn.XLOOKUP(A5&B5&C5,盘货信息!$A:$A&盘货信息!$B:$B&盘货信息!$C:$C,盘货信息!$W:$W)="","",_xlfn.XLOOKUP(A5&B5&C5,盘货信息!$A:$A&盘货信息!$B:$B&盘货信息!$C:$C,盘货信息!$W:$W)&"，")&"送货入户，退换免运费")}
A6: =IF(盘货信息!A6="","",盘货信息!A6) | B6: =IF(盘货信息!B6="","",盘货信息!B6) | C6: =IF(盘货信息!C6="","",盘货信息!C6) | D6: =_xlfn.TEXTJOIN(CHAR(10),TRUE,OFFSET(INDIRECT("RC",FALSE),0,1,1,30)) | E6: =IF(C6="","",固定信息!$B$2) | F6: {=IF(C6="","","【"&C6&"】"&_xlfn.XLOOKUP(A6&B6&C6,盘货信息!$A:$A&盘货信息!$B:$B&盘货信息!$C:$C,盘货信息!$D:$D))} | G6: =IF(C6="","","【"&"活动时间："&固定信息!$B$3&"】") | H6: =IF($C6="","",固定信息!$B$1) | J6: {=_xlfn.XLOOKUP(A6&B6&C6,价格信息!$A:$A&价格信息!$B:$B&价格信息!$C:$C,价格信息!$D:$D)} | K6: {=IF(_xlfn.XLOOKUP(A6&B6&C6,价格信息!$A:$A&价格信息!$B:$B&价格信息!$C:$C,价格信息!$I:$I)="","","【优惠券链接】"&固定信息!$B$6)} | L6: =IF($C6="","",固定信息!$B$1) | M6: {=IF(_xlfn.XLOOKUP(A6&B6&C6,盘货信息!$A:$A&盘货信息!$B:$B&盘货信息!$C:$C,盘货信息!$O:$O)="","","【优惠券】领"&INDEX(_wpsfn.REGEXP(_xlfn.XLOOKUP(A6&B6&C6,盘货信息!$A:$A&盘货信息!$B:$B&盘货信息!$C:$C,盘货信息!$O:$O),"\d+"),1,1)&"元优惠券下单更优惠，优惠卷："&_xlfn.XLOOKUP(A6&B6&C6,盘货信息!$A:$A&盘货信息!$B:$B&盘货信息!$C:$C,盘货信息!$P:$P))} | N6: {=IF(AND(ISNUMBER(_xlfn.XLOOKUP(A6&B6&C6,盘货信息!$A:$A&盘货信息!$B:$B&盘货信息!$C:$C,盘货信息!$I:$I)),_xlfn.XLOOKUP(A6&B6&C6,盘货信息!$A:$A&盘货信息!$B:$B&盘货信息!$C:$C,盘货信息!$I:$I)>1),"【88VIP】立减"&_xlfn.XLOOKUP(A6&B6&C6,盘货信息!$A:$A&盘货信息!$B:$B&盘货信息!$C:$C,盘货信息!$I:$I)&"元","")} | O6: {=IF(_xlfn.XLOOKUP(A6&B6&C6,盘货信息!$A:$A&盘货信息!$B:$B&盘货信息!$C:$C,盘货信息!$K:$K)="","",IF(AND(_xlfn.XLOOKUP(A6&B6&C6,盘货信息!$A:$A&盘货信息!$B:$B&盘货信息!$C:$C,盘货信息!$G:$G)="不参加",_xlfn.XLOOKUP(A6&B6&C6,盘货信息!$A:$A&盘货信息!$B:$B&盘货信息!$C:$C,盘货信息!$H:$H)=""),"【以旧换新】"&_xlfn.XLOOKUP(A6&B6&C6,盘货信息!$A:$A&盘货信息!$B:$B&盘货信息!$C:$C,盘货信息!$K:$K)&"元以旧换新补贴（可无旧机换新）",""))} | P6: {=_xlfn.XLOOKUP(A6&B6&C6,赠品!$A:$A&赠品!$B:$B&赠品!$C:$C,赠品!$D:$D)} | Q6: =IF($C6="","",IF(AND(M6="",N6="",P6=""),"",固定信息!$B$1)) | R6: {=IF(ISNUMBER(SEARCH("是",_xlfn.XLOOKUP(A6&B6&C6,盘货信息!$A:$A&盘货信息!$B:$B&盘货信息!$C:$C,盘货信息!$U:$U))),"【折扣】指定型号满2类享96折，满3类享94折","")} | S6: {=IF(_xlfn.XLOOKUP(A6&B6&C6,盘货信息!$A:$A&盘货信息!$B:$B&盘货信息!$C:$C,盘货信息!$Q:$Q)<1,"","【红包】活动时间购机送"&_xlfn.TEXTJOIN("",,IF(ISNUMBER(--MID(_xlfn.XLOOKUP(A6&B6&C6,盘货信息!$A:$A&盘货信息!$B:$B&盘货信息!$C:$C,盘货信息!$Q:$Q),_xlfn.SEQUENCE(LEN(_xlfn.XLOOKUP(A6&B6&C6,盘货信息!$A:$A&盘货信息!$B:$B&盘货信息!$C:$C,盘货信息!$Q:$Q))),1)),MID(_xlfn.XLOOKUP(A6&B6&C6,盘货信息!$A:$A&盘货信息!$B:$B&盘货信息!$C:$C,盘货信息!$Q:$Q),_xlfn.SEQUENCE(LEN(_xlfn.XLOOKUP(A6&B6&C6,盘货信息!$A:$A&盘货信息!$B:$B&盘货信息!$C:$C,盘货信息!$Q:$Q))),1),""))&"元")} | T6: {=IF(ISNUMBER(SEARCH("是",_xlfn.XLOOKUP(A6&B6&C6,盘货信息!$A:$A&盘货信息!$B:$B&盘货信息!$C:$C,盘货信息!$T:$T))),"【瓜分】"&固定信息!$B$7,"")} | U6: =IF($C6="","",IF(AND(R6="",S6="",T6=""),"",固定信息!$B$1)) | V6: {=IF(C6="","","【服务】"&IF(_xlfn.XLOOKUP(A6&B6&C6,盘货信息!$A:$A&盘货信息!$B:$B&盘货信息!$C:$C,盘货信息!$V:$V)="","",_xlfn.XLOOKUP(A6&B6&C6,盘货信息!$A:$A&盘货信息!$B:$B&盘货信息!$C:$C,盘货信息!$V:$V)&"免息,")&IF(_xlfn.XLOOKUP(A6&B6&C6,盘货信息!$A:$A&盘货信息!$B:$B&盘货信息!$C:$C,盘货信息!$W:$W)="","",_xlfn.XLOOKUP(A6&B6&C6,盘货信息!$A:$A&盘货信息!$B:$B&盘货信息!$C:$C,盘货信息!$W:$W)&"，")&"送货入户，退换免运费")}
A7: =IF(盘货信息!A7="","",盘货信息!A7) | B7: =IF(盘货信息!B7="","",盘货信息!B7) | C7: =IF(盘货信息!C7="","",盘货信息!C7) | D7: =_xlfn.TEXTJOIN(CHAR(10),TRUE,OFFSET(INDIRECT("RC",FALSE),0,1,1,30)) | E7: =IF(C7="","",固定信息!$B$2) | F7: {=IF(C7="","","【"&C7&"】"&_xlfn.XLOOKUP(A7&B7&C7,盘货信息!$A:$A&盘货信息!$B:$B&盘货信息!$C:$C,盘货信息!$D:$D))} | G7: =IF(C7="","","【"&"活动时间："&固定信息!$B$3&"】") | H7: =IF($C7="","",固定信息!$B$1) | J7: {=_xlfn.XLOOKUP(A7&B7&C7,价格信息!$A:$A&价格信息!$B:$B&价格信息!$C:$C,价格信息!$D:$D)} | K7: {=IF(_xlfn.XLOOKUP(A7&B7&C7,价格信息!$A:$A&价格信息!$B:$B&价格信息!$C:$C,价格信息!$I:$I)="","","【优惠券链接】"&固定信息!$B$6)} | L7: =IF($C7="","",固定信息!$B$1) | M7: {=IF(_xlfn.XLOOKUP(A7&B7&C7,盘货信息!$A:$A&盘货信息!$B:$B&盘货信息!$C:$C,盘货信息!$O:$O)="","","【优惠券】领"&INDEX(_wpsfn.REGEXP(_xlfn.XLOOKUP(A7&B7&C7,盘货信息!$A:$A&盘货信息!$B:$B&盘货信息!$C:$C,盘货信息!$O:$O),"\d+"),1,1)&"元优惠券下单更优惠，优惠卷："&_xlfn.XLOOKUP(A7&B7&C7,盘货信息!$A:$A&盘货信息!$B:$B&盘货信息!$C:$C,盘货信息!$P:$P))} | N7: {=IF(AND(ISNUMBER(_xlfn.XLOOKUP(A7&B7&C7,盘货信息!$A:$A&盘货信息!$B:$B&盘货信息!$C:$C,盘货信息!$I:$I)),_xlfn.XLOOKUP(A7&B7&C7,盘货信息!$A:$A&盘货信息!$B:$B&盘货信息!$C:$C,盘货信息!$I:$I)>1),"【88VIP】立减"&_xlfn.XLOOKUP(A7&B7&C7,盘货信息!$A:$A&盘货信息!$B:$B&盘货信息!$C:$C,盘货信息!$I:$I)&"元","")} | O7: {=IF(_xlfn.XLOOKUP(A7&B7&C7,盘货信息!$A:$A&盘货信息!$B:$B&盘货信息!$C:$C,盘货信息!$K:$K)="","",IF(AND(_xlfn.XLOOKUP(A7&B7&C7,盘货信息!$A:$A&盘货信息!$B:$B&盘货信息!$C:$C,盘货信息!$G:$G)="不参加",_xlfn.XLOOKUP(A7&B7&C7,盘货信息!$A:$A&盘货信息!$B:$B&盘货信息!$C:$C,盘货信息!$H:$H)=""),"【以旧换新】"&_xlfn.XLOOKUP(A7&B7&C7,盘货信息!$A:$A&盘货信息!$B:$B&盘货信息!$C:$C,盘货信息!$K:$K)&"元以旧换新补贴（可无旧机换新）",""))} | P7: {=_xlfn.XLOOKUP(A7&B7&C7,赠品!$A:$A&赠品!$B:$B&赠品!$C:$C,赠品!$D:$D)} | Q7: =IF($C7="","",IF(AND(M7="",N7="",P7=""),"",固定信息!$B$1)) | R7: {=IF(ISNUMBER(SEARCH("是",_xlfn.XLOOKUP(A7&B7&C7,盘货信息!$A:$A&盘货信息!$B:$B&盘货信息!$C:$C,盘货信息!$U:$U))),"【折扣】指定型号满2类享96折，满3类享94折","")} | S7: {=IF(_xlfn.XLOOKUP(A7&B7&C7,盘货信息!$A:$A&盘货信息!$B:$B&盘货信息!$C:$C,盘货信息!$Q:$Q)<1,"","【红包】活动时间购机送"&_xlfn.TEXTJOIN("",,IF(ISNUMBER(--MID(_xlfn.XLOOKUP(A7&B7&C7,盘货信息!$A:$A&盘货信息!$B:$B&盘货信息!$C:$C,盘货信息!$Q:$Q),_xlfn.SEQUENCE(LEN(_xlfn.XLOOKUP(A7&B7&C7,盘货信息!$A:$A&盘货信息!$B:$B&盘货信息!$C:$C,盘货信息!$Q:$Q))),1)),MID(_xlfn.XLOOKUP(A7&B7&C7,盘货信息!$A:$A&盘货信息!$B:$B&盘货信息!$C:$C,盘货信息!$Q:$Q),_xlfn.SEQUENCE(LEN(_xlfn.XLOOKUP(A7&B7&C7,盘货信息!$A:$A&盘货信息!$B:$B&盘货信息!$C:$C,盘货信息!$Q:$Q))),1),""))&"元")} | T7: {=IF(ISNUMBER(SEARCH("是",_xlfn.XLOOKUP(A7&B7&C7,盘货信息!$A:$A&盘货信息!$B:$B&盘货信息!$C:$C,盘货信息!$T:$T))),"【瓜分】"&固定信息!$B$7,"")} | U7: =IF($C7="","",IF(AND(R7="",S7="",T7=""),"",固定信息!$B$1)) | V7: {=IF(C7="","","【服务】"&IF(_xlfn.XLOOKUP(A7&B7&C7,盘货信息!$A:$A&盘货信息!$B:$B&盘货信息!$C:$C,盘货信息!$V:$V)="","",_xlfn.XLOOKUP(A7&B7&C7,盘货信息!$A:$A&盘货信息!$B:$B&盘货信息!$C:$C,盘货信息!$V:$V)&"免息,")&IF(_xlfn.XLOOKUP(A7&B7&C7,盘货信息!$A:$A&盘货信息!$B:$B&盘货信息!$C:$C,盘货信息!$W:$W)="","",_xlfn.XLOOKUP(A7&B7&C7,盘货信息!$A:$A&盘货信息!$B:$B&盘货信息!$C:$C,盘货信息!$W:$W)&"，")&"送货入户，退换免运费")}
A8: =IF(盘货信息!A8="","",盘货信息!A8) | B8: =IF(盘货信息!B8="","",盘货信息!B8) | C8: =IF(盘货信息!C8="","",盘货信息!C8) | D8: =_xlfn.TEXTJOIN(CHAR(10),TRUE,OFFSET(INDIRECT("RC",FALSE),0,1,1,30)) | E8: =IF(C8="","",固定信息!$B$2) | F8: {=IF(C8="","","【"&C8&"】"&_xlfn.XLOOKUP(A8&B8&C8,盘货信息!$A:$A&盘货信息!$B:$B&盘货信息!$C:$C,盘货信息!$D:$D))} | G8: =IF(C8="","","【"&"活动时间："&固定信息!$B$3&"】") | H8: =IF($C8="","",固定信息!$B$1) | J8: {=_xlfn.XLOOKUP(A8&B8&C8,价格信息!$A:$A&价格信息!$B:$B&价格信息!$C:$C,价格信息!$D:$D)} | K8: {=IF(_xlfn.XLOOKUP(A8&B8&C8,价格信息!$A:$A&价格信息!$B:$B&价格信息!$C:$C,价格信息!$I:$I)="","","【优惠券链接】"&固定信息!$B$6)} | L8: =IF($C8="","",固定信息!$B$1) | M8: {=IF(_xlfn.XLOOKUP(A8&B8&C8,盘货信息!$A:$A&盘货信息!$B:$B&盘货信息!$C:$C,盘货信息!$O:$O)="","","【优惠券】领"&INDEX(_wpsfn.REGEXP(_xlfn.XLOOKUP(A8&B8&C8,盘货信息!$A:$A&盘货信息!$B:$B&盘货信息!$C:$C,盘货信息!$O:$O),"\d+"),1,1)&"元优惠券下单更优惠，优惠卷："&_xlfn.XLOOKUP(A8&B8&C8,盘货信息!$A:$A&盘货信息!$B:$B&盘货信息!$C:$C,盘货信息!$P:$P))} | N8: {=IF(AND(ISNUMBER(_xlfn.XLOOKUP(A8&B8&C8,盘货信息!$A:$A&盘货信息!$B:$B&盘货信息!$C:$C,盘货信息!$I:$I)),_xlfn.XLOOKUP(A8&B8&C8,盘货信息!$A:$A&盘货信息!$B:$B&盘货信息!$C:$C,盘货信息!$I:$I)>1),"【88VIP】立减"&_xlfn.XLOOKUP(A8&B8&C8,盘货信息!$A:$A&盘货信息!$B:$B&盘货信息!$C:$C,盘货信息!$I:$I)&"元","")} | O8: {=IF(_xlfn.XLOOKUP(A8&B8&C8,盘货信息!$A:$A&盘货信息!$B:$B&盘货信息!$C:$C,盘货信息!$K:$K)="","",IF(AND(_xlfn.XLOOKUP(A8&B8&C8,盘货信息!$A:$A&盘货信息!$B:$B&盘货信息!$C:$C,盘货信息!$G:$G)="不参加",_xlfn.XLOOKUP(A8&B8&C8,盘货信息!$A:$A&盘货信息!$B:$B&盘货信息!$C:$C,盘货信息!$H:$H)=""),"【以旧换新】"&_xlfn.XLOOKUP(A8&B8&C8,盘货信息!$A:$A&盘货信息!$B:$B&盘货信息!$C:$C,盘货信息!$K:$K)&"元以旧换新补贴（可无旧机换新）",""))} | P8: {=_xlfn.XLOOKUP(A8&B8&C8,赠品!$A:$A&赠品!$B:$B&赠品!$C:$C,赠品!$D:$D)} | Q8: =IF($C8="","",IF(AND(M8="",N8="",P8=""),"",固定信息!$B$1)) | R8: {=IF(ISNUMBER(SEARCH("是",_xlfn.XLOOKUP(A8&B8&C8,盘货信息!$A:$A&盘货信息!$B:$B&盘货信息!$C:$C,盘货信息!$U:$U))),"【折扣】指定型号满2类享96折，满3类享94折","")} | S8: {=IF(_xlfn.XLOOKUP(A8&B8&C8,盘货信息!$A:$A&盘货信息!$B:$B&盘货信息!$C:$C,盘货信息!$Q:$Q)<1,"","【红包】活动时间购机送"&_xlfn.TEXTJOIN("",,IF(ISNUMBER(--MID(_xlfn.XLOOKUP(A8&B8&C8,盘货信息!$A:$A&盘货信息!$B:$B&盘货信息!$C:$C,盘货信息!$Q:$Q),_xlfn.SEQUENCE(LEN(_xlfn.XLOOKUP(A8&B8&C8,盘货信息!$A:$A&盘货信息!$B:$B&盘货信息!$C:$C,盘货信息!$Q:$Q))),1)),MID(_xlfn.XLOOKUP(A8&B8&C8,盘货信息!$A:$A&盘货信息!$B:$B&盘货信息!$C:$C,盘货信息!$Q:$Q),_xlfn.SEQUENCE(LEN(_xlfn.XLOOKUP(A8&B8&C8,盘货信息!$A:$A&盘货信息!$B:$B&盘货信息!$C:$C,盘货信息!$Q:$Q))),1),""))&"元")} | T8: {=IF(ISNUMBER(SEARCH("是",_xlfn.XLOOKUP(A8&B8&C8,盘货信息!$A:$A&盘货信息!$B:$B&盘货信息!$C:$C,盘货信息!$T:$T))),"【瓜分】"&固定信息!$B$7,"")} | U8: =IF($C8="","",IF(AND(R8="",S8="",T8=""),"",固定信息!$B$1)) | V8: {=IF(C8="","","【服务】"&IF(_xlfn.XLOOKUP(A8&B8&C8,盘货信息!$A:$A&盘货信息!$B:$B&盘货信息!$C:$C,盘货信息!$V:$V)="","",_xlfn.XLOOKUP(A8&B8&C8,盘货信息!$A:$A&盘货信息!$B:$B&盘货信息!$C:$C,盘货信息!$V:$V)&"免息,")&IF(_xlfn.XLOOKUP(A8&B8&C8,盘货信息!$A:$A&盘货信息!$B:$B&盘货信息!$C:$C,盘货信息!$W:$W)="","",_xlfn.XLOOKUP(A8&B8&C8,盘货信息!$A:$A&盘货信息!$B:$B&盘货信息!$C:$C,盘货信息!$W:$W)&"，")&"送货入户，退换免运费")}
A9: =IF(盘货信息!A9="","",盘货信息!A9) | B9: =IF(盘货信息!B9="","",盘货信息!B9) | C9: =IF(盘货信息!C9="","",盘货信息!C9) | D9: =_xlfn.TEXTJOIN(CHAR(10),TRUE,OFFSET(INDIRECT("RC",FALSE),0,1,1,30)) | E9: =IF(C9="","",固定信息!$B$2) | F9: {=IF(C9="","","【"&C9&"】"&_xlfn.XLOOKUP(A9&B9&C9,盘货信息!$A:$A&盘货信息!$B:$B&盘货信息!$C:$C,盘货信息!$D:$D))} | G9: =IF(C9="","","【"&"活动时间："&固定信息!$B$3&"】") | H9: =IF($C9="","",固定信息!$B$1) | J9: {=_xlfn.XLOOKUP(A9&B9&C9,价格信息!$A:$A&价格信息!$B:$B&价格信息!$C:$C,价格信息!$D:$D)} | K9: {=IF(_xlfn.XLOOKUP(A9&B9&C9,价格信息!$A:$A&价格信息!$B:$B&价格信息!$C:$C,价格信息!$I:$I)="","","【优惠券链接】"&固定信息!$B$6)} | L9: =IF($C9="","",固定信息!$B$1) | M9: {=IF(_xlfn.XLOOKUP(A9&B9&C9,盘货信息!$A:$A&盘货信息!$B:$B&盘货信息!$C:$C,盘货信息!$O:$O)="","","【优惠券】领"&INDEX(_wpsfn.REGEXP(_xlfn.XLOOKUP(A9&B9&C9,盘货信息!$A:$A&盘货信息!$B:$B&盘货信息!$C:$C,盘货信息!$O:$O),"\d+"),1,1)&"元优惠券下单更优惠，优惠卷："&_xlfn.XLOOKUP(A9&B9&C9,盘货信息!$A:$A&盘货信息!$B:$B&盘货信息!$C:$C,盘货信息!$P:$P))} | N9: {=IF(AND(ISNUMBER(_xlfn.XLOOKUP(A9&B9&C9,盘货信息!$A:$A&盘货信息!$B:$B&盘货信息!$C:$C,盘货信息!$I:$I)),_xlfn.XLOOKUP(A9&B9&C9,盘货信息!$A:$A&盘货信息!$B:$B&盘货信息!$C:$C,盘货信息!$I:$I)>1),"【88VIP】立减"&_xlfn.XLOOKUP(A9&B9&C9,盘货信息!$A:$A&盘货信息!$B:$B&盘货信息!$C:$C,盘货信息!$I:$I)&"元","")} | O9: {=IF(_xlfn.XLOOKUP(A9&B9&C9,盘货信息!$A:$A&盘货信息!$B:$B&盘货信息!$C:$C,盘货信息!$K:$K)="","",IF(AND(_xlfn.XLOOKUP(A9&B9&C9,盘货信息!$A:$A&盘货信息!$B:$B&盘货信息!$C:$C,盘货信息!$G:$G)="不参加",_xlfn.XLOOKUP(A9&B9&C9,盘货信息!$A:$A&盘货信息!$B:$B&盘货信息!$C:$C,盘货信息!$H:$H)=""),"【以旧换新】"&_xlfn.XLOOKUP(A9&B9&C9,盘货信息!$A:$A&盘货信息!$B:$B&盘货信息!$C:$C,盘货信息!$K:$K)&"元以旧换新补贴（可无旧机换新）",""))} | P9: {=_xlfn.XLOOKUP(A9&B9&C9,赠品!$A:$A&赠品!$B:$B&赠品!$C:$C,赠品!$D:$D)} | Q9: =IF($C9="","",IF(AND(M9="",N9="",P9=""),"",固定信息!$B$1)) | R9: {=IF(ISNUMBER(SEARCH("是",_xlfn.XLOOKUP(A9&B9&C9,盘货信息!$A:$A&盘货信息!$B:$B&盘货信息!$C:$C,盘货信息!$U:$U))),"【折扣】指定型号满2类享96折，满3类享94折","")} | S9: {=IF(_xlfn.XLOOKUP(A9&B9&C9,盘货信息!$A:$A&盘货信息!$B:$B&盘货信息!$C:$C,盘货信息!$Q:$Q)<1,"","【红包】活动时间购机送"&_xlfn.TEXTJOIN("",,IF(ISNUMBER(--MID(_xlfn.XLOOKUP(A9&B9&C9,盘货信息!$A:$A&盘货信息!$B:$B&盘货信息!$C:$C,盘货信息!$Q:$Q),_xlfn.SEQUENCE(LEN(_xlfn.XLOOKUP(A9&B9&C9,盘货信息!$A:$A&盘货信息!$B:$B&盘货信息!$C:$C,盘货信息!$Q:$Q))),1)),MID(_xlfn.XLOOKUP(A9&B9&C9,盘货信息!$A:$A&盘货信息!$B:$B&盘货信息!$C:$C,盘货信息!$Q:$Q),_xlfn.SEQUENCE(LEN(_xlfn.XLOOKUP(A9&B9&C9,盘货信息!$A:$A&盘货信息!$B:$B&盘货信息!$C:$C,盘货信息!$Q:$Q))),1),""))&"元")} | T9: {=IF(ISNUMBER(SEARCH("是",_xlfn.XLOOKUP(A9&B9&C9,盘货信息!$A:$A&盘货信息!$B:$B&盘货信息!$C:$C,盘货信息!$T:$T))),"【瓜分】"&固定信息!$B$7,"")} | U9: =IF($C9="","",IF(AND(R9="",S9="",T9=""),"",固定信息!$B$1)) | V9: {=IF(C9="","","【服务】"&IF(_xlfn.XLOOKUP(A9&B9&C9,盘货信息!$A:$A&盘货信息!$B:$B&盘货信息!$C:$C,盘货信息!$V:$V)="","",_xlfn.XLOOKUP(A9&B9&C9,盘货信息!$A:$A&盘货信息!$B:$B&盘货信息!$C:$C,盘货信息!$V:$V)&"免息,")&IF(_xlfn.XLOOKUP(A9&B9&C9,盘货信息!$A:$A&盘货信息!$B:$B&盘货信息!$C:$C,盘货信息!$W:$W)="","",_xlfn.XLOOKUP(A9&B9&C9,盘货信息!$A:$A&盘货信息!$B:$B&盘货信息!$C:$C,盘货信息!$W:$W)&"，")&"送货入户，退换免运费")}
A10: =IF(盘货信息!A10="","",盘货信息!A10) | B10: =IF(盘货信息!B10="","",盘货信息!B10) | C10: =IF(盘货信息!C10="","",盘货信息!C10) | D10: =_xlfn.TEXTJOIN(CHAR(10),TRUE,OFFSET(INDIRECT("RC",FALSE),0,1,1,30)) | E10: =IF(C10="","",固定信息!$B$2) | F10: {=IF(C10="","","【"&C10&"】"&_xlfn.XLOOKUP(A10&B10&C10,盘货信息!$A:$A&盘货信息!$B:$B&盘货信息!$C:$C,盘货信息!$D:$D))} | G10: =IF(C10="","","【"&"活动时间："&固定信息!$B$3&"】") | H10: =IF($C10="","",固定信息!$B$1) | J10: {=_xlfn.XLOOKUP(A10&B10&C10,价格信息!$A:$A&价格信息!$B:$B&价格信息!$C:$C,价格信息!$D:$D)} | K10: {=IF(_xlfn.XLOOKUP(A10&B10&C10,价格信息!$A:$A&价格信息!$B:$B&价格信息!$C:$C,价格信息!$I:$I)="","","【优惠券链接】"&固定信息!$B$6)} | L10: =IF($C10="","",固定信息!$B$1) | M10: {=IF(_xlfn.XLOOKUP(A10&B10&C10,盘货信息!$A:$A&盘货信息!$B:$B&盘货信息!$C:$C,盘货信息!$O:$O)="","","【优惠券】领"&INDEX(_wpsfn.REGEXP(_xlfn.XLOOKUP(A10&B10&C10,盘货信息!$A:$A&盘货信息!$B:$B&盘货信息!$C:$C,盘货信息!$O:$O),"\d+"),1,1)&"元优惠券下单更优惠，优惠卷："&_xlfn.XLOOKUP(A10&B10&C10,盘货信息!$A:$A&盘货信息!$B:$B&盘货信息!$C:$C,盘货信息!$P:$P))} | N10: {=IF(AND(ISNUMBER(_xlfn.XLOOKUP(A10&B10&C10,盘货信息!$A:$A&盘货信息!$B:$B&盘货信息!$C:$C,盘货信息!$I:$I)),_xlfn.XLOOKUP(A10&B10&C10,盘货信息!$A:$A&盘货信息!$B:$B&盘货信息!$C:$C,盘货信息!$I:$I)>1),"【88VIP】立减"&_xlfn.XLOOKUP(A10&B10&C10,盘货信息!$A:$A&盘货信息!$B:$B&盘货信息!$C:$C,盘货信息!$I:$I)&"元","")} | O10: {=IF(_xlfn.XLOOKUP(A10&B10&C10,盘货信息!$A:$A&盘货信息!$B:$B&盘货信息!$C:$C,盘货信息!$K:$K)="","",IF(AND(_xlfn.XLOOKUP(A10&B10&C10,盘货信息!$A:$A&盘货信息!$B:$B&盘货信息!$C:$C,盘货信息!$G:$G)="不参加",_xlfn.XLOOKUP(A10&B10&C10,盘货信息!$A:$A&盘货信息!$B:$B&盘货信息!$C:$C,盘货信息!$H:$H)=""),"【以旧换新】"&_xlfn.XLOOKUP(A10&B10&C10,盘货信息!$A:$A&盘货信息!$B:$B&盘货信息!$C:$C,盘货信息!$K:$K)&"元以旧换新补贴（可无旧机换新）",""))} | P10: {=_xlfn.XLOOKUP(A10&B10&C10,赠品!$A:$A&赠品!$B:$B&赠品!$C:$C,赠品!$D:$D)} | Q10: =IF($C10="","",IF(AND(M10="",N10="",P10=""),"",固定信息!$B$1)) | R10: {=IF(ISNUMBER(SEARCH("是",_xlfn.XLOOKUP(A10&B10&C10,盘货信息!$A:$A&盘货信息!$B:$B&盘货信息!$C:$C,盘货信息!$U:$U))),"【折扣】指定型号满2类享96折，满3类享94折","")} | S10: {=IF(_xlfn.XLOOKUP(A10&B10&C10,盘货信息!$A:$A&盘货信息!$B:$B&盘货信息!$C:$C,盘货信息!$Q:$Q)<1,"","【红包】活动时间购机送"&_xlfn.TEXTJOIN("",,IF(ISNUMBER(--MID(_xlfn.XLOOKUP(A10&B10&C10,盘货信息!$A:$A&盘货信息!$B:$B&盘货信息!$C:$C,盘货信息!$Q:$Q),_xlfn.SEQUENCE(LEN(_xlfn.XLOOKUP(A10&B10&C10,盘货信息!$A:$A&盘货信息!$B:$B&盘货信息!$C:$C,盘货信息!$Q:$Q))),1)),MID(_xlfn.XLOOKUP(A10&B10&C10,盘货信息!$A:$A&盘货信息!$B:$B&盘货信息!$C:$C,盘货信息!$Q:$Q),_xlfn.SEQUENCE(LEN(_xlfn.XLOOKUP(A10&B10&C10,盘货信息!$A:$A&盘货信息!$B:$B&盘货信息!$C:$C,盘货信息!$Q:$Q))),1),""))&"元")} | T10: {=IF(ISNUMBER(SEARCH("是",_xlfn.XLOOKUP(A10&B10&C10,盘货信息!$A:$A&盘货信息!$B:$B&盘货信息!$C:$C,盘货信息!$T:$T))),"【瓜分】"&固定信息!$B$7,"")} | U10: =IF($C10="","",IF(AND(R10="",S10="",T10=""),"",固定信息!$B$1)) | V10: {=IF(C10="","","【服务】"&IF(_xlfn.XLOOKUP(A10&B10&C10,盘货信息!$A:$A&盘货信息!$B:$B&盘货信息!$C:$C,盘货信息!$V:$V)="","",_xlfn.XLOOKUP(A10&B10&C10,盘货信息!$A:$A&盘货信息!$B:$B&盘货信息!$C:$C,盘货信息!$V:$V)&"免息,")&IF(_xlfn.XLOOKUP(A10&B10&C10,盘货信息!$A:$A&盘货信息!$B:$B&盘货信息!$C:$C,盘货信息!$W:$W)="","",_xlfn.XLOOKUP(A10&B10&C10,盘货信息!$A:$A&盘货信息!$B:$B&盘货信息!$C:$C,盘货信息!$W:$W)&"，")&"送货入户，退换免运费")}
A11: =IF(盘货信息!A11="","",盘货信息!A11) | B11: =IF(盘货信息!B11="","",盘货信息!B11) | C11: =IF(盘货信息!C11="","",盘货信息!C11) | D11: =_xlfn.TEXTJOIN(CHAR(10),TRUE,OFFSET(INDIRECT("RC",FALSE),0,1,1,30)) | E11: =IF(C11="","",固定信息!$B$2) | F11: {=IF(C11="","","【"&C11&"】"&_xlfn.XLOOKUP(A11&B11&C11,盘货信息!$A:$A&盘货信息!$B:$B&盘货信息!$C:$C,盘货信息!$D:$D))} | G11: =IF(C11="","","【"&"活动时间："&固定信息!$B$3&"】") | H11: =IF($C11="","",固定信息!$B$1) | J11: {=_xlfn.XLOOKUP(A11&B11&C11,价格信息!$A:$A&价格信息!$B:$B&价格信息!$C:$C,价格信息!$D:$D)} | K11: {=IF(_xlfn.XLOOKUP(A11&B11&C11,价格信息!$A:$A&价格信息!$B:$B&价格信息!$C:$C,价格信息!$I:$I)="","","【优惠券链接】"&固定信息!$B$6)} | L11: =IF($C11="","",固定信息!$B$1) | M11: {=IF(_xlfn.XLOOKUP(A11&B11&C11,盘货信息!$A:$A&盘货信息!$B:$B&盘货信息!$C:$C,盘货信息!$O:$O)="","","【优惠券】领"&INDEX(_wpsfn.REGEXP(_xlfn.XLOOKUP(A11&B11&C11,盘货信息!$A:$A&盘货信息!$B:$B&盘货信息!$C:$C,盘货信息!$O:$O),"\d+"),1,1)&"元优惠券下单更优惠，优惠卷："&_xlfn.XLOOKUP(A11&B11&C11,盘货信息!$A:$A&盘货信息!$B:$B&盘货信息!$C:$C,盘货信息!$P:$P))} | N11: {=IF(AND(ISNUMBER(_xlfn.XLOOKUP(A11&B11&C11,盘货信息!$A:$A&盘货信息!$B:$B&盘货信息!$C:$C,盘货信息!$I:$I)),_xlfn.XLOOKUP(A11&B11&C11,盘货信息!$A:$A&盘货信息!$B:$B&盘货信息!$C:$C,盘货信息!$I:$I)>1),"【88VIP】立减"&_xlfn.XLOOKUP(A11&B11&C11,盘货信息!$A:$A&盘货信息!$B:$B&盘货信息!$C:$C,盘货信息!$I:$I)&"元","")} | O11: {=IF(_xlfn.XLOOKUP(A11&B11&C11,盘货信息!$A:$A&盘货信息!$B:$B&盘货信息!$C:$C,盘货信息!$K:$K)="","",IF(AND(_xlfn.XLOOKUP(A11&B11&C11,盘货信息!$A:$A&盘货信息!$B:$B&盘货信息!$C:$C,盘货信息!$G:$G)="不参加",_xlfn.XLOOKUP(A11&B11&C11,盘货信息!$A:$A&盘货信息!$B:$B&盘货信息!$C:$C,盘货信息!$H:$H)=""),"【以旧换新】"&_xlfn.XLOOKUP(A11&B11&C11,盘货信息!$A:$A&盘货信息!$B:$B&盘货信息!$C:$C,盘货信息!$K:$K)&"元以旧换新补贴（可无旧机换新）",""))} | P11: {=_xlfn.XLOOKUP(A11&B11&C11,赠品!$A:$A&赠品!$B:$B&赠品!$C:$C,赠品!$D:$D)} | Q11: =IF($C11="","",IF(AND(M11="",N11="",P11=""),"",固定信息!$B$1)) | R11: {=IF(ISNUMBER(SEARCH("是",_xlfn.XLOOKUP(A11&B11&C11,盘货信息!$A:$A&盘货信息!$B:$B&盘货信息!$C:$C,盘货信息!$U:$U))),"【折扣】指定型号满2类享96折，满3类享94折","")} | S11: {=IF(_xlfn.XLOOKUP(A11&B11&C11,盘货信息!$A:$A&盘货信息!$B:$B&盘货信息!$C:$C,盘货信息!$Q:$Q)<1,"","【红包】活动时间购机送"&_xlfn.TEXTJOIN("",,IF(ISNUMBER(--MID(_xlfn.XLOOKUP(A11&B11&C11,盘货信息!$A:$A&盘货信息!$B:$B&盘货信息!$C:$C,盘货信息!$Q:$Q),_xlfn.SEQUENCE(LEN(_xlfn.XLOOKUP(A11&B11&C11,盘货信息!$A:$A&盘货信息!$B:$B&盘货信息!$C:$C,盘货信息!$Q:$Q))),1)),MID(_xlfn.XLOOKUP(A11&B11&C11,盘货信息!$A:$A&盘货信息!$B:$B&盘货信息!$C:$C,盘货信息!$Q:$Q),_xlfn.SEQUENCE(LEN(_xlfn.XLOOKUP(A11&B11&C11,盘货信息!$A:$A&盘货信息!$B:$B&盘货信息!$C:$C,盘货信息!$Q:$Q))),1),""))&"元")} | T11: {=IF(ISNUMBER(SEARCH("是",_xlfn.XLOOKUP(A11&B11&C11,盘货信息!$A:$A&盘货信息!$B:$B&盘货信息!$C:$C,盘货信息!$T:$T))),"【瓜分】"&固定信息!$B$7,"")} | U11: =IF($C11="","",IF(AND(R11="",S11="",T11=""),"",固定信息!$B$1)) | V11: {=IF(C11="","","【服务】"&IF(_xlfn.XLOOKUP(A11&B11&C11,盘货信息!$A:$A&盘货信息!$B:$B&盘货信息!$C:$C,盘货信息!$V:$V)="","",_xlfn.XLOOKUP(A11&B11&C11,盘货信息!$A:$A&盘货信息!$B:$B&盘货信息!$C:$C,盘货信息!$V:$V)&"免息,")&IF(_xlfn.XLOOKUP(A11&B11&C11,盘货信息!$A:$A&盘货信息!$B:$B&盘货信息!$C:$C,盘货信息!$W:$W)="","",_xlfn.XLOOKUP(A11&B11&C11,盘货信息!$A:$A&盘货信息!$B:$B&盘货信息!$C:$C,盘货信息!$W:$W)&"，")&"送货入户，退换免运费")}
A12: =IF(盘货信息!A12="","",盘货信息!A12) | B12: =IF(盘货信息!B12="","",盘货信息!B12) | C12: =IF(盘货信息!C12="","",盘货信息!C12) | D12: =_xlfn.TEXTJOIN(CHAR(10),TRUE,OFFSET(INDIRECT("RC",FALSE),0,1,1,30)) | E12: =IF(C12="","",固定信息!$B$2) | F12: {=IF(C12="","","【"&C12&"】"&_xlfn.XLOOKUP(A12&B12&C12,盘货信息!$A:$A&盘货信息!$B:$B&盘货信息!$C:$C,盘货信息!$D:$D))} | G12: =IF(C12="","","【"&"活动时间："&固定信息!$B$3&"】") | H12: =IF($C12="","",固定信息!$B$1) | J12: {=_xlfn.XLOOKUP(A12&B12&C12,价格信息!$A:$A&价格信息!$B:$B&价格信息!$C:$C,价格信息!$D:$D)} | K12: {=IF(_xlfn.XLOOKUP(A12&B12&C12,价格信息!$A:$A&价格信息!$B:$B&价格信息!$C:$C,价格信息!$I:$I)="","","【优惠券链接】"&固定信息!$B$6)} | L12: =IF($C12="","",固定信息!$B$1) | M12: {=IF(_xlfn.XLOOKUP(A12&B12&C12,盘货信息!$A:$A&盘货信息!$B:$B&盘货信息!$C:$C,盘货信息!$O:$O)="","","【优惠券】领"&INDEX(_wpsfn.REGEXP(_xlfn.XLOOKUP(A12&B12&C12,盘货信息!$A:$A&盘货信息!$B:$B&盘货信息!$C:$C,盘货信息!$O:$O),"\d+"),1,1)&"元优惠券下单更优惠，优惠卷："&_xlfn.XLOOKUP(A12&B12&C12,盘货信息!$A:$A&盘货信息!$B:$B&盘货信息!$C:$C,盘货信息!$P:$P))} | N12: {=IF(AND(ISNUMBER(_xlfn.XLOOKUP(A12&B12&C12,盘货信息!$A:$A&盘货信息!$B:$B&盘货信息!$C:$C,盘货信息!$I:$I)),_xlfn.XLOOKUP(A12&B12&C12,盘货信息!$A:$A&盘货信息!$B:$B&盘货信息!$C:$C,盘货信息!$I:$I)>1),"【88VIP】立减"&_xlfn.XLOOKUP(A12&B12&C12,盘货信息!$A:$A&盘货信息!$B:$B&盘货信息!$C:$C,盘货信息!$I:$I)&"元","")} | O12: {=IF(_xlfn.XLOOKUP(A12&B12&C12,盘货信息!$A:$A&盘货信息!$B:$B&盘货信息!$C:$C,盘货信息!$K:$K)="","",IF(AND(_xlfn.XLOOKUP(A12&B12&C12,盘货信息!$A:$A&盘货信息!$B:$B&盘货信息!$C:$C,盘货信息!$G:$G)="不参加",_xlfn.XLOOKUP(A12&B12&C12,盘货信息!$A:$A&盘货信息!$B:$B&盘货信息!$C:$C,盘货信息!$H:$H)=""),"【以旧换新】"&_xlfn.XLOOKUP(A12&B12&C12,盘货信息!$A:$A&盘货信息!$B:$B&盘货信息!$C:$C,盘货信息!$K:$K)&"元以旧换新补贴（可无旧机换新）",""))} | P12: {=_xlfn.XLOOKUP(A12&B12&C12,赠品!$A:$A&赠品!$B:$B&赠品!$C:$C,赠品!$D:$D)} | Q12: =IF($C12="","",IF(AND(M12="",N12="",P12=""),"",固定信息!$B$1)) | R12: {=IF(ISNUMBER(SEARCH("是",_xlfn.XLOOKUP(A12&B12&C12,盘货信息!$A:$A&盘货信息!$B:$B&盘货信息!$C:$C,盘货信息!$U:$U))),"【折扣】指定型号满2类享96折，满3类享94折","")} | S12: {=IF(_xlfn.XLOOKUP(A12&B12&C12,盘货信息!$A:$A&盘货信息!$B:$B&盘货信息!$C:$C,盘货信息!$Q:$Q)<1,"","【红包】活动时间购机送"&_xlfn.TEXTJOIN("",,IF(ISNUMBER(--MID(_xlfn.XLOOKUP(A12&B12&C12,盘货信息!$A:$A&盘货信息!$B:$B&盘货信息!$C:$C,盘货信息!$Q:$Q),_xlfn.SEQUENCE(LEN(_xlfn.XLOOKUP(A12&B12&C12,盘货信息!$A:$A&盘货信息!$B:$B&盘货信息!$C:$C,盘货信息!$Q:$Q))),1)),MID(_xlfn.XLOOKUP(A12&B12&C12,盘货信息!$A:$A&盘货信息!$B:$B&盘货信息!$C:$C,盘货信息!$Q:$Q),_xlfn.SEQUENCE(LEN(_xlfn.XLOOKUP(A12&B12&C12,盘货信息!$A:$A&盘货信息!$B:$B&盘货信息!$C:$C,盘货信息!$Q:$Q))),1),""))&"元")} | T12: {=IF(ISNUMBER(SEARCH("是",_xlfn.XLOOKUP(A12&B12&C12,盘货信息!$A:$A&盘货信息!$B:$B&盘货信息!$C:$C,盘货信息!$T:$T))),"【瓜分】"&固定信息!$B$7,"")} | U12: =IF($C12="","",IF(AND(R12="",S12="",T12=""),"",固定信息!$B$1)) | V12: {=IF(C12="","","【服务】"&IF(_xlfn.XLOOKUP(A12&B12&C12,盘货信息!$A:$A&盘货信息!$B:$B&盘货信息!$C:$C,盘货信息!$V:$V)="","",_xlfn.XLOOKUP(A12&B12&C12,盘货信息!$A:$A&盘货信息!$B:$B&盘货信息!$C:$C,盘货信息!$V:$V)&"免息,")&IF(_xlfn.XLOOKUP(A12&B12&C12,盘货信息!$A:$A&盘货信息!$B:$B&盘货信息!$C:$C,盘货信息!$W:$W)="","",_xlfn.XLOOKUP(A12&B12&C12,盘货信息!$A:$A&盘货信息!$B:$B&盘货信息!$C:$C,盘货信息!$W:$W)&"，")&"送货入户，退换免运费")}
A13: =IF(盘货信息!A13="","",盘货信息!A13) | B13: =IF(盘货信息!B13="","",盘货信息!B13) | C13: =IF(盘货信息!C13="","",盘货信息!C13) | D13: =_xlfn.TEXTJOIN(CHAR(10),TRUE,OFFSET(INDIRECT("RC",FALSE),0,1,1,30)) | E13: =IF(C13="","",固定信息!$B$2) | F13: {=IF(C13="","","【"&C13&"】"&_xlfn.XLOOKUP(A13&B13&C13,盘货信息!$A:$A&盘货信息!$B:$B&盘货信息!$C:$C,盘货信息!$D:$D))} | G13: =IF(C13="","","【"&"活动时间："&固定信息!$B$3&"】") | H13: =IF($C13="","",固定信息!$B$1) | J13: {=_xlfn.XLOOKUP(A13&B13&C13,价格信息!$A:$A&价格信息!$B:$B&价格信息!$C:$C,价格信息!$D:$D)} | K13: {=IF(_xlfn.XLOOKUP(A13&B13&C13,价格信息!$A:$A&价格信息!$B:$B&价格信息!$C:$C,价格信息!$I:$I)="","","【优惠券链接】"&固定信息!$B$6)} | L13: =IF($C13="","",固定信息!$B$1) | M13: {=IF(_xlfn.XLOOKUP(A13&B13&C13,盘货信息!$A:$A&盘货信息!$B:$B&盘货信息!$C:$C,盘货信息!$O:$O)="","","【优惠券】领"&INDEX(_wpsfn.REGEXP(_xlfn.XLOOKUP(A13&B13&C13,盘货信息!$A:$A&盘货信息!$B:$B&盘货信息!$C:$C,盘货信息!$O:$O),"\d+"),1,1)&"元优惠券下单更优惠，优惠卷："&_xlfn.XLOOKUP(A13&B13&C13,盘货信息!$A:$A&盘货信息!$B:$B&盘货信息!$C:$C,盘货信息!$P:$P))} | N13: {=IF(AND(ISNUMBER(_xlfn.XLOOKUP(A13&B13&C13,盘货信息!$A:$A&盘货信息!$B:$B&盘货信息!$C:$C,盘货信息!$I:$I)),_xlfn.XLOOKUP(A13&B13&C13,盘货信息!$A:$A&盘货信息!$B:$B&盘货信息!$C:$C,盘货信息!$I:$I)>1),"【88VIP】立减"&_xlfn.XLOOKUP(A13&B13&C13,盘货信息!$A:$A&盘货信息!$B:$B&盘货信息!$C:$C,盘货信息!$I:$I)&"元","")} | O13: {=IF(_xlfn.XLOOKUP(A13&B13&C13,盘货信息!$A:$A&盘货信息!$B:$B&盘货信息!$C:$C,盘货信息!$K:$K)="","",IF(AND(_xlfn.XLOOKUP(A13&B13&C13,盘货信息!$A:$A&盘货信息!$B:$B&盘货信息!$C:$C,盘货信息!$G:$G)="不参加",_xlfn.XLOOKUP(A13&B13&C13,盘货信息!$A:$A&盘货信息!$B:$B&盘货信息!$C:$C,盘货信息!$H:$H)=""),"【以旧换新】"&_xlfn.XLOOKUP(A13&B13&C13,盘货信息!$A:$A&盘货信息!$B:$B&盘货信息!$C:$C,盘货信息!$K:$K)&"元以旧换新补贴（可无旧机换新）",""))} | P13: {=_xlfn.XLOOKUP(A13&B13&C13,赠品!$A:$A&赠品!$B:$B&赠品!$C:$C,赠品!$D:$D)} | Q13: =IF($C13="","",IF(AND(M13="",N13="",P13=""),"",固定信息!$B$1)) | R13: {=IF(ISNUMBER(SEARCH("是",_xlfn.XLOOKUP(A13&B13&C13,盘货信息!$A:$A&盘货信息!$B:$B&盘货信息!$C:$C,盘货信息!$U:$U))),"【折扣】指定型号满2类享96折，满3类享94折","")} | S13: {=IF(_xlfn.XLOOKUP(A13&B13&C13,盘货信息!$A:$A&盘货信息!$B:$B&盘货信息!$C:$C,盘货信息!$Q:$Q)<1,"","【红包】活动时间购机送"&_xlfn.TEXTJOIN("",,IF(ISNUMBER(--MID(_xlfn.XLOOKUP(A13&B13&C13,盘货信息!$A:$A&盘货信息!$B:$B&盘货信息!$C:$C,盘货信息!$Q:$Q),_xlfn.SEQUENCE(LEN(_xlfn.XLOOKUP(A13&B13&C13,盘货信息!$A:$A&盘货信息!$B:$B&盘货信息!$C:$C,盘货信息!$Q:$Q))),1)),MID(_xlfn.XLOOKUP(A13&B13&C13,盘货信息!$A:$A&盘货信息!$B:$B&盘货信息!$C:$C,盘货信息!$Q:$Q),_xlfn.SEQUENCE(LEN(_xlfn.XLOOKUP(A13&B13&C13,盘货信息!$A:$A&盘货信息!$B:$B&盘货信息!$C:$C,盘货信息!$Q:$Q))),1),""))&"元")} | T13: {=IF(ISNUMBER(SEARCH("是",_xlfn.XLOOKUP(A13&B13&C13,盘货信息!$A:$A&盘货信息!$B:$B&盘货信息!$C:$C,盘货信息!$T:$T))),"【瓜分】"&固定信息!$B$7,"")} | U13: =IF($C13="","",IF(AND(R13="",S13="",T13=""),"",固定信息!$B$1)) | V13: {=IF(C13="","","【服务】"&IF(_xlfn.XLOOKUP(A13&B13&C13,盘货信息!$A:$A&盘货信息!$B:$B&盘货信息!$C:$C,盘货信息!$V:$V)="","",_xlfn.XLOOKUP(A13&B13&C13,盘货信息!$A:$A&盘货信息!$B:$B&盘货信息!$C:$C,盘货信息!$V:$V)&"免息,")&IF(_xlfn.XLOOKUP(A13&B13&C13,盘货信息!$A:$A&盘货信息!$B:$B&盘货信息!$C:$C,盘货信息!$W:$W)="","",_xlfn.XLOOKUP(A13&B13&C13,盘货信息!$A:$A&盘货信息!$B:$B&盘货信息!$C:$C,盘货信息!$W:$W)&"，")&"送货入户，退换免运费")}
... A501: =IF(盘货信息!A501="","",盘货信息!A501) | B501: =IF(盘货信息!B501="","",盘货信息!B501) | C501: =IF(盘货信息!C501="","",盘货信息!C501) | D501: =_xlfn.TEXTJOIN(CHAR(10),TRUE,OFFSET(INDIRECT("RC",FALSE),0,1,1,30)) | E501: =IF(C501="","",固定信息!$B$2) | F501: {=IF(C501="","","【"&C501&"】"&_xlfn.XLOOKUP(A501&B501&C501,盘货信息!$A:$A&盘货信息!$B:$B&盘货信息!$C:$C,盘货信息!$D:$D))} | G501: =IF(C501="","","【"&"活动时间："&固定信息!$B$3&"】") | H501: =IF($C501="","",固定信息!$B$1) | J501: {=_xlfn.XLOOKUP(A501&B501&C501,价格信息!$A:$A&价格信息!$B:$B&价格信息!$C:$C,价格信息!$D:$D)} | K501: {=IF(_xlfn.XLOOKUP(A501&B501&C501,价格信息!$A:$A&价格信息!$B:$B&价格信息!$C:$C,价格信息!$I:$I)="","","【优惠券链接】"&固定信息!$B$6)} | L501: =IF($C501="","",固定信息!$B$1) | M501: {=IF(_xlfn.XLOOKUP(A501&B501&C501,盘货信息!$A:$A&盘货信息!$B:$B&盘货信息!$C:$C,盘货信息!$O:$O)="","","【优惠券】领"&INDEX(_wpsfn.REGEXP(_xlfn.XLOOKUP(A501&B501&C501,盘货信息!$A:$A&盘货信息!$B:$B&盘货信息!$C:$C,盘货信息!$O:$O),"\d+"),1,1)&"元优惠券下单更优惠，优惠卷："&_xlfn.XLOOKUP(A501&B501&C501,盘货信息!$A:$A&盘货信息!$B:$B&盘货信息!$C:$C,盘货信息!$P:$P))} | N501: {=IF(AND(ISNUMBER(_xlfn.XLOOKUP(A501&B501&C501,盘货信息!$A:$A&盘货信息!$B:$B&盘货信息!$C:$C,盘货信息!$I:$I)),_xlfn.XLOOKUP(A501&B501&C501,盘货信息!$A:$A&盘货信息!$B:$B&盘货信息!$C:$C,盘货信息!$I:$I)>1),"【88VIP】立减"&_xlfn.XLOOKUP(A501&B501&C501,盘货信息!$A:$A&盘货信息!$B:$B&盘货信息!$C:$C,盘货信息!$I:$I)&"元","")} | O501: {=IF(_xlfn.XLOOKUP(A501&B501&C501,盘货信息!$A:$A&盘货信息!$B:$B&盘货信息!$C:$C,盘货信息!$K:$K)="","",IF(AND(_xlfn.XLOOKUP(A501&B501&C501,盘货信息!$A:$A&盘货信息!$B:$B&盘货信息!$C:$C,盘货信息!$G:$G)="不参加",_xlfn.XLOOKUP(A501&B501&C501,盘货信息!$A:$A&盘货信息!$B:$B&盘货信息!$C:$C,盘货信息!$H:$H)=""),"【以旧换新】"&_xlfn.XLOOKUP(A501&B501&C501,盘货信息!$A:$A&盘货信息!$B:$B&盘货信息!$C:$C,盘货信息!$K:$K)&"元以旧换新补贴（可无旧机换新）",""))} | P501: {=_xlfn.XLOOKUP(A501&B501&C501,赠品!$A:$A&赠品!$B:$B&赠品!$C:$C,赠品!$D:$D)} | Q501: =IF($C501="","",IF(AND(M501="",N501="",P501=""),"",固定信息!$B$1)) | R501: {=IF(ISNUMBER(SEARCH("是",_xlfn.XLOOKUP(A501&B501&C501,盘货信息!$A:$A&盘货信息!$B:$B&盘货信息!$C:$C,盘货信息!$U:$U))),"【折扣】指定型号满2类享96折，满3类享94折","")} | S501: {=IF(_xlfn.XLOOKUP(A501&B501&C501,盘货信息!$A:$A&盘货信息!$B:$B&盘货信息!$C:$C,盘货信息!$Q:$Q)<1,"","【红包】活动时间购机送"&_xlfn.TEXTJOIN("",,IF(ISNUMBER(--MID(_xlfn.XLOOKUP(A501&B501&C501,盘货信息!$A:$A&盘货信息!$B:$B&盘货信息!$C:$C,盘货信息!$Q:$Q),_xlfn.SEQUENCE(LEN(_xlfn.XLOOKUP(A501&B501&C501,盘货信息!$A:$A&盘货信息!$B:$B&盘货信息!$C:$C,盘货信息!$Q:$Q))),1)),MID(_xlfn.XLOOKUP(A501&B501&C501,盘货信息!$A:$A&盘货信息!$B:$B&盘货信息!$C:$C,盘货信息!$Q:$Q),_xlfn.SEQUENCE(LEN(_xlfn.XLOOKUP(A501&B501&C501,盘货信息!$A:$A&盘货信息!$B:$B&盘货信息!$C:$C,盘货信息!$Q:$Q))),1),""))&"元")} | T501: {=IF(ISNUMBER(SEARCH("是",_xlfn.XLOOKUP(A501&B501&C501,盘货信息!$A:$A&盘货信息!$B:$B&盘货信息!$C:$C,盘货信息!$T:$T))),"【瓜分】"&固定信息!$B$7,"")} | U501: =IF($C501="","",IF(AND(R501="",S501="",T501=""),"",固定信息!$B$1)) | V501: {=IF(C501="","","【服务】"&IF(_xlfn.XLOOKUP(A501&B501&C501,盘货信息!$A:$A&盘货信息!$B:$B&盘货信息!$C:$C,盘货信息!$V:$V)="","",_xlfn.XLOOKUP(A501&B501&C501,盘货信息!$A:$A&盘货信息!$B:$B&盘货信息!$C:$C,盘货信息!$V:$V)&"免息,")&IF(_xlfn.XLOOKUP(A501&B501&C501,盘货信息!$A:$A&盘货信息!$B:$B&盘货信息!$C:$C,盘货信息!$W:$W)="","",_xlfn.XLOOKUP(A501&B501&C501,盘货信息!$A:$A&盘货信息!$B:$B&盘货信息!$C:$C,盘货信息!$W:$W)&"，")&"送货入户，退换免运费")}

Sheet 价格信息
A1: =IF(盘货信息!A1="","",盘货信息!A1) -> ID | B1: =IF(盘货信息!B1="","",盘货信息!B1) -> SKUID | C1: =IF(盘货信息!C1="","",盘货信息!C1) -> 型号 | D1: 价格 | E1: 焕新补贴预估价 | F1: 到手价 | G1: 88vip95折 | H1: 优惠券-明券 | I1: 优惠券（金额） | J1: 以旧换新 | K1: 限时补贴 | L1: 主图打标额度 | M1: 是否参加焕新补贴-真国补
A2: =IF(盘货信息!A2="","",盘货信息!A2) | B2: =IF(盘货信息!B2="","",盘货信息!B2) | C2: =IF(盘货信息!C2="","",盘货信息!C2) | D2: =IF(C2="","",E2&"="&F2&IF(G2="","","-"&G2)&IF(H2="","","-"&H2)&IF(I2="","","-"&I2)&IF(J2="","","-"&J2)&IF(K2="","","-"&K2)&IF(L2="","","-"&L2)&IF(M2="","","-"&M2)) | E2: {=IF(C2="","",IF(_xlfn.XLOOKUP(A2&B2&C2,盘货信息!$A:$A&盘货信息!$B:$B&盘货信息!$C:$C,盘货信息!$N:$N)="","【立减到手价"&_xlfn.XLOOKUP(A2&B2&C2,盘货信息!$A:$A&盘货信息!$B:$B&盘货信息!$C:$C,盘货信息!$F:$F)&"元】","【焕新补贴预估价"&_xlfn.XLOOKUP(A2&B2&C2,盘货信息!$A:$A&盘货信息!$B:$B&盘货信息!$C:$C,盘货信息!$N:$N)&"元】"))} | F2: {=IF(C2="","",_xlfn.XLOOKUP(A2&B2&C2,盘货信息!$A:$A&盘货信息!$B:$B&盘货信息!$C:$C,盘货信息!$E:$E)&"元到手价")} | G2: {=IF(C2="","",IF(_xlfn.XLOOKUP(A2&B2&C2,盘货信息!$A:$A&盘货信息!$B:$B&盘货信息!$C:$C,盘货信息!$I:$I)="","","88VIP95折"))} | H2: {=IF(C2="","",IF(_xlfn.XLOOKUP(A2&B2&C2,盘货信息!$A:$A&盘货信息!$B:$B&盘货信息!$C:$C,盘货信息!$J:$J)="","",_xlfn.XLOOKUP(A2&B2&C2,盘货信息!$A:$A&盘货信息!$B:$B&盘货信息!$C:$C,盘货信息!$J:$J)&"元优惠卷"))} | I2: {=IF(C2="","",IF(_xlfn.XLOOKUP(A2&B2&C2,盘货信息!$A:$A&盘货信息!$B:$B&盘货信息!$C:$C,盘货信息!$R:$R)="","",_xlfn.XLOOKUP(A2&B2&C2,盘货信息!$A:$A&盘货信息!$B:$B&盘货信息!$C:$C,盘货信息!$R:$R)&"元优惠卷"))} | J2: {=IF(C2="","",IF(_xlfn.XLOOKUP(A2&B2&C2,盘货信息!$A:$A&盘货信息!$B:$B&盘货信息!$C:$C,盘货信息!$K:$K)="","",IF(OR(_xlfn.XLOOKUP(A2&B2&C2,盘货信息!$A:$A&盘货信息!$B:$B&盘货信息!$C:$C,盘货信息!$G:$G)="参加",_xlfn.XLOOKUP(A2&B2&C2,盘货信息!$A:$A&盘货信息!$B:$B&盘货信息!$C:$C,盘货信息!$H:$H)="1（纯自补）"),_xlfn.XLOOKUP(A2&B2&C2,盘货信息!$A:$A&盘货信息!$B:$B&盘货信息!$C:$C,盘货信息!$K:$K)&"元以旧换新（可无旧机换新）","")))} | K2: {=IF(C2="","",IF(_xlfn.XLOOKUP(A2&B2&C2,盘货信息!$A:$A&盘货信息!$B:$B&盘货信息!$C:$C,盘货信息!$L:$L)="","",_xlfn.XLOOKUP(A2&B2&C2,盘货信息!$A:$A&盘货信息!$B:$B&盘货信息!$C:$C,盘货信息!$L:$L)&"元限时补贴"))} | L2: {=IF(C2="","",IF(_xlfn.XLOOKUP(A2&B2&C2,盘货信息!$A:$A&盘货信息!$B:$B&盘货信息!$C:$C,盘货信息!$M:$M)="","",_xlfn.XLOOKUP(A2&B2&C2,盘货信息!$A:$A&盘货信息!$B:$B&盘货信息!$C:$C,盘货信息!$M:$M)&"元消费券"))} | M2: {=IF(C2="","",IF(_xlfn.XLOOKUP(A2&B2&C2,盘货信息!$A:$A&盘货信息!$B:$B&盘货信息!$C:$C,盘货信息!$G:$G)="不参加","","焕新补贴优惠【全民可用，不限地址】"))}
A3: =IF(盘货信息!A3="","",盘货信息!A3) | B3: =IF(盘货信息!B3="","",盘货信息!B3) | C3: =IF(盘货信息!C3="","",盘货信息!C3) | D3: =IF(C3="","",E3&"="&F3&IF(G3="","","-"&G3)&IF(H3="","","-"&H3)&IF(I3="","","-"&I3)&IF(J3="","","-"&J3)&IF(K3="","","-"&K3)&IF(L3="","","-"&L3)&IF(M3="","","-"&M3)) | E3: {=IF(C3="","",IF(_xlfn.XLOOKUP(A3&B3&C3,盘货信息!$A:$A&盘货信息!$B:$B&盘货信息!$C:$C,盘货信息!$N:$N)="","【立减到手价"&_xlfn.XLOOKUP(A3&B3&C3,盘货信息!$A:$A&盘货信息!$B:$B&盘货信息!$C:$C,盘货信息!$F:$F)&"元】","【焕新补贴预估价"&_xlfn.XLOOKUP(A3&B3&C3,盘货信息!$A:$A&盘货信息!$B:$B&盘货信息!$C:$C,盘货信息!$N:$N)&"元】"))} | F3: {=IF(C3="","",_xlfn.XLOOKUP(A3&B3&C3,盘货信息!$A:$A&盘货信息!$B:$B&盘货信息!$C:$C,盘货信息!$E:$E)&"元到手价")} | G3: {=IF(C3="","",IF(_xlfn.XLOOKUP(A3&B3&C3,盘货信息!$A:$A&盘货信息!$B:$B&盘货信息!$C:$C,盘货信息!$I:$I)="","","88VIP95折"))} | H3: {=IF(C3="","",IF(_xlfn.XLOOKUP(A3&B3&C3,盘货信息!$A:$A&盘货信息!$B:$B&盘货信息!$C:$C,盘货信息!$J:$J)="","",_xlfn.XLOOKUP(A3&B3&C3,盘货信息!$A:$A&盘货信息!$B:$B&盘货信息!$C:$C,盘货信息!$J:$J)&"元优惠卷"))} | I3: {=IF(C3="","",IF(_xlfn.XLOOKUP(A3&B3&C3,盘货信息!$A:$A&盘货信息!$B:$B&盘货信息!$C:$C,盘货信息!$R:$R)="","",_xlfn.XLOOKUP(A3&B3&C3,盘货信息!$A:$A&盘货信息!$B:$B&盘货信息!$C:$C,盘货信息!$R:$R)&"元优惠卷"))} | J3: {=IF(C3="","",IF(_xlfn.XLOOKUP(A3&B3&C3,盘货信息!$A:$A&盘货信息!$B:$B&盘货信息!$C:$C,盘货信息!$K:$K)="","",IF(OR(_xlfn.XLOOKUP(A3&B3&C3,盘货信息!$A:$A&盘货信息!$B:$B&盘货信息!$C:$C,盘货信息!$G:$G)="参加",_xlfn.XLOOKUP(A3&B3&C3,盘货信息!$A:$A&盘货信息!$B:$B&盘货信息!$C:$C,盘货信息!$H:$H)="1（纯自补）"),_xlfn.XLOOKUP(A3&B3&C3,盘货信息!$A:$A&盘货信息!$B:$B&盘货信息!$C:$C,盘货信息!$K:$K)&"元以旧换新（可无旧机换新）","")))} | K3: {=IF(C3="","",IF(_xlfn.XLOOKUP(A3&B3&C3,盘货信息!$A:$A&盘货信息!$B:$B&盘货信息!$C:$C,盘货信息!$L:$L)="","",_xlfn.XLOOKUP(A3&B3&C3,盘货信息!$A:$A&盘货信息!$B:$B&盘货信息!$C:$C,盘货信息!$L:$L)&"元限时补贴"))} | L3: {=IF(C3="","",IF(_xlfn.XLOOKUP(A3&B3&C3,盘货信息!$A:$A&盘货信息!$B:$B&盘货信息!$C:$C,盘货信息!$M:$M)="","",_xlfn.XLOOKUP(A3&B3&C3,盘货信息!$A:$A&盘货信息!$B:$B&盘货信息!$C:$C,盘货信息!$M:$M)&"元消费券"))} | M3: {=IF(C3="","",IF(_xlfn.XLOOKUP(A3&B3&C3,盘货信息!$A:$A&盘货信息!$B:$B&盘货信息!$C:$C,盘货信息!$G:$G)="不参加","","焕新补贴优惠【全民可用，不限地址】"))}
A4: =IF(盘货信息!A4="","",盘货信息!A4) | B4: =IF(盘货信息!B4="","",盘货信息!B4) | C4: =IF(盘货信息!C4="","",盘货信息!C4) | D4: =IF(C4="","",E4&"="&F4&IF(G4="","","-"&G4)&IF(H4="","","-"&H4)&IF(I4="","","-"&I4)&IF(J4="","","-"&J4)&IF(K4="","","-"&K4)&IF(L4="","","-"&L4)&IF(M4="","","-"&M4)) | E4: {=IF(C4="","",IF(_xlfn.XLOOKUP(A4&B4&C4,盘货信息!$A:$A&盘货信息!$B:$B&盘货信息!$C:$C,盘货信息!$N:$N)="","【立减到手价"&_xlfn.XLOOKUP(A4&B4&C4,盘货信息!$A:$A&盘货信息!$B:$B&盘货信息!$C:$C,盘货信息!$F:$F)&"元】","【焕新补贴预估价"&_xlfn.XLOOKUP(A4&B4&C4,盘货信息!$A:$A&盘货信息!$B:$B&盘货信息!$C:$C,盘货信息!$N:$N)&"元】"))} | F4: {=IF(C4="","",_xlfn.XLOOKUP(A4&B4&C4,盘货信息!$A:$A&盘货信息!$B:$B&盘货信息!$C:$C,盘货信息!$E:$E)&"元到手价")} | G4: {=IF(C4="","",IF(_xlfn.XLOOKUP(A4&B4&C4,盘货信息!$A:$A&盘货信息!$B:$B&盘货信息!$C:$C,盘货信息!$I:$I)="","","88VIP95折"))} | H4: {=IF(C4="","",IF(_xlfn.XLOOKUP(A4&B4&C4,盘货信息!$A:$A&盘货信息!$B:$B&盘货信息!$C:$C,盘货信息!$J:$J)="","",_xlfn.XLOOKUP(A4&B4&C4,盘货信息!$A:$A&盘货信息!$B:$B&盘货信息!$C:$C,盘货信息!$J:$J)&"元优惠卷"))} | I4: {=IF(C4="","",IF(_xlfn.XLOOKUP(A4&B4&C4,盘货信息!$A:$A&盘货信息!$B:$B&盘货信息!$C:$C,盘货信息!$R:$R)="","",_xlfn.XLOOKUP(A4&B4&C4,盘货信息!$A:$A&盘货信息!$B:$B&盘货信息!$C:$C,盘货信息!$R:$R)&"元优惠卷"))} | J4: {=IF(C4="","",IF(_xlfn.XLOOKUP(A4&B4&C4,盘货信息!$A:$A&盘货信息!$B:$B&盘货信息!$C:$C,盘货信息!$K:$K)="","",IF(OR(_xlfn.XLOOKUP(A4&B4&C4,盘货信息!$A:$A&盘货信息!$B:$B&盘货信息!$C:$C,盘货信息!$G:$G)="参加",_xlfn.XLOOKUP(A4&B4&C4,盘货信息!$A:$A&盘货信息!$B:$B&盘货信息!$C:$C,盘货信息!$H:$H)="1（纯自补）"),_xlfn.XLOOKUP(A4&B4&C4,盘货信息!$A:$A&盘货信息!$B:$B&盘货信息!$C:$C,盘货信息!$K:$K)&"元以旧换新（可无旧机换新）","")))} | K4: {=IF(C4="","",IF(_xlfn.XLOOKUP(A4&B4&C4,盘货信息!$A:$A&盘货信息!$B:$B&盘货信息!$C:$C,盘货信息!$L:$L)="","",_xlfn.XLOOKUP(A4&B4&C4,盘货信息!$A:$A&盘货信息!$B:$B&盘货信息!$C:$C,盘货信息!$L:$L)&"元限时补贴"))} | L4: {=IF(C4="","",IF(_xlfn.XLOOKUP(A4&B4&C4,盘货信息!$A:$A&盘货信息!$B:$B&盘货信息!$C:$C,盘货信息!$M:$M)="","",_xlfn.XLOOKUP(A4&B4&C4,盘货信息!$A:$A&盘货信息!$B:$B&盘货信息!$C:$C,盘货信息!$M:$M)&"元消费券"))} | M4: {=IF(C4="","",IF(_xlfn.XLOOKUP(A4&B4&C4,盘货信息!$A:$A&盘货信息!$B:$B&盘货信息!$C:$C,盘货信息!$G:$G)="不参加","","焕新补贴优惠【全民可用，不限地址】"))}
A5: =IF(盘货信息!A5="","",盘货信息!A5) | B5: =IF(盘货信息!B5="","",盘货信息!B5) | C5: =IF(盘货信息!C5="","",盘货信息!C5) | D5: =IF(C5="","",E5&"="&F5&IF(G5="","","-"&G5)&IF(H5="","","-"&H5)&IF(I5="","","-"&I5)&IF(J5="","","-"&J5)&IF(K5="","","-"&K5)&IF(L5="","","-"&L5)&IF(M5="","","-"&M5)) | E5: {=IF(C5="","",IF(_xlfn.XLOOKUP(A5&B5&C5,盘货信息!$A:$A&盘货信息!$B:$B&盘货信息!$C:$C,盘货信息!$N:$N)="","【立减到手价"&_xlfn.XLOOKUP(A5&B5&C5,盘货信息!$A:$A&盘货信息!$B:$B&盘货信息!$C:$C,盘货信息!$F:$F)&"元】","【焕新补贴预估价"&_xlfn.XLOOKUP(A5&B5&C5,盘货信息!$A:$A&盘货信息!$B:$B&盘货信息!$C:$C,盘货信息!$N:$N)&"元】"))} | F5: {=IF(C5="","",_xlfn.XLOOKUP(A5&B5&C5,盘货信息!$A:$A&盘货信息!$B:$B&盘货信息!$C:$C,盘货信息!$E:$E)&"元到手价")} | G5: {=IF(C5="","",IF(_xlfn.XLOOKUP(A5&B5&C5,盘货信息!$A:$A&盘货信息!$B:$B&盘货信息!$C:$C,盘货信息!$I:$I)="","","88VIP95折"))} | H5: {=IF(C5="","",IF(_xlfn.XLOOKUP(A5&B5&C5,盘货信息!$A:$A&盘货信息!$B:$B&盘货信息!$C:$C,盘货信息!$J:$J)="","",_xlfn.XLOOKUP(A5&B5&C5,盘货信息!$A:$A&盘货信息!$B:$B&盘货信息!$C:$C,盘货信息!$J:$J)&"元优惠卷"))} | I5: {=IF(C5="","",IF(_xlfn.XLOOKUP(A5&B5&C5,盘货信息!$A:$A&盘货信息!$B:$B&盘货信息!$C:$C,盘货信息!$R:$R)="","",_xlfn.XLOOKUP(A5&B5&C5,盘货信息!$A:$A&盘货信息!$B:$B&盘货信息!$C:$C,盘货信息!$R:$R)&"元优惠卷"))} | J5: {=IF(C5="","",IF(_xlfn.XLOOKUP(A5&B5&C5,盘货信息!$A:$A&盘货信息!$B:$B&盘货信息!$C:$C,盘货信息!$K:$K)="","",IF(OR(_xlfn.XLOOKUP(A5&B5&C5,盘货信息!$A:$A&盘货信息!$B:$B&盘货信息!$C:$C,盘货信息!$G:$G)="参加",_xlfn.XLOOKUP(A5&B5&C5,盘货信息!$A:$A&盘货信息!$B:$B&盘货信息!$C:$C,盘货信息!$H:$H)="1（纯自补）"),_xlfn.XLOOKUP(A5&B5&C5,盘货信息!$A:$A&盘货信息!$B:$B&盘货信息!$C:$C,盘货信息!$K:$K)&"元以旧换新（可无旧机换新）","")))} | K5: {=IF(C5="","",IF(_xlfn.XLOOKUP(A5&B5&C5,盘货信息!$A:$A&盘货信息!$B:$B&盘货信息!$C:$C,盘货信息!$L:$L)="","",_xlfn.XLOOKUP(A5&B5&C5,盘货信息!$A:$A&盘货信息!$B:$B&盘货信息!$C:$C,盘货信息!$L:$L)&"元限时补贴"))} | L5: {=IF(C5="","",IF(_xlfn.XLOOKUP(A5&B5&C5,盘货信息!$A:$A&盘货信息!$B:$B&盘货信息!$C:$C,盘货信息!$M:$M)="","",_xlfn.XLOOKUP(A5&B5&C5,盘货信息!$A:$A&盘货信息!$B:$B&盘货信息!$C:$C,盘货信息!$M:$M)&"元消费券"))} | M5: {=IF(C5="","",IF(_xlfn.XLOOKUP(A5&B5&C5,盘货信息!$A:$A&盘货信息!$B:$B&盘货信息!$C:$C,盘货信息!$G:$G)="不参加","","焕新补贴优惠【全民可用，不限地址】"))}
A6: =IF(盘货信息!A6="","",盘货信息!A6) | B6: =IF(盘货信息!B6="","",盘货信息!B6) | C6: =IF(盘货信息!C6="","",盘货信息!C6) | D6: =IF(C6="","",E6&"="&F6&IF(G6="","","-"&G6)&IF(H6="","","-"&H6)&IF(I6="","","-"&I6)&IF(J6="","","-"&J6)&IF(K6="","","-"&K6)&IF(L6="","","-"&L6)&IF(M6="","","-"&M6)) | E6: {=IF(C6="","",IF(_xlfn.XLOOKUP(A6&B6&C6,盘货信息!$A:$A&盘货信息!$B:$B&盘货信息!$C:$C,盘货信息!$N:$N)="","【立减到手价"&_xlfn.XLOOKUP(A6&B6&C6,盘货信息!$A:$A&盘货信息!$B:$B&盘货信息!$C:$C,盘货信息!$F:$F)&"元】","【焕新补贴预估价"&_xlfn.XLOOKUP(A6&B6&C6,盘货信息!$A:$A&盘货信息!$B:$B&盘货信息!$C:$C,盘货信息!$N:$N)&"元】"))} | F6: {=IF(C6="","",_xlfn.XLOOKUP(A6&B6&C6,盘货信息!$A:$A&盘货信息!$B:$B&盘货信息!$C:$C,盘货信息!$E:$E)&"元到手价")} | G6: {=IF(C6="","",IF(_xlfn.XLOOKUP(A6&B6&C6,盘货信息!$A:$A&盘货信息!$B:$B&盘货信息!$C:$C,盘货信息!$I:$I)="","","88VIP95折"))} | H6: {=IF(C6="","",IF(_xlfn.XLOOKUP(A6&B6&C6,盘货信息!$A:$A&盘货信息!$B:$B&盘货信息!$C:$C,盘货信息!$J:$J)="","",_xlfn.XLOOKUP(A6&B6&C6,盘货信息!$A:$A&盘货信息!$B:$B&盘货信息!$C:$C,盘货信息!$J:$J)&"元优惠卷"))} | I6: {=IF(C6="","",IF(_xlfn.XLOOKUP(A6&B6&C6,盘货信息!$A:$A&盘货信息!$B:$B&盘货信息!$C:$C,盘货信息!$R:$R)="","",_xlfn.XLOOKUP(A6&B6&C6,盘货信息!$A:$A&盘货信息!$B:$B&盘货信息!$C:$C,盘货信息!$R:$R)&"元优惠卷"))} | J6: {=IF(C6="","",IF(_xlfn.XLOOKUP(A6&B6&C6,盘货信息!$A:$A&盘货信息!$B:$B&盘货信息!$C:$C,盘货信息!$K:$K)="","",IF(OR(_xlfn.XLOOKUP(A6&B6&C6,盘货信息!$A:$A&盘货信息!$B:$B&盘货信息!$C:$C,盘货信息!$G:$G)="参加",_xlfn.XLOOKUP(A6&B6&C6,盘货信息!$A:$A&盘货信息!$B:$B&盘货信息!$C:$C,盘货信息!$H:$H)="1（纯自补）"),_xlfn.XLOOKUP(A6&B6&C6,盘货信息!$A:$A&盘货信息!$B:$B&盘货信息!$C:$C,盘货信息!$K:$K)&"元以旧换新（可无旧机换新）","")))} | K6: {=IF(C6="","",IF(_xlfn.XLOOKUP(A6&B6&C6,盘货信息!$A:$A&盘货信息!$B:$B&盘货信息!$C:$C,盘货信息!$L:$L)="","",_xlfn.XLOOKUP(A6&B6&C6,盘货信息!$A:$A&盘货信息!$B:$B&盘货信息!$C:$C,盘货信息!$L:$L)&"元限时补贴"))} | L6: {=IF(C6="","",IF(_xlfn.XLOOKUP(A6&B6&C6,盘货信息!$A:$A&盘货信息!$B:$B&盘货信息!$C:$C,盘货信息!$M:$M)="","",_xlfn.XLOOKUP(A6&B6&C6,盘货信息!$A:$A&盘货信息!$B:$B&盘货信息!$C:$C,盘货信息!$M:$M)&"元消费券"))} | M6: {=IF(C6="","",IF(_xlfn.XLOOKUP(A6&B6&C6,盘货信息!$A:$A&盘货信息!$B:$B&盘货信息!$C:$C,盘货信息!$G:$G)="不参加","","焕新补贴优惠【全民可用，不限地址】"))}
A7: =IF(盘货信息!A7="","",盘货信息!A7) | B7: =IF(盘货信息!B7="","",盘货信息!B7) | C7: =IF(盘货信息!C7="","",盘货信息!C7) | D7: =IF(C7="","",E7&"="&F7&IF(G7="","","-"&G7)&IF(H7="","","-"&H7)&IF(I7="","","-"&I7)&IF(J7="","","-"&J7)&IF(K7="","","-"&K7)&IF(L7="","","-"&L7)&IF(M7="","","-"&M7)) | E7: {=IF(C7="","",IF(_xlfn.XLOOKUP(A7&B7&C7,盘货信息!$A:$A&盘货信息!$B:$B&盘货信息!$C:$C,盘货信息!$N:$N)="","【立减到手价"&_xlfn.XLOOKUP(A7&B7&C7,盘货信息!$A:$A&盘货信息!$B:$B&盘货信息!$C:$C,盘货信息!$F:$F)&"元】","【焕新补贴预估价"&_xlfn.XLOOKUP(A7&B7&C7,盘货信息!$A:$A&盘货信息!$B:$B&盘货信息!$C:$C,盘货信息!$N:$N)&"元】"))} | F7: {=IF(C7="","",_xlfn.XLOOKUP(A7&B7&C7,盘货信息!$A:$A&盘货信息!$B:$B&盘货信息!$C:$C,盘货信息!$E:$E)&"元到手价")} | G7: {=IF(C7="","",IF(_xlfn.XLOOKUP(A7&B7&C7,盘货信息!$A:$A&盘货信息!$B:$B&盘货信息!$C:$C,盘货信息!$I:$I)="","","88VIP95折"))} | H7: {=IF(C7="","",IF(_xlfn.XLOOKUP(A7&B7&C7,盘货信息!$A:$A&盘货信息!$B:$B&盘货信息!$C:$C,盘货信息!$J:$J)="","",_xlfn.XLOOKUP(A7&B7&C7,盘货信息!$A:$A&盘货信息!$B:$B&盘货信息!$C:$C,盘货信息!$J:$J)&"元优惠卷"))} | I7: {=IF(C7="","",IF(_xlfn.XLOOKUP(A7&B7&C7,盘货信息!$A:$A&盘货信息!$B:$B&盘货信息!$C:$C,盘货信息!$R:$R)="","",_xlfn.XLOOKUP(A7&B7&C7,盘货信息!$A:$A&盘货信息!$B:$B&盘货信息!$C:$C,盘货信息!$R:$R)&"元优惠卷"))} | J7: {=IF(C7="","",IF(_xlfn.XLOOKUP(A7&B7&C7,盘货信息!$A:$A&盘货信息!$B:$B&盘货信息!$C:$C,盘货信息!$K:$K)="","",IF(OR(_xlfn.XLOOKUP(A7&B7&C7,盘货信息!$A:$A&盘货信息!$B:$B&盘货信息!$C:$C,盘货信息!$G:$G)="参加",_xlfn.XLOOKUP(A7&B7&C7,盘货信息!$A:$A&盘货信息!$B:$B&盘货信息!$C:$C,盘货信息!$H:$H)="1（纯自补）"),_xlfn.XLOOKUP(A7&B7&C7,盘货信息!$A:$A&盘货信息!$B:$B&盘货信息!$C:$C,盘货信息!$K:$K)&"元以旧换新（可无旧机换新）","")))} | K7: {=IF(C7="","",IF(_xlfn.XLOOKUP(A7&B7&C7,盘货信息!$A:$A&盘货信息!$B:$B&盘货信息!$C:$C,盘货信息!$L:$L)="","",_xlfn.XLOOKUP(A7&B7&C7,盘货信息!$A:$A&盘货信息!$B:$B&盘货信息!$C:$C,盘货信息!$L:$L)&"元限时补贴"))} | L7: {=IF(C7="","",IF(_xlfn.XLOOKUP(A7&B7&C7,盘货信息!$A:$A&盘货信息!$B:$B&盘货信息!$C:$C,盘货信息!$M:$M)="","",_xlfn.XLOOKUP(A7&B7&C7,盘货信息!$A:$A&盘货信息!$B:$B&盘货信息!$C:$C,盘货信息!$M:$M)&"元消费券"))} | M7: {=IF(C7="","",IF(_xlfn.XLOOKUP(A7&B7&C7,盘货信息!$A:$A&盘货信息!$B:$B&盘货信息!$C:$C,盘货信息!$G:$G)="不参加","","焕新补贴优惠【全民可用，不限地址】"))}
A8: =IF(盘货信息!A8="","",盘货信息!A8) | B8: =IF(盘货信息!B8="","",盘货信息!B8) | C8: =IF(盘货信息!C8="","",盘货信息!C8) | D8: =IF(C8="","",E8&"="&F8&IF(G8="","","-"&G8)&IF(H8="","","-"&H8)&IF(I8="","","-"&I8)&IF(J8="","","-"&J8)&IF(K8="","","-"&K8)&IF(L8="","","-"&L8)&IF(M8="","","-"&M8)) | E8: {=IF(C8="","",IF(_xlfn.XLOOKUP(A8&B8&C8,盘货信息!$A:$A&盘货信息!$B:$B&盘货信息!$C:$C,盘货信息!$N:$N)="","【立减到手价"&_xlfn.XLOOKUP(A8&B8&C8,盘货信息!$A:$A&盘货信息!$B:$B&盘货信息!$C:$C,盘货信息!$F:$F)&"元】","【焕新补贴预估价"&_xlfn.XLOOKUP(A8&B8&C8,盘货信息!$A:$A&盘货信息!$B:$B&盘货信息!$C:$C,盘货信息!$N:$N)&"元】"))} | F8: {=IF(C8="","",_xlfn.XLOOKUP(A8&B8&C8,盘货信息!$A:$A&盘货信息!$B:$B&盘货信息!$C:$C,盘货信息!$E:$E)&"元到手价")} | G8: {=IF(C8="","",IF(_xlfn.XLOOKUP(A8&B8&C8,盘货信息!$A:$A&盘货信息!$B:$B&盘货信息!$C:$C,盘货信息!$I:$I)="","","88VIP95折"))} | H8: {=IF(C8="","",IF(_xlfn.XLOOKUP(A8&B8&C8,盘货信息!$A:$A&盘货信息!$B:$B&盘货信息!$C:$C,盘货信息!$J:$J)="","",_xlfn.XLOOKUP(A8&B8&C8,盘货信息!$A:$A&盘货信息!$B:$B&盘货信息!$C:$C,盘货信息!$J:$J)&"元优惠卷"))} | I8: {=IF(C8="","",IF(_xlfn.XLOOKUP(A8&B8&C8,盘货信息!$A:$A&盘货信息!$B:$B&盘货信息!$C:$C,盘货信息!$R:$R)="","",_xlfn.XLOOKUP(A8&B8&C8,盘货信息!$A:$A&盘货信息!$B:$B&盘货信息!$C:$C,盘货信息!$R:$R)&"元优惠卷"))} | J8: {=IF(C8="","",IF(_xlfn.XLOOKUP(A8&B8&C8,盘货信息!$A:$A&盘货信息!$B:$B&盘货信息!$C:$C,盘货信息!$K:$K)="","",IF(OR(_xlfn.XLOOKUP(A8&B8&C8,盘货信息!$A:$A&盘货信息!$B:$B&盘货信息!$C:$C,盘货信息!$G:$G)="参加",_xlfn.XLOOKUP(A8&B8&C8,盘货信息!$A:$A&盘货信息!$B:$B&盘货信息!$C:$C,盘货信息!$H:$H)="1（纯自补）"),_xlfn.XLOOKUP(A8&B8&C8,盘货信息!$A:$A&盘货信息!$B:$B&盘货信息!$C:$C,盘货信息!$K:$K)&"元以旧换新（可无旧机换新）","")))} | K8: {=IF(C8="","",IF(_xlfn.XLOOKUP(A8&B8&C8,盘货信息!$A:$A&盘货信息!$B:$B&盘货信息!$C:$C,盘货信息!$L:$L)="","",_xlfn.XLOOKUP(A8&B8&C8,盘货信息!$A:$A&盘货信息!$B:$B&盘货信息!$C:$C,盘货信息!$L:$L)&"元限时补贴"))} | L8: {=IF(C8="","",IF(_xlfn.XLOOKUP(A8&B8&C8,盘货信息!$A:$A&盘货信息!$B:$B&盘货信息!$C:$C,盘货信息!$M:$M)="","",_xlfn.XLOOKUP(A8&B8&C8,盘货信息!$A:$A&盘货信息!$B:$B&盘货信息!$C:$C,盘货信息!$M:$M)&"元消费券"))} | M8: {=IF(C8="","",IF(_xlfn.XLOOKUP(A8&B8&C8,盘货信息!$A:$A&盘货信息!$B:$B&盘货信息!$C:$C,盘货信息!$G:$G)="不参加","","焕新补贴优惠【全民可用，不限地址】"))}
A9: =IF(盘货信息!A9="","",盘货信息!A9) | B9: =IF(盘货信息!B9="","",盘货信息!B9) | C9: =IF(盘货信息!C9="","",盘货信息!C9) | D9: =IF(C9="","",E9&"="&F9&IF(G9="","","-"&G9)&IF(H9="","","-"&H9)&IF(I9="","","-"&I9)&IF(J9="","","-"&J9)&IF(K9="","","-"&K9)&IF(L9="","","-"&L9)&IF(M9="","","-"&M9)) | E9: {=IF(C9="","",IF(_xlfn.XLOOKUP(A9&B9&C9,盘货信息!$A:$A&盘货信息!$B:$B&盘货信息!$C:$C,盘货信息!$N:$N)="","【立减到手价"&_xlfn.XLOOKUP(A9&B9&C9,盘货信息!$A:$A&盘货信息!$B:$B&盘货信息!$C:$C,盘货信息!$F:$F)&"元】","【焕新补贴预估价"&_xlfn.XLOOKUP(A9&B9&C9,盘货信息!$A:$A&盘货信息!$B:$B&盘货信息!$C:$C,盘货信息!$N:$N)&"元】"))} | F9: {=IF(C9="","",_xlfn.XLOOKUP(A9&B9&C9,盘货信息!$A:$A&盘货信息!$B:$B&盘货信息!$C:$C,盘货信息!$E:$E)&"元到手价")} | G9: {=IF(C9="","",IF(_xlfn.XLOOKUP(A9&B9&C9,盘货信息!$A:$A&盘货信息!$B:$B&盘货信息!$C:$C,盘货信息!$I:$I)="","","88VIP95折"))} | H9: {=IF(C9="","",IF(_xlfn.XLOOKUP(A9&B9&C9,盘货信息!$A:$A&盘货信息!$B:$B&盘货信息!$C:$C,盘货信息!$J:$J)="","",_xlfn.XLOOKUP(A9&B9&C9,盘货信息!$A:$A&盘货信息!$B:$B&盘货信息!$C:$C,盘货信息!$J:$J)&"元优惠卷"))} | I9: {=IF(C9="","",IF(_xlfn.XLOOKUP(A9&B9&C9,盘货信息!$A:$A&盘货信息!$B:$B&盘货信息!$C:$C,盘货信息!$R:$R)="","",_xlfn.XLOOKUP(A9&B9&C9,盘货信息!$A:$A&盘货信息!$B:$B&盘货信息!$C:$C,盘货信息!$R:$R)&"元优惠卷"))} | J9: {=IF(C9="","",IF(_xlfn.XLOOKUP(A9&B9&C9,盘货信息!$A:$A&盘货信息!$B:$B&盘货信息!$C:$C,盘货信息!$K:$K)="","",IF(OR(_xlfn.XLOOKUP(A9&B9&C9,盘货信息!$A:$A&盘货信息!$B:$B&盘货信息!$C:$C,盘货信息!$G:$G)="参加",_xlfn.XLOOKUP(A9&B9&C9,盘货信息!$A:$A&盘货信息!$B:$B&盘货信息!$C:$C,盘货信息!$H:$H)="1（纯自补）"),_xlfn.XLOOKUP(A9&B9&C9,盘货信息!$A:$A&盘货信息!$B:$B&盘货信息!$C:$C,盘货信息!$K:$K)&"元以旧换新（可无旧机换新）","")))} | K9: {=IF(C9="","",IF(_xlfn.XLOOKUP(A9&B9&C9,盘货信息!$A:$A&盘货信息!$B:$B&盘货信息!$C:$C,盘货信息!$L:$L)="","",_xlfn.XLOOKUP(A9&B9&C9,盘货信息!$A:$A&盘货信息!$B:$B&盘货信息!$C:$C,盘货信息!$L:$L)&"元限时补贴"))} | L9: {=IF(C9="","",IF(_xlfn.XLOOKUP(A9&B9&C9,盘货信息!$A:$A&盘货信息!$B:$B&盘货信息!$C:$C,盘货信息!$M:$M)="","",_xlfn.XLOOKUP(A9&B9&C9,盘货信息!$A:$A&盘货信息!$B:$B&盘货信息!$C:$C,盘货信息!$M:$M)&"元消费券"))} | M9: {=IF(C9="","",IF(_xlfn.XLOOKUP(A9&B9&C9,盘货信息!$A:$A&盘货信息!$B:$B&盘货信息!$C:$C,盘货信息!$G:$G)="不参加","","焕新补贴优惠【全民可用，不限地址】"))}
A10: =IF(盘货信息!A10="","",盘货信息!A10) | B10: =IF(盘货信息!B10="","",盘货信息!B10) | C10: =IF(盘货信息!C10="","",盘货信息!C10) | D10: =IF(C10="","",E10&"="&F10&IF(G10="","","-"&G10)&IF(H10="","","-"&H10)&IF(I10="","","-"&I10)&IF(J10="","","-"&J10)&IF(K10="","","-"&K10)&IF(L10="","","-"&L10)&IF(M10="","","-"&M10)) | E10: {=IF(C10="","",IF(_xlfn.XLOOKUP(A10&B10&C10,盘货信息!$A:$A&盘货信息!$B:$B&盘货信息!$C:$C,盘货信息!$N:$N)="","【立减到手价"&_xlfn.XLOOKUP(A10&B10&C10,盘货信息!$A:$A&盘货信息!$B:$B&盘货信息!$C:$C,盘货信息!$F:$F)&"元】","【焕新补贴预估价"&_xlfn.XLOOKUP(A10&B10&C10,盘货信息!$A:$A&盘货信息!$B:$B&盘货信息!$C:$C,盘货信息!$N:$N)&"元】"))} | F10: {=IF(C10="","",_xlfn.XLOOKUP(A10&B10&C10,盘货信息!$A:$A&盘货信息!$B:$B&盘货信息!$C:$C,盘货信息!$E:$E)&"元到手价")} | G10: {=IF(C10="","",IF(_xlfn.XLOOKUP(A10&B10&C10,盘货信息!$A:$A&盘货信息!$B:$B&盘货信息!$C:$C,盘货信息!$I:$I)="","","88VIP95折"))} | H10: {=IF(C10="","",IF(_xlfn.XLOOKUP(A10&B10&C10,盘货信息!$A:$A&盘货信息!$B:$B&盘货信息!$C:$C,盘货信息!$J:$J)="","",_xlfn.XLOOKUP(A10&B10&C10,盘货信息!$A:$A&盘货信息!$B:$B&盘货信息!$C:$C,盘货信息!$J:$J)&"元优惠卷"))} | I10: {=IF(C10="","",IF(_xlfn.XLOOKUP(A10&B10&C10,盘货信息!$A:$A&盘货信息!$B:$B&盘货信息!$C:$C,盘货信息!$R:$R)="","",_xlfn.XLOOKUP(A10&B10&C10,盘货信息!$A:$A&盘货信息!$B:$B&盘货信息!$C:$C,盘货信息!$R:$R)&"元优惠卷"))} | J10: {=IF(C10="","",IF(_xlfn.XLOOKUP(A10&B10&C10,盘货信息!$A:$A&盘货信息!$B:$B&盘货信息!$C:$C,盘货信息!$K:$K)="","",IF(OR(_xlfn.XLOOKUP(A10&B10&C10,盘货信息!$A:$A&盘货信息!$B:$B&盘货信息!$C:$C,盘货信息!$G:$G)="参加",_xlfn.XLOOKUP(A10&B10&C10,盘货信息!$A:$A&盘货信息!$B:$B&盘货信息!$C:$C,盘货信息!$H:$H)="1（纯自补）"),_xlfn.XLOOKUP(A10&B10&C10,盘货信息!$A:$A&盘货信息!$B:$B&盘货信息!$C:$C,盘货信息!$K:$K)&"元以旧换新（可无旧机换新）","")))} | K10: {=IF(C10="","",IF(_xlfn.XLOOKUP(A10&B10&C10,盘货信息!$A:$A&盘货信息!$B:$B&盘货信息!$C:$C,盘货信息!$L:$L)="","",_xlfn.XLOOKUP(A10&B10&C10,盘货信息!$A:$A&盘货信息!$B:$B&盘货信息!$C:$C,盘货信息!$L:$L)&"元限时补贴"))} | L10: {=IF(C10="","",IF(_xlfn.XLOOKUP(A10&B10&C10,盘货信息!$A:$A&盘货信息!$B:$B&盘货信息!$C:$C,盘货信息!$M:$M)="","",_xlfn.XLOOKUP(A10&B10&C10,盘货信息!$A:$A&盘货信息!$B:$B&盘货信息!$C:$C,盘货信息!$M:$M)&"元消费券"))} | M10: {=IF(C10="","",IF(_xlfn.XLOOKUP(A10&B10&C10,盘货信息!$A:$A&盘货信息!$B:$B&盘货信息!$C:$C,盘货信息!$G:$G)="不参加","","焕新补贴优惠【全民可用，不限地址】"))}
A11: =IF(盘货信息!A11="","",盘货信息!A11) | B11: =IF(盘货信息!B11="","",盘货信息!B11) | C11: =IF(盘货信息!C11="","",盘货信息!C11) | D11: =IF(C11="","",E11&"="&F11&IF(G11="","","-"&G11)&IF(H11="","","-"&H11)&IF(I11="","","-"&I11)&IF(J11="","","-"&J11)&IF(K11="","","-"&K11)&IF(L11="","","-"&L11)&IF(M11="","","-"&M11)) | E11: {=IF(C11="","",IF(_xlfn.XLOOKUP(A11&B11&C11,盘货信息!$A:$A&盘货信息!$B:$B&盘货信息!$C:$C,盘货信息!$N:$N)="","【立减到手价"&_xlfn.XLOOKUP(A11&B11&C11,盘货信息!$A:$A&盘货信息!$B:$B&盘货信息!$C:$C,盘货信息!$F:$F)&"元】","【焕新补贴预估价"&_xlfn.XLOOKUP(A11&B11&C11,盘货信息!$A:$A&盘货信息!$B:$B&盘货信息!$C:$C,盘货信息!$N:$N)&"元】"))} | F11: {=IF(C11="","",_xlfn.XLOOKUP(A11&B11&C11,盘货信息!$A:$A&盘货信息!$B:$B&盘货信息!$C:$C,盘货信息!$E:$E)&"元到手价")} | G11: {=IF(C11="","",IF(_xlfn.XLOOKUP(A11&B11&C11,盘货信息!$A:$A&盘货信息!$B:$B&盘货信息!$C:$C,盘货信息!$I:$I)="","","88VIP95折"))} | H11: {=IF(C11="","",IF(_xlfn.XLOOKUP(A11&B11&C11,盘货信息!$A:$A&盘货信息!$B:$B&盘货信息!$C:$C,盘货信息!$J:$J)="","",_xlfn.XLOOKUP(A11&B11&C11,盘货信息!$A:$A&盘货信息!$B:$B&盘货信息!$C:$C,盘货信息!$J:$J)&"元优惠卷"))} | I11: {=IF(C11="","",IF(_xlfn.XLOOKUP(A11&B11&C11,盘货信息!$A:$A&盘货信息!$B:$B&盘货信息!$C:$C,盘货信息!$R:$R)="","",_xlfn.XLOOKUP(A11&B11&C11,盘货信息!$A:$A&盘货信息!$B:$B&盘货信息!$C:$C,盘货信息!$R:$R)&"元优惠卷"))} | J11: {=IF(C11="","",IF(_xlfn.XLOOKUP(A11&B11&C11,盘货信息!$A:$A&盘货信息!$B:$B&盘货信息!$C:$C,盘货信息!$K:$K)="","",IF(OR(_xlfn.XLOOKUP(A11&B11&C11,盘货信息!$A:$A&盘货信息!$B:$B&盘货信息!$C:$C,盘货信息!$G:$G)="参加",_xlfn.XLOOKUP(A11&B11&C11,盘货信息!$A:$A&盘货信息!$B:$B&盘货信息!$C:$C,盘货信息!$H:$H)="1（纯自补）"),_xlfn.XLOOKUP(A11&B11&C11,盘货信息!$A:$A&盘货信息!$B:$B&盘货信息!$C:$C,盘货信息!$K:$K)&"元以旧换新（可无旧机换新）","")))} | K11: {=IF(C11="","",IF(_xlfn.XLOOKUP(A11&B11&C11,盘货信息!$A:$A&盘货信息!$B:$B&盘货信息!$C:$C,盘货信息!$L:$L)="","",_xlfn.XLOOKUP(A11&B11&C11,盘货信息!$A:$A&盘货信息!$B:$B&盘货信息!$C:$C,盘货信息!$L:$L)&"元限时补贴"))} | L11: {=IF(C11="","",IF(_xlfn.XLOOKUP(A11&B11&C11,盘货信息!$A:$A&盘货信息!$B:$B&盘货信息!$C:$C,盘货信息!$M:$M)="","",_xlfn.XLOOKUP(A11&B11&C11,盘货信息!$A:$A&盘货信息!$B:$B&盘货信息!$C:$C,盘货信息!$M:$M)&"元消费券"))} | M11: {=IF(C11="","",IF(_xlfn.XLOOKUP(A11&B11&C11,盘货信息!$A:$A&盘货信息!$B:$B&盘货信息!$C:$C,盘货信息!$G:$G)="不参加","","焕新补贴优惠【全民可用，不限地址】"))}
A12: =IF(盘货信息!A12="","",盘货信息!A12) | B12: =IF(盘货信息!B12="","",盘货信息!B12) | C12: =IF(盘货信息!C12="","",盘货信息!C12) | D12: =IF(C12="","",E12&"="&F12&IF(G12="","","-"&G12)&IF(H12="","","-"&H12)&IF(I12="","","-"&I12)&IF(J12="","","-"&J12)&IF(K12="","","-"&K12)&IF(L12="","","-"&L12)&IF(M12="","","-"&M12)) | E12: {=IF(C12="","",IF(_xlfn.XLOOKUP(A12&B12&C12,盘货信息!$A:$A&盘货信息!$B:$B&盘货信息!$C:$C,盘货信息!$N:$N)="","【立减到手价"&_xlfn.XLOOKUP(A12&B12&C12,盘货信息!$A:$A&盘货信息!$B:$B&盘货信息!$C:$C,盘货信息!$F:$F)&"元】","【焕新补贴预估价"&_xlfn.XLOOKUP(A12&B12&C12,盘货信息!$A:$A&盘货信息!$B:$B&盘货信息!$C:$C,盘货信息!$N:$N)&"元】"))} | F12: {=IF(C12="","",_xlfn.XLOOKUP(A12&B12&C12,盘货信息!$A:$A&盘货信息!$B:$B&盘货信息!$C:$C,盘货信息!$E:$E)&"元到手价")} | G12: {=IF(C12="","",IF(_xlfn.XLOOKUP(A12&B12&C12,盘货信息!$A:$A&盘货信息!$B:$B&盘货信息!$C:$C,盘货信息!$I:$I)="","","88VIP95折"))} | H12: {=IF(C12="","",IF(_xlfn.XLOOKUP(A12&B12&C12,盘货信息!$A:$A&盘货信息!$B:$B&盘货信息!$C:$C,盘货信息!$J:$J)="","",_xlfn.XLOOKUP(A12&B12&C12,盘货信息!$A:$A&盘货信息!$B:$B&盘货信息!$C:$C,盘货信息!$J:$J)&"元优惠卷"))} | I12: {=IF(C12="","",IF(_xlfn.XLOOKUP(A12&B12&C12,盘货信息!$A:$A&盘货信息!$B:$B&盘货信息!$C:$C,盘货信息!$R:$R)="","",_xlfn.XLOOKUP(A12&B12&C12,盘货信息!$A:$A&盘货信息!$B:$B&盘货信息!$C:$C,盘货信息!$R:$R)&"元优惠卷"))} | J12: {=IF(C12="","",IF(_xlfn.XLOOKUP(A12&B12&C12,盘货信息!$A:$A&盘货信息!$B:$B&盘货信息!$C:$C,盘货信息!$K:$K)="","",IF(OR(_xlfn.XLOOKUP(A12&B12&C12,盘货信息!$A:$A&盘货信息!$B:$B&盘货信息!$C:$C,盘货信息!$G:$G)="参加",_xlfn.XLOOKUP(A12&B12&C12,盘货信息!$A:$A&盘货信息!$B:$B&盘货信息!$C:$C,盘货信息!$H:$H)="1（纯自补）"),_xlfn.XLOOKUP(A12&B12&C12,盘货信息!$A:$A&盘货信息!$B:$B&盘货信息!$C:$C,盘货信息!$K:$K)&"元以旧换新（可无旧机换新）","")))} | K12: {=IF(C12="","",IF(_xlfn.XLOOKUP(A12&B12&C12,盘货信息!$A:$A&盘货信息!$B:$B&盘货信息!$C:$C,盘货信息!$L:$L)="","",_xlfn.XLOOKUP(A12&B12&C12,盘货信息!$A:$A&盘货信息!$B:$B&盘货信息!$C:$C,盘货信息!$L:$L)&"元限时补贴"))} | L12: {=IF(C12="","",IF(_xlfn.XLOOKUP(A12&B12&C12,盘货信息!$A:$A&盘货信息!$B:$B&盘货信息!$C:$C,盘货信息!$M:$M)="","",_xlfn.XLOOKUP(A12&B12&C12,盘货信息!$A:$A&盘货信息!$B:$B&盘货信息!$C:$C,盘货信息!$M:$M)&"元消费券"))} | M12: {=IF(C12="","",IF(_xlfn.XLOOKUP(A12&B12&C12,盘货信息!$A:$A&盘货信息!$B:$B&盘货信息!$C:$C,盘货信息!$G:$G)="不参加","","焕新补贴优惠【全民可用，不限地址】"))}
